File: Data/Susceptibility/Eu5In2Sb6_TBe339_16p06mg_MPMS_MvT_aAxis_041523.dat
[Header]
; MPMS3 Data File (default extension .dat)
; Copyright (c) 2007, Quantum Design, Inc. All rights reserved.
TITLE,
FILEOPENTIME,3890735758.18508,04/15/2023,3:55 pm
BYAPP,MPMS3 w/ AC,1.0,1.1
INFO,MPMS3 Measurement Release 1.1.16 Build 419, MultiVu Release 2.3.4.15,APPNAME
INFO,Linear Motor Servo Controller,MOTOR_MODULE_NAME
INFO,3101-100 F0,MOTOR_HW_VERSION
INFO,MMC1118,MOTOR_SERIAL_NUMBER
INFO,01.04.28,MOTOR_SOFTWARE_VERSION
INFO,Quantum Design Squid Module,SQUID_MODULE_NAME
INFO,3101-501 B0,SQUID_HW_VERSION
INFO,SQM313,SQUID_SERIAL_NUMBER
INFO,01.03.04,SQUID_SOFTWARE_VERSION
INFO,Quantum Design VSM Oven,OVEN_MODULE_NAME
INFO,3101-201 A3,OVEN_HW_VERSION
INFO,OVB345,OVEN_SERIAL_NUMBER
INFO,01.07.07,OVEN_SOFTWARE_VERSION
INFO,SQUID AC,AC_MODULE_NAME
INFO,3101-401 G0,AC_HW_VERSION
INFO,SAC210,AC_SERIAL_NUMBER
INFO,SQUID AC 00.95.07,AC_SOFTWARE_VERSION
INFO,TCI318,COIL_SERIAL_NUMBER
INFO,0,MOMENT_UNITS
INFO,Eu5In2Sb6_TBe339_16p06mg_MPMS_MvT_aAxis_041523,SAMPLE_MATERIAL
INFO,,SAMPLE_COMMENT
INFO,16.06,SAMPLE_MASS
INFO,,SAMPLE_VOLUME
INFO,,SAMPLE_MOLECULAR_WEIGHT
INFO,,SAMPLE_SIZE
INFO,,SAMPLE_SHAPE
INFO,Brass,SAMPLE_HOLDER
INFO,Standard,SAMPLE_HOLDER_DETAIL
INFO,66.33,SAMPLE_OFFSET
DATATYPE,COMMENT,1
DATATYPE,TIME,2
STARTUPAXIS,X,2
STARTUPAXIS,Y1,5
FIELDGROUP, VSM,2,3,4,5,6,8,9,10,11,14,15
FIELDGROUP, DC, 2,3,4,14,56,57,58,59,60,61,62,63,64,65,66,67,68,69
FIELDGROUP, AC, 2,3,4,11,16,17,18,19,20,21,22,23,24,25,26,27,28,29,30
STARTUPGROUP, All
[Data]
Comment,Time Stamp (sec),Temperature (K),Magnetic Field (Oe),Moment (emu),M. Std. Err. (emu),Transport Action,Averaging Time (sec),Frequency (Hz),Peak Amplitude (mm),Center Position (mm),Lockin Signal' (V),Lockin Signal (V),Range,M. Quad. Signal (emu),AC Moment (emu),AC M. Std Err. (emu),AC Phase (deg),AC Phase Std. Err. (deg),AC Susceptibility (emu/Oe),AC Suscept. Std Err. (emu/Oe),AC X' (emu/Oe),AC X' Std Err. (emu/Oe),AC X'' (emu/Oe),AC X'' Std Err. (emu/Oe),AC Drive (Oe),AC Frequency (Hz),AC Averaging Time (sec),AC Cycles,AC Range,AC Measure Type,AC Signal' (V),AC Signal'' (V),AC Trim Coil Ratio,AC Trim Coil Phase,Min. Temperature (K),Max. Temperature (K),Min. Field (Oe),Max. Field (Oe),Mass (grams),Motor Lag (deg),Pressure (Torr),Measure Count,Measurement Number,SQUID Status (code),Motor Status (code),Measure Status (code),Motor Current (amps),Motor Temp. (C),Temp. Status (code),Field Status (code),Chamber Status (code),Chamber Temp (K),Redirection State,Evercool Status,Average Temp (K),Rotation Angle (deg),Rotator state,DC Moment Fixed Ctr (emu),DC Moment Err Fixed Ctr (emu),DC Moment Free Ctr (emu),DC Moment Err Free Ctr (emu),DC Fixed Fit,DC Free Fit,DC Calculated Center (mm),DC Calculated Center Err (mm),DC Scan Length (mm),DC Scan Time (s),DC Number of Points,DC Squid Drift,DC Min V (V),DC Max V (V),DC Scans per Measure,Map 01,Map 02,Map 03,Map 04,Map 05,Map 06,Map 07,Map 08,Map 09,Map 10,Map 11,Map 12,Map 13,Map 14,Map 15,Map 16
,3890735933.05642,1.99844121932983,1000.27911376953,,,3,,,,3.89276242256165,,,,,,,,,,,,,,,,,,,,,,,,,1.99844121932983,1.99844121932983,1000.27911376953,1000.27911376953,,,2.92036724090576,,0,,,,,,1,1,1,1.99844121932983,0,0,0,,,,,,,,,,,,,,,,,,,,,,,,,,,,,,,,,
,3890735993.06327,2.63833057880402,1000.27911376953,,,6,,,,3.89276242256165,,,100,,,,,,,,,,,,,,,,,,,,,,2.60134434700012,2.66859698295593,1000.27911376953,1000.27911376953,,,3.30424857139587,,1,0,0,0,0.0014495849609375,35.190616607666,6,1,1,2.67531681060791,0,4232058208,2.63125414848328,,,0.0137486979345408,0.00065409025725225,0.0137489466401289,0.000654100607837022,0.979980707168579,0.980094134807587,3.8849823474884,0,30,1,200,-0.00283100013621151,-0.622698068618774,0.16497628390789,1,,,,,,,,,,,,,,,,
,3890736044.13004,3.34213423728943,1000.27911376953,,,6,,,,3.89276242256165,,,100,,,,,,,,,,,,,,,,,,,,,,3.30858469009399,3.36592793464661,1000.27911376953,1000.27911376953,,,3.67352604866028,,1,0,0,0,0.00152587890625,34.7018585205078,6,1,1,3.37568378448486,0,4232058208,3.33456435203552,,,0.0155973881923558,0.000742036734473096,0.015597617517388,0.000742046481812997,0.98024994134903,0.980329394340515,3.88629055023193,1.48660659790039,30,1,200,-0.00353895709849894,-0.703485131263733,0.181847155094147,1,,,,,,,,,,,,,,,,
,3890736095.13939,4.08316135406494,1000.27911376953,,,6,,,,3.89276242256165,,,100,,,,,,,,,,,,,,,,,,,,,,4.04919815063477,4.10929822921753,1000.27911376953,1000.27911376953,,,3.99042463302612,,1,0,0,0,0.0164031982421875,34.2131004333496,6,1,1,4.11712455749512,0,4232058368,4.07618999481201,,,0.0178057307860347,0.000847096631751796,0.0178059475603827,0.000847105995811407,0.980301558971405,0.98035854101181,3.88729023933411,1.26850227388786E-6,30,1,200,-0.0039064809679985,-0.806065082550049,0.215890869498253,1,,,,,,,,,,,,,,,,
,3890736146.60892,4.83068656921387,1000.27911376953,,,6,,,,3.89276242256165,,,100,,,,,,,,,,,,,,,,,,,,,,4.7980375289917,4.85563945770264,1000.27911376953,1000.27911376953,,,4.25637340545654,,1,0,0,0,0.0156402587890625,34.2131004333496,6,1,1,4.86333560943604,0,4232058144,4.8240122795105,,,0.0202322667829906,0.000962536871142491,0.0202324656405046,0.000962545622648486,0.980340301990509,0.980377733707428,3.88832449913025,0,30,1,200,-0.00415617087855935,-0.914881825447082,0.243043333292007,1,,,,,,,,,,,,,,,,
,3890736197.66992,5.58871912956238,1000.27911376953,,,6,,,,3.89276242256165,,,100,,,,,,,,,,,,,,,,,,,,,,5.55310487747192,5.61108255386353,1000.27911376953,1000.27911376953,,,4.47501516342163,,1,0,0,0,0.0014495849609375,36.1681327819824,6,1,1,5.62433338165283,0,4232058240,5.58079042434692,,,0.022896656451945,0.00108929089225157,0.0228968342840162,0.00108929884550583,0.980454087257385,0.980477869510651,3.88923454284668,6.3689626017549E-8,30,1,200,-0.00462595699355006,-1.03085768222809,0.274112313985825,1,,,,,,,,,,,,,,,,
,3890736248.59725,6.37978911399841,1000.27911376953,,,6,,,,3.89276242256165,,,100,,,,,,,,,,,,,,,,,,,,,,6.35148286819458,6.41430044174194,1000.27911376953,1000.27911376953,,,4.67483854293823,,1,0,0,0,0.0014495849609375,34.2131004333496,6,1,1,6.41430044174194,0,4232058176,6.38094511032105,,,0.0259446671444274,0.00123429265705594,0.0259448256572712,0.00123429981830224,0.980669498443603,0.980685412883759,3.8898937702179,0,30,1,200,-0.00527356937527657,-1.17040252685547,0.310667842626572,1,,,,,,,,,,,,,,,,
,3890736299.62935,7.18874430656433,1000.27911376953,,,6,,,,3.89276242256165,,,100,,,,,,,,,,,,,,,,,,,,,,7.15402841567993,7.21592998504639,1000.27911376953,1000.27911376953,,,4.85262489318848,,1,0,0,0,0.0182342529296875,35.190616607666,6,1,1,7.22346019744873,0,4232058304,7.18403453826904,,,0.0294707741743484,0.00140203854383588,0.0294708532771215,0.00140204221774555,0.98089200258255,0.980895340442657,3.89145708084106,0,30,1,200,-0.00321179279126227,-1.33935809135437,0.352804839611053,1,,,,,,,,,,,,,,,,
,3890736350.48707,7.99137020111084,1000.27911376953,,,6,,,,3.89276242256165,,,100,,,,,,,,,,,,,,,,,,,,,,7.95693778991699,8.01837635040283,1000.27911376953,1000.27911376953,,,5.00277328491211,,1,0,0,0,0.00152587890625,35.190616607666,6,1,1,8.02580261230469,0,4232058208,7.98734750747681,,,0.0284944442996458,0.00135559708157918,0.0284945245519244,0.00135560080891306,0.980616867542267,0.980620324611664,3.89142560958862,1,30,1,200,0.00028096282039769,-1.3004606962204,0.337271809577942,1,,,,,,,,,,,,,,,,
,3890736406.96291,8.89338970184326,1000.27911376953,,,6,,,,3.89776641462821,,,100,,,,,,,,,,,,,,,,,,,,,,8.85853958129883,8.92208099365234,1000.27911376953,1000.27911376953,,,5.15843439102173,,1,0,0,0,0.0014495849609375,35.190616607666,6,1,1,8.9282398223877,0,4232058400,8.88922119140625,,,0.0272440516299964,0.00129610763830333,0.0272444701095962,0.00129612530218498,0.980741500854492,0.980831623077393,3.89096188545227,0,30,1,200,4.30981781391893E-5,-1.23740792274475,0.330419808626175,1,,,,,,,,,,,,,,,,
,3890736457.82446,9.70582056045532,1000.27911376953,,,6,,,,3.89776641462821,,,100,,,,,,,,,,,,,,,,,,,,,,9.67406749725342,9.73757362365723,1000.27911376953,1000.27911376953,,,5.28215312957764,,1,0,0,0,0.0188446044921875,34.7018585205078,6,1,1,9.73757362365723,0,4232058272,9.70661525726318,,,0.0262460934706234,0.00124863393669568,0.026246524711344,0.00124865208269077,0.980609059333801,0.980707168579102,3.89064335823059,0,30,1,200,0.000147487939102575,-1.19377291202545,0.316126823425293,1,,,,,,,,,,,,,,,,
,3890736508.8191,10.5304837226868,1000.27911376953,,,6,,,,3.89776641462821,,,100,,,,,,,,,,,,,,,,,,,,,,10.4972801208496,10.5593271255493,1000.27911376953,1000.27911376953,,,5.39305400848389,,1,0,0,0,0.0014495849609375,34.2131004333496,6,1,1,10.5636873245239,0,4232058336,10.528208732605,,,0.0253475424612698,0.00120588291082715,0.0253479802125632,0.00120590121272369,0.980737686157227,0.980846583843231,3.89028644561768,0,30,1,200,-6.1070779338479E-5,-1.15319395065308,0.303291320800781,1,,,,,,,,,,,,,,,,
,3890736559.79531,11.3515810966492,1000.27911376953,,,6,,,,3.89776641462821,,,100,,,,,,,,,,,,,,,,,,,,,,11.3185663223267,11.3776931762695,1000.27911376953,1000.27911376953,,,5.48968505859375,,1,0,0,0,0.0014495849609375,35.190616607666,6,1,1,11.3845958709717,0,4232058528,11.3477922439575,,,0.0245133198572733,0.00116620092147688,0.0245137761683732,0.0011662199197829,0.980531692504883,0.980651378631592,3.88988399505615,0.0346731059253216,30,1,200,-0.000150667357956991,-1.11501824855804,0.291298657655716,1,,,,,,,,,,,,,,,,
,3890736610.873,12.1810517311096,1000.27911376953,,,6,,,,3.89776641462821,,,100,,,,,,,,,,,,,,,,,,,,,,12.1450080871582,12.2088422775269,1000.27911376953,1000.27911376953,,,5.58194923400879,,1,0,0,0,0.0014495849609375,34.7018585205078,6,1,1,12.217095375061,0,4232058240,12.1776927947998,,,0.0237108431285049,0.00112802306855146,0.02371130819694,0.00112804225574869,0.98055511713028,0.980689525604248,3.88942193984985,0,30,1,200,-0.000304877117741853,-1.07779145240784,0.279754281044006,1,,,,,,,,,,,,,,,,
,3890736661.8712,13.011785030365,1000.27911376953,,,6,,,,3.89776641462821,,,100,,,,,,,,,,,,,,,,,,,,,,12.9745817184448,13.0426988601685,1000.27911376953,1000.27911376953,,,5.66096830368042,,1,0,0,0,0.00152587890625,34.2131004333496,6,1,1,13.0489883422852,0,4232058304,13.0097780227661,,,0.0228604759972462,0.00108756850895205,0.0228609709316997,0.0010875887106921,0.980499982833862,0.980658292770386,3.88869976997375,1.60194053933083E-6,30,1,200,-7.27308506611735E-5,-1.03910136222839,0.267612814903259,1,,,,,,,,,,,,,,,,
,3890736712.96464,13.8366327285767,1000.27911376953,,,6,,,,3.89776641462821,,,100,,,,,,,,,,,,,,,,,,,,,,13.8004560470581,13.8695287704468,1000.27911376953,1000.27911376953,,,5.73038959503174,,1,0,0,0,0.0218963623046875,34.2131004333496,6,1,1,13.8728094100952,0,4232058304,13.837495803833,,,0.0216003958340161,0.0010276299498695,0.0216009152583308,0.0010276508776301,0.980084955692291,0.980270624160767,3.88784623146057,0,30,1,200,0.0014082663692534,-0.987226247787476,0.261013448238373,1,,,,,,,,,,,,,,,,
,3890736764.00416,14.6728687286377,1000.27911376953,,,6,,,,3.89776641462821,,,100,,,,,,,,,,,,,,,,,,,,,,14.6382465362549,14.6919641494751,1000.27911376953,1000.27911376953,,,5.79666471481323,,1,0,0,0,0.0014495849609375,35.190616607666,6,1,1,14.7074909210205,0,4232058496,14.6660721302032,,,0.0192690593860331,0.000916709650929074,0.0192695912915339,0.000916730466746455,0.980512142181396,0.980764985084534,3.88632488250732,5.73495149612427,30,1,200,2.32131624215981E-5,-0.873983979225159,0.230590790510178,1,,,,,,,,,,,,,,,,
,3890736814.79387,15.5654377937317,1000.27911376953,,,6,,,,3.89776641462821,,,100,,,,,,,,,,,,,,,,,,,,,,15.5301666259766,15.5951089859009,1000.27911376953,1000.27911376953,,,5.85219621658325,,1,0,0,0,0.0014495849609375,35.190616607666,2,1,1,15.6007089614868,0,4232058112,15.5626472473145,,,0.0186890127479028,0.000889114538376494,0.0186895032833426,0.000889133933430974,0.980518400669098,0.980747222900391,3.88688039779663,0,30,1,200,-0.000154281151480973,-0.855277419090271,0.222002059221268,1,,,,,,,,,,,,,,,,
,3890736865.90095,16.3969974517822,1000.27911376953,,,6,,,,3.89776641462821,,,100,,,,,,,,,,,,,,,,,,,,,,16.360372543335,16.4266147613525,1000.27911376953,1000.27911376953,,,5.87017250061035,,1,0,0,0,0.01953125,34.7018585205078,2,1,1,16.4336223602295,0,4232058144,16.3935222625732,,,0.0181330776327135,0.000862668428237344,0.0181335593197757,0.000862687447314096,0.98039311170578,0.980624794960022,3.88677763938904,0,30,1,200,-0.00015134911518544,-0.826262831687927,0.213914155960083,1,,,,,,,,,,,,,,,,
,3890736917.0814,17.2407903671265,1000.27911376953,,,6,,,,3.89776641462821,,,100,,,,,,,,,,,,,,,,,,,,,,17.2027854919434,17.2577705383301,1000.27911376953,1000.27911376953,,,5.90157270431519,,1,0,0,0,0.0014495849609375,35.190616607666,2,1,1,17.2787952423096,0,4232058272,17.2293028831482,,,0.0175805791250087,0.000836383007489079,0.0175810393965654,0.000836401161410485,0.980422914028168,0.980652809143066,3.88682866096497,1.97150421142578,30,1,200,-8.61388398334384E-5,-0.797309577465057,0.205915436148643,1,,,,,,,,,,,,,,,,
,3890736968.45644,18.0807056427002,1000.27911376953,,,6,,,,3.89776641462821,,,100,,,,,,,,,,,,,,,,,,,,,,18.0435600280762,18.1092834472656,1000.27911376953,1000.27911376953,,,5.93429183959961,,1,0,0,0,0.021514892578125,34.7018585205078,2,1,1,18.1178512573242,0,4232058208,18.0778011322021,,,0.017042483949295,0.000810797106681018,0.0170429486280366,0.00081081567527139,0.979602754116058,0.979817748069763,3.88696980476379,0.174301013350487,30,1,200,-0.000119896998512559,-0.779791295528412,0.19809664785862,1,,,,,,,,,,,,,,,,
,3890737019.31628,18.9207763671875,1000.27911376953,,,6,,,,3.89776641462821,,,100,,,,,,,,,,,,,,,,,,,,,,18.8860149383545,18.9464530944824,1000.27911376953,1000.27911376953,,,5.96531248092651,,1,0,0,0,0.02166748046875,35.190616607666,2,1,1,18.9555377960205,0,4232058272,18.9162509918213,,,0.0165253658711726,0.000786184902680557,0.0165257865746219,0.000786201675079948,0.980237901210785,0.98044764995575,3.88726806640625,5.73555326461792,30,1,200,-7.9274810559582E-5,-0.751878976821899,0.201627999544144,1,,,,,,,,,,,,,,,,
,3890737070.41209,19.7575283050537,1000.27911376953,,,6,,,,3.89776641462821,,,100,,,,,,,,,,,,,,,,,,,,,,19.7157649993896,19.7851905822754,1000.27911376953,1000.27911376953,,,5.9981575012207,,1,0,0,0,0.0139617919921875,34.7018585205078,2,1,1,19.7992916107178,0,4232058112,19.750178527832,,,0.0160241563255834,0.000762335813533126,0.0160245317259456,0.00076235090583451,0.980529963970184,0.980717241764069,3.88791561126709,0.174383863806725,30,1,200,-6.32265000604093E-5,-0.735586881637573,0.194427385926247,1,,,,,,,,,,,,,,,,
,3890737121.4478,19.9999704360962,1000.27911376953,,,6,,,,3.89776641462821,,,100,,,,,,,,,,,,,,,,,,,,,,19.9997730255127,20.0002365112305,1000.27911376953,1000.27911376953,,,6.00440311431885,,1,0,0,0,0.023040771484375,34.7018585205078,5,1,1,19.9998302459717,0,4232058464,20.0000408172607,,,0.0158966194435499,0.000756270502757309,0.0158970069346996,0.000756286004739894,0.980378866195679,0.98057746887207,3.88758540153503,0,30,1,200,-0.00036993037792854,-0.72036349773407,0.192344129085541,1,,,,,,,,,,,,,,,,
,3890737182.74004,23.0610065460205,1000.27911376953,,,6,,,,3.89776641462821,,,100,,,,,,,,,,,,,,,,,,,,,,22.7218723297119,23.3430519104004,1000.27911376953,1000.27911376953,,,6.10862016677856,,1,0,0,0,0.0199127197265625,35.190616607666,2,1,1,23.4001407623291,0,4232058464,23.0308120727539,,,0.0141297204185268,0.000672220173763319,0.0141299607199142,0.000672230199693067,0.979758501052856,0.979862093925476,3.89028930664063,0,30,1,200,0.00272413995116949,-0.653127133846283,0.167752519249916,1,,,,,,,,,,,,,,,,
,3890737239.18188,31.7384185791016,1000.27911376953,,,6,,,,3.90299226437563,,,100,,,,,,,,,,,,,,,,,,,,,,31.3697814941406,32.0781173706055,1000.27911376953,1000.27911376953,,,6.30527210235596,,1,0,0,0,0.0206756591796875,34.7018585205078,2,1,1,32.1070556640625,0,4232058112,31.7062160491943,,,0.0107887355372236,0.00051327923490846,0.0107888840422801,0.00051328563068427,0.979162693023682,0.979225337505341,3.89709258079529,0,30,1,200,0.00156950333621353,-0.494667202234268,0.124304011464119,1,,,,,,,,,,,,,,,,
,3890737295.36254,40.4903774261475,1000.27911376953,,,6,,,,3.90826877732983,,,100,,,,,,,,,,,,,,,,,,,,,,40.1403160095215,40.7728462219238,1000.27911376953,1000.27911376953,,,6.44575309753418,,1,0,0,0,0.0218963623046875,35.190616607666,2,1,1,40.8404388427734,0,4232058208,40.4534278869629,,,0.00863105615288434,0.000410594480867874,0.00863109240706792,0.000410596093830235,0.983337998390198,0.983354330062866,3.90556883811951,0,30,1,200,0.000927433371543884,-0.400426357984543,0.105563260614872,1,,,,,,,,,,,,,,,,
,3890737346.63867,48.4897308349609,1000.27911376953,,,6,,,,3.90826877732983,,,100,,,,,,,,,,,,,,,,,,,,,,48.1654434204102,48.7809143066406,1000.27911376953,1000.27911376953,,,6.54464673995972,,1,0,0,0,0.0014495849609375,35.190616607666,2,1,1,48.8140182495117,0,4232058272,48.467066192627,,,0.00727333496407811,0.000346032586941934,0.00727323074112946,0.000346026813519927,0.979148149490356,0.97926139831543,3.91619372367859,,30,1,200,0.000671514833811671,-0.332427054643631,0.0874841287732124,1,,,,,,,,,,,,,,,,
,3890737403.09953,57.383508682251,1000.27911376953,,,6,,,,3.91367354340232,,,100,,,,,,,,,,,,,,,,,,,,,,57.0207366943359,57.6816673278809,1000.27911376953,1000.27911376953,,,6.62845420837402,,1,0,0,0,0.0012969970703125,34.2131004333496,2,1,1,57.746280670166,0,4232058400,57.3596527099609,,,0.00617601177467484,0.000293830270352223,0.00617586549892854,0.000293820846625021,0.97858715057373,0.978982329368591,3.92862296104431,,30,1,200,0.000479462760267779,-0.284404844045639,0.0727509036660194,1,,,,,,,,,,,,,,,,
,3890737464.63217,67.1274604797363,1000.27911376953,,,6,,,,3.92415304852716,,,100,,,,,,,,,,,,,,,,,,,,,,66.7183990478516,67.472412109375,1000.27911376953,1000.27911376953,,,6.6993556022644,,1,0,0,0,0.02197265625,34.7018585205078,2,1,1,67.5365219116211,0,4232058400,67.1024536132813,,,0.00529056655329101,0.000251691243803573,0.00529047327511117,0.000251683302001147,0.981150209903717,0.981903672218323,3.94343566894531,,30,1,200,0.000306200206978247,-0.243621870875359,0.0607801303267479,1,,,,,,,,,,,,,,,,
,3890737520.84814,76.1240501403809,1000.27911376953,,,6,,,,3.92966998196224,,,100,,,,,,,,,,,,,,,,,,,,,,75.7744750976563,76.4041137695313,1000.27911376953,1000.27911376953,,,6.75578260421753,,1,0,0,0,0.0019073486328125,34.7018585205078,2,1,1,76.4736251831055,0,4232058272,76.0947830200195,,,0.00467042784240277,0.00022221035335254,0.00467026442059078,0.000222195335054831,0.976631104946136,0.978069543838501,3.9591076374054,5.74804067611694,30,1,200,0.000220630361582153,-0.211978271603584,0.0522357262670994,1,,,,,,,,,,,,,,,,
,3890737577.26868,85.164794921875,1000.27911376953,,,6,,,,3.93507103475305,,,100,,,,,,,,,,,,,,,,,,,,,,84.7820129394531,85.4785537719727,1000.27911376953,1000.27911376953,,,6.79960584640503,,1,0,0,0,0.0223541259765625,34.7018585205078,2,1,1,85.5475769042969,0,4232058624,85.1311614990234,,,0.00417474079972051,0.000198635602550187,0.00417459355028878,0.000198616696660512,0.974736571311951,0.977229654788971,3.97494888305664,0,30,1,200,0.00015128479572013,-0.195519790053368,0.0453274734318256,1,,,,,,,,,,,,,,,,
,3890737638.88561,95.2767944335938,1000.27911376953,,,6,,,,3.94552448721856,,,100,,,,,,,,,,,,,,,,,,,,,,94.9209518432617,95.5508422851562,1000.27911376953,1000.27911376953,,,6.83829641342163,,1,0,0,0,0.0014495849609375,35.190616607666,2,1,1,95.6326370239258,0,4232058368,95.2337936401367,,,0.0037380357324729,0.000177862997081452,0.00373792444404793,0.000177842250170436,0.973433971405029,0.976932644844055,3.99352121353149,1.26781733342796E-5,30,1,200,0.000119717449706513,-0.170190647244453,0.0391107834875584,1,,,,,,,,,,,,,,,,
,3890737700.85783,105.4621925354,1000.27911376953,,,6,,,,3.95635683899892,,,100,,,,,,,,,,,,,,,,,,,,,,105.087020874023,105.706481933594,1000.27911376953,1000.27911376953,,,6.87662696838379,,1,0,0,0,0.01953125,34.7018585205078,2,1,1,105.837364196777,0,4232058240,105.418974304199,,,0.00338027325878814,0.000160847882405039,0.00338019318882063,0.000160824712109681,0.971647202968597,0.976266086101532,4.01281452178955,1.53073633555323E-5,30,1,200,7.13413537596352E-5,-0.158537641167641,0.0448196418583393,1,,,,,,,,,,,,,,,,
,3890737762.73719,115.694499969482,1000.27911376953,,,6,,,,3.9669991004439,,,100,,,,,,,,,,,,,,,,,,,,,,115.324508666992,115.995780944824,1000.27911376953,1000.27911376953,,,6.92577505111694,,1,0,0,0,0.021209716796875,34.7018585205078,2,1,1,116.064491271973,0,4232058368,115.657307434082,,,0.00308460943035211,0.000146788114103056,0.00308459734846187,0.000146762388630394,0.969522416591644,0.975783586502075,4.03431177139282,0.156842827796936,30,1,200,7.92129794717766E-5,-0.148977503180504,0.0404410101473331,1,,,,,,,,,,,,,,,,
,3890737838.77321,128.274063110352,1000.27911376953,,,6,,,,3.98453266634036,,,10,,,,,,,,,,,,,,,,,,,,,,127.935653686523,128.543319702148,1000.27911376953,1000.27911376953,,,6.9703254699707,,1,0,0,0,0.022735595703125,35.190616607666,2,1,1,128.61247253418,0,4232058336,128.235510253906,,,0.00278104743061451,0.000132351121031512,0.00278110046031402,0.000132323843116003,0.967437922954559,0.975296139717102,4.06163644790649,0,30,1,200,0.000294122495688498,-1.28571617603302,0.355331271886826,1,,,,,,,,,,,,,,,,
,3890737938.76001,144.869499206543,1000.27911376953,,,6,,,,4.01146737972144,,,10,,,,,,,,,,,,,,,,,,,,,,144.494827270508,145.133865356445,1000.27911376953,1000.27911376953,,,7.01805973052979,,1,0,0,0,0.0014495849609375,34.7018585205078,2,1,1,145.244171142578,0,4232058336,144.814532470703,,,0.00246342398215759,0.000117246056422707,0.00246350565414199,0.000117216224313549,0.964734494686127,0.974135875701904,4.09848594665527,0,30,1,200,-7.90161720942706E-5,-1.18558704853058,0.305910289287567,1,,,,,,,,,,,,,,,,
,3890738038.78771,161.347053527832,1000.27911376953,,,6,,,,4.04030081233489,,,10,,,,,,,,,,,,,,,,,,,,,,160.970703125,161.651214599609,1000.27911376953,1000.27911376953,,,7.0584774017334,,1,0,0,0,0.00152587890625,34.7018585205078,2,1,1,161.723403930664,0,4232058272,161.298648071289,,,0.00221002921295147,0.000105194735646058,0.00221014099554647,0.000105163220979435,0.962402164936066,0.973280608654022,4.13620281219482,0,30,1,200,-0.000183497730176896,-0.997056543827057,0.265419125556946,1,,,,,,,,,,,,,,,,
,3890738138.82712,177.890785217285,1000.27911376953,,,6,,,,4.0723943674563,,,10,,,,,,,,,,,,,,,,,,,,,,177.505081176758,178.160903930664,1000.27911376953,1000.27911376953,,,7.09516477584839,,1,0,0,0,0.0177001953125,34.2131004333496,2,1,1,178.276489257813,0,4232058304,177.837387084961,,,0.00200312423503382,9.53530058493348E-5,0.00200325094410425,9.53207855110104E-5,0.960583627223969,0.972574830055237,4.17492628097534,0,30,1,200,-7.84929434303194E-5,-0.933411180973053,0.231400072574615,1,,,,,,,,,,,,,,,,
,3890738285.86745,202.262222290039,1000.27911376953,,,6,,,,4.12792363837749,,,10,,,,,,,,,,,,,,,,,,,,,,201.526321411133,202.831253051758,1000.27911376953,1000.27911376953,,,7.1474175453186,,1,0,0,0,0.004425048828125,34.2131004333496,2,1,1,202.998123168945,0,4232058272,202.180942111545,,,0.00175715013900617,8.36440063488592E-5,0.00175732270634482,8.36161495126483E-5,0.960621058940887,0.973749935626984,4.23413944244385,0,30,1,200,-1.10103883343982E-5,-0.859997272491455,0.189557537436485,1,,,,,,,,,,,,,,,,
,3890738435.44761,227.041999816895,1000.27911376953,,,6,,,,4.18906271403454,,,10,,,,,,,,,,,,,,,,,,,,,,226.310791015625,227.637985229492,1000.27911376953,1000.27911376953,,,7.21077156066895,,1,0,0,0,0.0030517578125,34.7018585205078,2,1,1,227.773208618164,0,4232058368,226.975031534831,,,0.00156383943682752,7.4444523251679E-5,0.00156394991406658,7.44173331838231E-5,0.95977258682251,0.972661733627319,4.29564332962036,0.172572702169418,30,1,200,-0.000339604332111776,-0.69536417722702,0.153250336647034,1,,,,,,,,,,,,,,,,
,3890738584.59315,251.808860778809,1000.27911376953,,,6,,,,4.25690221827602,,,10,,,,,,,,,,,,,,,,,,,,,,251.085540771484,252.398025512695,1000.27911376953,1000.27911376953,,,7.36794996261597,,1,0,0,0,0.0014495849609375,34.2131004333496,2,1,1,252.532180786133,0,4232058304,251.733071221246,,,0.00140970159676357,6.7106952384825E-5,0.00140972012697203,6.70808226723624E-5,0.959779679775238,0.971478700637817,4.35912418365479,0.355122983455658,30,1,200,-0.000411896035075188,-0.653536915779114,0.121995449066162,1,,,,,,,,,,,,,,,,
,3890738734.12912,276.652603149414,1000.27911376953,,,6,,,,4.33211295672033,,,10,,,,,,,,,,,,,,,,,,,,,,275.904479980469,277.239105224609,1000.27911376953,1000.27911376953,,,7.57770824432373,,1,0,0,0,0.0218963623046875,34.7018585205078,2,1,1,277.400726318359,0,4232058368,276.580169677734,,,0.00128260597216807,6.10546719038412E-5,0.00128252992646001,6.10309121861153E-5,0.96063244342804,0.970154881477356,4.42446708679199,0.000319311453495175,30,1,200,-0.000337727920850739,-0.619478285312653,0.0958245322108269,1,,,,,,,,,,,,,,,,
,3890738875.55104,298.810317993164,1000.27911376953,,,6,,,,4.40442677015001,,,10,,,,,,,,,,,,,,,,,,,,,,298.696105957031,298.902160644531,1000.27911376953,1000.27911376953,,,7.47863340377808,,1,0,0,0,0.0194549560546875,34.7018585205078,6,1,1,298.924530029297,0,4232058560,298.798205566406,,,0.0011908817141954,5.6689318847022E-5,0.00119068604895392,5.66666619816195E-5,0.960228681564331,0.966660380363464,4.48224401473999,0.171754866838455,30,1,200,-0.000730424479115754,-0.595666348934174,0.184700429439545,1,,,,,,,,,,,,,,,,
,3890738926.44552,299.834609985352,1000.27911376953,,,6,,,,4.40442677015001,,,10,,,,,,,,,,,,,,,,,,,,,,299.822509765625,299.846008300781,1000.27911376953,1000.27911376953,,,7.47515869140625,,1,0,0,0,0.0014495849609375,34.2131004333496,5,1,1,299.846710205078,0,4232058528,299.834704589844,,,0.00118881636097628,5.65921151076024E-5,0.00118862425748968,5.6568556674354E-5,0.959733068943024,0.966644465923309,4.48537874221802,0,30,1,200,-0.000530752062331885,-0.597420811653137,0.181935369968414,1,,,,,,,,,,,,,,,,
,3890739938.08521,2.11472511291504,1000.27911376953,,,6,,,,3.89485180069272,,,100,,,,,,,,,,,,,,,,,,,,,,2.07859301567078,2.14019441604614,1000.27911376953,1000.27911376953,,,2.9190137386322,,1,0,0,0,0.0202178955078125,34.7018585205078,6,1,1,2.1508572101593,0,4232058112,2.10556654930115,,,0.0125662178984286,0.000597847958194466,0.0125665937524946,0.00059786260405577,0.978832721710205,0.979089856147766,3.88283228874207,0,30,1,200,-0.00227393209934235,-0.576670229434967,0.157196089625359,1,,,,,,,,,,,,,,,,
,3890739989.31584,2.84455752372742,1000.27911376953,,,6,,,,3.89485180069272,,,100,,,,,,,,,,,,,,,,,,,,,,2.80875563621521,2.87535333633423,1000.27911376953,1000.27911376953,,,3.382643699646,,1,0,0,0,0.00152587890625,35.190616607666,6,1,1,2.88035941123962,0,4232058240,2.83818111419678,,,0.0142429028522705,0.000677607259959742,0.0142432507888225,0.000677621143622819,0.979555785655975,0.979749262332916,3.88459324836731,1.86791240253115E-7,30,1,200,-0.00304905627854168,-0.645353257656097,0.177519336342812,1,,,,,,,,,,,,,,,,
,3890740040.21245,3.591801404953,1000.27911376953,,,6,,,,3.89485180069272,,,100,,,,,,,,,,,,,,,,,,,,,,3.55616402626038,3.61596727371216,1000.27911376953,1000.27911376953,,,3.76253390312195,,1,0,0,0,0.0139617919921875,34.7018585205078,6,1,1,3.62743878364563,0,4232058240,3.58361234664917,,,0.0162968447564763,0.000775321798319876,0.0162971701927342,0.000775335151328266,0.979676008224487,0.979811549186707,3.88628530502319,0,30,1,200,-0.00360552780330181,-0.738077223300934,0.192182675004005,1,,,,,,,,,,,,,,,,
,3890740091.09226,4.35541343688965,1000.27911376953,,,6,,,,3.89485180069272,,,100,,,,,,,,,,,,,,,,,,,,,,4.32302761077881,4.38381147384644,1000.27911376953,1000.27911376953,,,4.08429002761841,,1,0,0,0,0.0014495849609375,34.7018585205078,6,1,1,4.38779926300049,0,4232058176,4.35049695968628,,,0.0186558148165335,0.000887544194381706,0.0186561164552863,0.000887556856889856,0.979996740818024,0.980091989040375,3.88772344589233,,30,1,200,-0.00385305657982826,-0.841492474079132,0.221758648753166,1,,,,,,,,,,,,,,,,
,3890740142.00152,5.13587331771851,1000.27911376953,,,6,,,,3.89485180069272,,,100,,,,,,,,,,,,,,,,,,,,,,5.09935331344604,5.16183376312256,1000.27911376953,1000.27911376953,,,4.36051177978516,,1,0,0,0,0.0014495849609375,34.7018585205078,6,1,1,5.17239332199097,0,4232058208,5.12961120605469,,,0.021256748036206,0.00101128073841034,0.0212570342969408,0.00101129298797379,0.980089247226715,0.980157315731049,3.88883709907532,6.42544137008372E-7,30,1,200,-0.00425274902954698,-0.963733375072479,0.254658341407776,1,,,,,,,,,,,,,,,,
,3890740192.95922,5.91602945327759,1000.27911376953,,,6,,,,3.89485180069272,,,100,,,,,,,,,,,,,,,,,,,,,,5.88258695602417,5.93392133712769,1000.27911376953,1000.27911376953,,,4.58862733840942,,1,0,0,0,0.0014495849609375,34.7018585205078,6,1,1,5.94947195053101,0,4232058336,5.90490281581879,,,0.0240971563445616,0.00114641125785651,0.0240974086540896,0.00114642231900746,0.980125367641449,0.980166733264923,3.89016509056091,0,30,1,200,-0.00454225391149521,-1.0938628911972,0.290694028139114,1,,,,,,,,,,,,,,,,
,3890740244.06223,6.69784092903137,1000.27911376953,,,6,,,,3.89485180069272,,,100,,,,,,,,,,,,,,,,,,,,,,6.66361236572266,6.71359825134277,1000.27911376953,1000.27911376953,,,4.77070045471191,,1,0,0,0,0.0170135498046875,34.7018585205078,6,1,1,6.73206949234009,0,4232058176,6.68842709064484,,,0.0272602670887575,0.00129689178242406,0.0272604863799043,0.00129690156854815,0.980240702629089,0.980265915393829,3.89120173454285,9.72243651631288E-5,30,1,200,-0.0054333652369678,-1.23514497280121,0.330917418003082,1,,,,,,,,,,,,,,,,
,3890740295.32051,7.50352787971497,1000.27911376953,,,6,,,,3.89485180069272,,,100,,,,,,,,,,,,,,,,,,,,,,7.46875619888306,7.53166198730469,1000.27911376953,1000.27911376953,,,4.93561840057373,,1,0,0,0,0.023040771484375,34.7018585205078,6,1,1,7.53829956054687,0,4232058304,7.49908304214478,,,0.0292184304532467,0.00139004579255598,0.0292185791472383,0.00139005256684612,0.980395615100861,0.980406582355499,3.89245128631592,0,30,1,200,-5.25253381056245E-5,-1.32991373538971,0.353982329368591,1,,,,,,,,,,,,,,,,
,3890740346.68679,8.28413343429565,1000.27911376953,,,6,,,,3.89485180069272,,,100,,,,,,,,,,,,,,,,,,,,,,8.25072288513184,8.31399154663086,1000.27911376953,1000.27911376953,,,5.06749582290649,,1,0,0,0,0.020751953125,36.1681327819824,6,1,1,8.31754398345947,0,4232058368,8.28252429962158,,,0.0280721679297903,0.00133552594001487,0.0280723398636562,0.00133553374222725,0.979925274848938,0.979939341545105,3.89210414886475,1.0261717307003E-6,30,1,200,0.000156168942339718,-1.2803920507431,0.338976353406906,1,,,,,,,,,,,,,,,,
,3890740398.18842,9.10788869857788,1000.27911376953,,,6,,,,3.89485180069272,,,100,,,,,,,,,,,,,,,,,,,,,,9.07228946685791,9.13178634643555,1000.27911376953,1000.27911376953,,,5.19272136688232,,1,0,0,0,0.0220489501953125,34.7018585205078,6,1,1,9.14348793029785,0,4232058144,9.10368614196777,,,0.0269731145868197,0.00128322893709804,0.0269732791901442,0.00128323638154856,0.980318188667297,0.980333507061005,3.89201521873474,1.97281908988953,30,1,200,-2.07557131943759E-5,-1.23218941688538,0.324630558490753,1,,,,,,,,,,,,,,,,
,3890740449.02352,9.91934633255005,1000.27911376953,,,6,,,,3.89485180069272,,,100,,,,,,,,,,,,,,,,,,,,,,9.88399124145508,9.94173812866211,1000.27911376953,1000.27911376953,,,5.30130195617676,,1,0,0,0,0.0218963623046875,34.7018585205078,6,1,1,9.95470142364502,0,4232058240,9.91606540679932,,,0.0260051706901233,0.00123717515153897,0.0260053690091038,0.00123718399579043,0.980497062206268,0.980521500110626,3.89127993583679,0,30,1,200,-4.18126437580213E-5,-1.18773460388184,0.312071025371551,1,,,,,,,,,,,,,,,,
,3890740499.77005,10.7399725914001,1000.27911376953,,,6,,,,3.89485180069272,,,100,,,,,,,,,,,,,,,,,,,,,,10.7047729492187,10.7680616378784,1000.27911376953,1000.27911376953,,,5.40639400482178,,1,0,0,0,0.00152587890625,34.7018585205078,6,1,1,10.7751722335815,0,4232058464,10.7382034301758,,,0.0251300427976621,0.00119554904209662,0.0251302405744331,0.00119555787614841,0.980175495147705,0.980199754238129,3.89126682281494,0.0790697410702705,30,1,200,-7.90723934187554E-5,-1.14708626270294,0.300612777471542,1,,,,,,,,,,,,,,,,
,3890740550.72733,11.5635137557983,1000.27911376953,,,6,,,,3.89485180069272,,,100,,,,,,,,,,,,,,,,,,,,,,11.5266008377075,11.5911931991577,1000.27911376953,1000.27911376953,,,5.4987301826477,,1,0,0,0,0.01251220703125,34.2131004333496,6,1,1,11.6004266738892,0,4232058240,11.5607109069824,,,0.0243083955677927,0.00115645548360179,0.0243086190308108,0.00115646534974888,0.980347990989685,0.980381667613983,3.89064764976501,0,30,1,200,-7.18584560672753E-5,-1.10811305046082,0.289858460426331,1,,,,,,,,,,,,,,,,
,3890740601.86911,12.3901686668396,1000.27911376953,,,6,,,,3.89485180069272,,,100,,,,,,,,,,,,,,,,,,,,,,12.3525381088257,12.4169263839722,1000.27911376953,1000.27911376953,,,5.58498668670654,,1,0,0,0,0.016632080078125,34.7018585205078,6,1,1,12.4277992248535,0,4232058304,12.3851579666138,,,0.0235062883627181,0.00111829687848631,0.023506554947836,0.00111830845910854,0.980324625968933,0.980374753475189,3.88972020149231,2.12908344110474E-5,30,1,200,0.000131114909891039,-1.07013785839081,0.279347538948059,1,,,,,,,,,,,,,,,,
,3890740653.06257,13.2226285934448,1000.27911376953,,,6,,,,3.89485180069272,,,100,,,,,,,,,,,,,,,,,,,,,,13.1887550354004,13.2563896179199,1000.27911376953,1000.27911376953,,,5.6608715057373,,1,0,0,0,0.0014495849609375,34.2131004333496,6,1,1,13.2601413726807,0,4232058304,13.2234769821167,,,0.0226042015761993,0.00107538838364652,0.0226045198739083,0.00107540202228608,0.979945659637451,0.980015516281128,3.88873839378357,0.0749658420681953,30,1,200,0.000361279118806124,-1.02850413322449,0.267475575208664,1,,,,,,,,,,,,,,,,
,3890740713.80653,14.2139449119568,1000.27911376953,,,6,,,,3.89986392764536,,,100,,,,,,,,,,,,,,,,,,,,,,14.1778373718262,14.2444324493408,1000.27911376953,1000.27911376953,,,5.73323774337769,,1,0,0,0,0.0162506103515625,34.7018585205078,6,1,1,14.2500524520874,0,4232058464,14.2116312026978,,,0.0198553484465115,0.000944630980750776,0.0198560071004598,0.000944656253309555,0.979003429412842,0.979311227798462,3.88676881790161,5.73473644256592,30,1,200,0.00423929886892438,-0.916561722755432,0.241673916578293,1,,,,,,,,,,,,,,,,
,3890740764.7559,15.0439882278442,1000.27911376953,,,6,,,,3.89986392764536,,,100,,,,,,,,,,,,,,,,,,,,,,15.0067472457886,15.0756635665894,1000.27911376953,1000.27911376953,,,5.79959392547607,,1,0,0,0,0.0012969970703125,34.2131004333496,6,1,1,15.0812292098999,0,4232058336,15.0417783737183,,,0.0190196604982089,0.000904852536641584,0.0190203017908169,0.000904876879635353,0.980085611343384,0.980430662631988,3.88636994361877,0,30,1,200,-0.000135635724291205,-0.861769318580627,0.23216986656189,1,,,,,,,,,,,,,,,,
,3890740815.91597,15.9404892921448,1000.27911376953,,,6,,,,3.89986392764536,,,100,,,,,,,,,,,,,,,,,,,,,,15.904260635376,15.9721832275391,1000.27911376953,1000.27911376953,,,5.8301830291748,,1,0,0,0,0.00152587890625,34.7018585205078,2,1,1,15.9767179489136,0,4232058176,15.9372282028198,,,0.0184349506981356,0.000877044637133381,0.0184355941306848,0.000877069318423583,0.979560494422913,0.979893863201141,3.8864254951477,0,30,1,200,-2.12933719012653E-6,-0.842322468757629,0.224103644490242,1,,,,,,,,,,,,,,,,
,3890740866.9421,16.7716588973999,1000.27911376953,,,6,,,,3.89986392764536,,,100,,,,,,,,,,,,,,,,,,,,,,16.7350482940674,16.8010921478271,1000.27911376953,1000.27911376953,,,5.85878038406372,,1,0,0,0,0.020904541015625,34.2131004333496,2,1,1,16.8082695007324,0,4232058208,16.765242767334,,,0.0178854808528489,0.000850896240425281,0.0178860806359487,0.000850919111583862,0.979973971843719,0.980309009552002,3.88652849197388,1.97142803668976,30,1,200,1.98456345970044E-5,-0.812636792659759,0.216829866170883,1,,,,,,,,,,,,,,,,
,3890740917.76609,17.6061477661133,1000.27911376953,,,6,,,,3.89986392764536,,,100,,,,,,,,,,,,,,,,,,,,,,17.5678157806396,17.6376781463623,1000.27911376953,1000.27911376953,,,5.88307857513428,,1,0,0,0,0.00152587890625,34.7018585205078,2,1,1,17.6444797515869,0,4232058144,17.6033248901367,,,0.0173388036382154,0.00082488898998523,0.0173393628230294,0.000824910463132907,0.979930222034454,0.980242371559143,3.8869743347168,1.65925407409668,30,1,200,-3.09169554384425E-5,-0.794167697429657,0.209526211023331,1,,,,,,,,,,,,,,,,
,3890740969.01436,18.4488477706909,1000.27911376953,,,6,,,,3.89986392764536,,,100,,,,,,,,,,,,,,,,,,,,,,18.4139556884766,18.4788818359375,1000.27911376953,1000.27911376953,,,5.9211688041687,,1,0,0,0,0.018463134765625,34.7018585205078,2,1,1,18.4837398529053,0,4232058432,18.4465858459473,,,0.016810030565075,0.000799737197691957,0.0168105795671612,0.000799758320564404,0.979635536670685,0.9799445271492,3.88694787025452,,30,1,200,-0.000160344949108548,-0.765724718570709,0.202489286661148,1,,,,,,,,,,,,,,,,
,3890741019.8191,19.2826805114746,1000.27911376953,,,6,,,,3.89986392764536,,,100,,,,,,,,,,,,,,,,,,,,,,19.2481937408447,19.3106422424316,1000.27911376953,1000.27911376953,,,5.94812726974487,,1,0,0,0,0.0139617919921875,34.2131004333496,2,1,1,19.3171672821045,0,4232058304,19.279903793335,,,0.0163003904487063,0.000775490921814849,0.0163009019577156,0.000775510782312538,0.979665458202362,0.979951143264771,3.88745045661926,0,30,1,200,-0.000171129824593663,-0.748063564300537,0.195706501603127,1,,,,,,,,,,,,,,,,
,3890741070.93119,19.9932518005371,1000.27911376953,,,6,,,,3.89986392764536,,,100,,,,,,,,,,,,,,,,,,,,,,19.9904232025146,19.9956550598145,1000.27911376953,1000.27911376953,,,5.97705507278442,,1,0,0,0,0.0212860107421875,34.7018585205078,5,1,1,19.9960803985596,0,4232058144,19.9934669494629,,,0.0158950937051406,0.000756209123088569,0.0158956004581498,0.000756228719128402,0.979647815227509,0.979943037033081,3.88723921775818,0,30,1,200,-0.000615188211668283,-0.72308474779129,0.190429031848907,1,,,,,,,,,,,,,,,,
,3890741121.63682,20.0005674362183,1000.27911376953,,,6,,,,3.89986392764536,,,100,,,,,,,,,,,,,,,,,,,,,,20.0003223419189,20.0009098052979,1000.27911376953,1000.27911376953,,,5.97902154922485,,1,0,0,0,0.021209716796875,34.2131004333496,1,1,1,20.0003280639648,0,4232058272,20.000626373291,,,0.0158925853799629,0.000756088035940079,0.0158930902126305,0.000756107482344465,0.97975891828537,0.980059683322906,3.88715696334839,0,30,1,200,-0.000586056266911328,-0.723042786121368,0.190220862627029,1,,,,,,,,,,,,,,,,
,3890741182.88108,26.0912780761719,1000.27911376953,,,6,,,,3.89986392764536,,,100,,,,,,,,,,,,,,,,,,,,,,25.7572727203369,26.3626327514648,1000.27911376953,1000.27911376953,,,6.16187143325806,,1,0,0,0,0.00152587890625,35.190616607666,2,1,1,26.4252834320068,0,4232058208,26.0550132751465,,,0.0127756653257057,0.000607807584688501,0.0127758990544809,0.000607817279201211,0.979246020317078,0.979359269142151,3.89195132255554,1.97280287742615,30,1,200,0.00228700134903193,-0.586747825145721,0.148812472820282,1,,,,,,,,,,,,,,,,
,3890741239.37109,34.79296875,1000.27911376953,,,6,,,,3.90503883191019,,,100,,,,,,,,,,,,,,,,,,,,,,34.4534225463867,35.075252532959,1000.27911376953,1000.27911376953,,,6.33709764480591,,1,0,0,0,0.0012969970703125,34.2131004333496,2,1,1,35.1325149536133,0,4232058368,34.7603965759277,,,0.00992852295937988,0.000472354715364243,0.00992864938478336,0.000472360171183713,0.979116320610046,0.979173064231873,3.89942026138306,,30,1,200,0.00119892880320549,-0.456302136182785,0.122361794114113,1,,,,,,,,,,,,,,,,
,3890741290.52093,42.7928199768066,1000.27911376953,,,6,,,,3.90503883191019,,,100,,,,,,,,,,,,,,,,,,,,,,42.437557220459,43.0524559020996,1000.27911376953,1000.27911376953,,,6.4545202255249,,1,0,0,0,0.0014495849609375,34.2131004333496,2,1,1,43.1480827331543,0,4232058336,42.729761505127,,,0.00819001811493409,0.000389646470404706,0.00818996704898348,0.000389643892989007,0.978878498077393,0.97889643907547,3.90822052955627,,30,1,200,0.000902193947695196,-0.375594466924667,0.0991244688630104,1,,,,,,,,,,,,,,,,
,3890741346.98463,51.5780429840088,1000.27911376953,,,6,,,,3.91027557904069,,,100,,,,,,,,,,,,,,,,,,,,,,51.22705078125,51.8839302062988,1000.27911376953,1000.27911376953,,,6.55342149734497,,1,0,0,0,0.018463134765625,34.7018585205078,2,1,1,51.9290351867676,0,4232058208,51.5595108032227,,,0.00684164644771027,0.000325501372294014,0.00684153198229689,0.000325494862924336,0.978209316730499,0.978359758853912,3.91960525512695,,30,1,200,0.000631580711342394,-0.31865793466568,0.0814267322421074,1,,,,,,,,,,,,,,,,
,3890741403.28836,60.4882774353027,1000.27911376953,,,6,,,,3.91559427654929,,,100,,,,,,,,,,,,,,,,,,,,,,60.140022277832,60.7732734680176,1000.27911376953,1000.27911376953,,,6.62991952896118,,1,0,0,0,0.0203704833984375,34.2131004333496,2,1,1,60.8365325927734,0,4232058208,60.457829284668,,,0.00585870140336993,0.000278739554412482,0.00585855038584782,0.000278729341875683,0.977666079998016,0.978157579898834,3.93259906768799,,30,1,200,0.00037980213528499,-0.274076253175735,0.0685565248131752,1,,,,,,,,,,,,,,,,
,3890741464.95176,70.2549324035645,1000.27911376953,,,6,,,,3.92597191230714,,,100,,,,,,,,,,,,,,,,,,,,,,69.88037109375,70.4904174804687,1000.27911376953,1000.27911376953,,,6.69316053390503,,1,0,0,0,0.0218963623046875,34.2131004333496,2,1,1,70.6294937133789,0,4232058464,70.1856517791748,,,0.0050524101852806,0.000240385630627506,0.00505224975824192,0.000240373492704605,0.976393163204193,0.977200448513031,3.9482889175415,6.60624550619104E-7,30,1,200,0.000295641861157492,-0.235683798789978,0.0579676069319248,1,,,,,,,,,,,,,,,,
,3890741521.18824,79.2223014831543,1000.27911376953,,,6,,,,3.93099168682084,,,100,,,,,,,,,,,,,,,,,,,,,,78.8700637817383,79.5108642578125,1000.27911376953,1000.27911376953,,,6.74496030807495,,1,0,0,0,0.0205230712890625,34.7018585205078,2,1,1,79.5745391845703,0,4232058272,79.1962661743164,,,0.0044815062535859,0.000213229068130882,0.0044813520035227,0.000213213271251205,0.975207269191742,0.976861476898193,3.96344804763794,5.74888134002686,30,1,200,0.000197232395294122,-0.205198243260384,0.0504647977650166,1,,,,,,,,,,,,,,,,
,3890741582.60726,89.1479797363281,1000.27911376953,,,6,,,,3.94159499626419,,,100,,,,,,,,,,,,,,,,,,,,,,88.7835845947266,89.4460144042969,1000.27911376953,1000.27911376953,,,6.7923846244812,,1,0,0,0,0.0228118896484375,34.2131004333496,2,1,1,89.5123748779297,0,4232058240,89.1291931152344,,,0.00398543539415572,0.00018963217354013,0.00398529724876375,0.00018961442903578,0.973950326442718,0.976318120956421,3.98112154006958,1.14948852569796E-6,30,1,200,0.00014291719708126,-0.188369244337082,0.0439095534384251,1,,,,,,,,,,,,,,,,
,3890741638.80063,98.4876136779785,1000.27911376953,,,6,,,,3.94700702570681,,,100,,,,,,,,,,,,,,,,,,,,,,98.1322937011719,98.7759094238281,1000.27911376953,1000.27911376953,,,6.82931995391846,,1,0,0,0,0.02197265625,34.2131004333496,2,1,1,98.8429336547852,0,4232058464,98.4533569335938,,,0.00361658543747218,0.000172089922778668,0.00361649466975034,0.000172068889683292,0.972202003002167,0.975945889949799,3.99774098396301,,30,1,200,9.27099827094935E-5,-0.164859160780907,0.0389882959425449,1,,,,,,,,,,,,,,,,
,3890741700.24331,108.534370422363,1000.27911376953,,,6,,,,3.95788977210718,,,100,,,,,,,,,,,,,,,,,,,,,,108.151611328125,108.818397521973,1000.27911376953,1000.27911376953,,,6.86544513702393,,1,0,0,0,0.019378662109375,34.2131004333496,2,1,1,108.917129516602,0,4232058272,108.487420654297,,,0.00328273402342658,0.000156211510884566,0.00328268699955314,0.000156188540439537,0.970537066459656,0.975448191165924,4.01715660095215,1.66000747680664,30,1,200,6.82283061905764E-5,-0.153522580862045,0.0345186926424503,1,,,,,,,,,,,,,,,,
,3890741767.00883,119.689193725586,1000.27911376953,,,6,,,,3.97456185342867,,,100,,,,,,,,,,,,,,,,,,,,,,119.337600708008,119.994804382324,1000.27911376953,1000.27911376953,,,6.9177393913269,,1,0,0,0,0.023040771484375,34.2131004333496,2,1,1,120.040786743164,0,4232058272,119.66319732666,,,0.002982177008919,0.00014191665255183,0.00298215996889128,0.000141891954854436,0.96882039308548,0.974785387516022,4.04124736785889,0,30,1,200,2.96453381452011E-5,-0.143399775028229,0.0304433740675449,1,,,,,,,,,,,,,,,,
,3890741833.9707,130.674247741699,1000.27911376953,,,6,,,,3.99169615629525,,,100,,,,,,,,,,,,,,,,,,,,,,130.313766479492,130.969192504883,1000.27911376953,1000.27911376953,,,6.95680952072144,,1,0,0,0,0.00152587890625,34.7018585205078,2,1,1,131.034729003906,0,4232058208,130.644766235352,,,0.00273050043555339,0.000129935808776087,0.0027306398803655,0.000129916180342717,0.969829976558685,0.977500379085541,4.06485223770142,2.01614785194397,30,1,200,-9.47647731663892E-6,-0.124009117484093,0.0269871968775988,1,,,,,,,,,,,,,,,,
,3890741924.02326,145.493766784668,1000.27911376953,,,6,,,,4.01282371531543,,,10,,,,,,,,,,,,,,,,,,,,,,145.158401489258,145.829132080078,1000.27911376953,1000.27911376953,,,6.99711561203003,,1,0,0,0,0.0014495849609375,34.2131004333496,2,1,1,145.829132080078,0,4232058272,145.498004150391,,,0.00244915809396021,0.000116567869237244,0.00244923926749357,0.000116539228253423,0.964542031288147,0.973541259765625,4.09850454330444,0,30,1,200,-0.000155230954987928,-1.14892303943634,0.337184190750122,1,,,,,,,,,,,,,,,,
,3890742023.95858,162.073455810547,1000.27911376953,,,6,,,,4.0418022080573,,,10,,,,,,,,,,,,,,,,,,,,,,161.674362182617,162.373168945313,1000.27911376953,1000.27911376953,,,7.03607320785522,,1,0,0,0,0.0014495849609375,34.2131004333496,2,1,1,162.472549438477,0,4232058336,162.052282714844,,,0.00219852540487556,0.000104648076650629,0.00219863389191182,0.000104617620025407,0.96217954158783,0.972608804702759,4.13634920120239,0,30,1,200,2.70072850980796E-5,-1.06615173816681,0.30178564786911,1,,,,,,,,,,,,,,,,
,3890742123.77673,178.628677368164,1000.27911376953,,,6,,,,4.07387895330213,,,10,,,,,,,,,,,,,,,,,,,,,,178.262710571289,178.928375244141,1000.27911376953,1000.27911376953,,,7.0696496963501,,1,0,0,0,0.005035400390625,34.7018585205078,2,1,1,178.994644165039,0,4232058304,178.595178222656,,,0.00199428660583316,9.49333658749613E-5,0.00199441385486402,9.49022467782999E-5,0.960306346416473,0.97183620929718,4.17516565322876,2.61067634710344E-5,30,1,200,-0.000267375493422151,-0.998760640621185,0.272358685731888,1,,,,,,,,,,,,,,,,
,3890742270.75913,203.029747009277,1000.27911376953,,,6,,,,4.1294492173968,,,10,,,,,,,,,,,,,,,,,,,,,,202.295288085938,203.601409912109,1000.27911376953,1000.27911376953,,,7.11679649353027,,1,0,0,0,0.02044677734375,34.7018585205078,2,1,1,203.764205932617,0,4232058272,202.966313680013,,,0.00175027974255707,8.33173488256633E-5,0.00175044980002885,8.32905348216246E-5,0.96049427986145,0.973100483417511,4.23412990570068,0,30,1,200,-0.000133343855850399,-0.810416638851166,0.236867323517799,1,,,,,,,,,,,,,,,,
,3890742419.98442,227.703552246094,1000.27911376953,,,6,,,,4.19065184556288,,,10,,,,,,,,,,,,,,,,,,,,,,226.967025756836,228.306182861328,1000.27911376953,1000.27911376953,,,7.17039346694946,,1,0,0,0,0.0201416015625,34.7018585205078,2,1,1,228.440078735352,0,4232058528,227.637615627713,,,0.00155642401124066,7.40919696364012E-5,0.00155652789753005,7.40650736264681E-5,0.959615409374237,0.972209513187408,4.29646348953247,3.36295088345651E-5,30,1,200,-0.000322076288284734,-0.748332679271698,0.206556409597397,1,,,,,,,,,,,,,,,,
,3890742569.4322,252.585517883301,1000.27911376953,,,6,,,,4.25889409006115,,,10,,,,,,,,,,,,,,,,,,,,,,251.880889892578,253.152145385742,1000.27911376953,1000.27911376953,,,7.31596422195435,,1,0,0,0,0.0014495849609375,34.2131004333496,2,1,1,253.290145874023,0,4232058272,252.511973063151,,,0.00141175705720685,6.7203840469228E-5,0.00141176135210679,6.71779454347368E-5,0.960144102573395,0.971494734287262,4.35930442810059,0,30,1,200,-0.00035768115776591,-0.703288912773132,0.182488054037094,1,,,,,,,,,,,,,,,,
,3890742718.65761,277.253631591797,1000.27911376953,,,6,,,,4.33414108592657,,,10,,,,,,,,,,,,,,,,,,,,,,276.497497558594,277.868774414062,1000.27911376953,1000.27911376953,,,7.38684988021851,,1,0,0,0,0.0014495849609375,34.2131004333496,2,1,1,278.009765625,0,4232058304,277.195658365885,,,0.00128252856807282,6.10501303684304E-5,0.00128244222953014,6.1026723249007E-5,0.960995197296143,0.970170199871063,4.42454671859741,1.62576866149902,30,1,200,-0.000373743328964338,-0.66368693113327,0.160938069224358,1,,,,,,,,,,,,,,,,
,3890742860.74928,299.019500732422,1000.27911376953,,,6,,,,4.40499804467657,,,10,,,,,,,,,,,,,,,,,,,,,,298.9140625,299.107727050781,1000.27911376953,1000.27911376953,,,7.35392570495606,,1,0,0,0,0.00152587890625,34.7018585205078,6,1,1,299.124938964844,0,4232058304,299.014965820313,,,0.00119024899658306,5.66596851037472E-5,0.00119004889310857,5.66368254528011E-5,0.96002060174942,0.966411471366882,4.48279762268066,,30,1,200,-0.000523891882039607,-0.526033103466034,0.144809052348137,1,,,,,,,,,,,,,,,,
,3890742911.93185,299.861541748047,1000.27911376953,,,6,,,,4.40499804467657,,,10,,,,,,,,,,,,,,,,,,,,,,299.850952148438,299.870422363281,1000.27911376953,1000.27911376953,,,7.36363840103149,,1,0,0,0,0.00152587890625,34.7018585205078,5,1,1,299.872131347656,0,4232058304,299.860870361328,,,0.00118859441376948,5.65813568429394E-5,0.00118840044249033,5.65579560134223E-5,0.959809839725494,0.966608107089996,4.48525714874268,0,30,1,200,-0.000651818641927093,-0.526528835296631,0.1434256285429,1,,,,,,,,,,,,,,,,
,3890742932.2897,299.926467895508,1000.27911376953,,,6,,,,4.40499804467657,,,10,,,,,,,,,,,,,,,,,,,,,,299.921173095703,299.93115234375,1000.27911376953,1000.27911376953,,,7.36946058273315,,1,0,0,0,0.022430419921875,34.7018585205078,5,1,1,299.931762695313,0,4232058272,299.926306152344,,,0.00118830886352044,5.6567713660809E-5,0.00118811856025234,5.65441696408574E-5,0.959840297698975,0.966815292835236,4.48617029190063,2.11805820465088,30,1,200,-0.000594837940298021,-0.526903688907623,0.142932921648026,1,,,,,,,,,,,,,,,,