File: Data/Susceptibility/Eu5In2Sb6_TBe339_16p06mg_MPMS_MvH_10K_aAxis_041523.dat
[Header]
; MPMS3 Data File (default extension .dat)
; Copyright (c) 2007, Quantum Design, Inc. All rights reserved.
TITLE,
FILEOPENTIME,3890744808.53825,04/15/2023,6:26 pm
BYAPP,MPMS3 w/ AC,1.0,1.1
INFO,MPMS3 Measurement Release 1.1.16 Build 419, MultiVu Release 2.3.4.15,APPNAME
INFO,Linear Motor Servo Controller,MOTOR_MODULE_NAME
INFO,3101-100 F0,MOTOR_HW_VERSION
INFO,MMC1118,MOTOR_SERIAL_NUMBER
INFO,01.04.28,MOTOR_SOFTWARE_VERSION
INFO,Quantum Design Squid Module,SQUID_MODULE_NAME
INFO,3101-501 B0,SQUID_HW_VERSION
INFO,SQM313,SQUID_SERIAL_NUMBER
INFO,01.03.04,SQUID_SOFTWARE_VERSION
INFO,Quantum Design VSM Oven,OVEN_MODULE_NAME
INFO,3101-201 A3,OVEN_HW_VERSION
INFO,OVB345,OVEN_SERIAL_NUMBER
INFO,01.07.07,OVEN_SOFTWARE_VERSION
INFO,SQUID AC,AC_MODULE_NAME
INFO,3101-401 G0,AC_HW_VERSION
INFO,SAC210,AC_SERIAL_NUMBER
INFO,SQUID AC 00.95.07,AC_SOFTWARE_VERSION
INFO,TCI318,COIL_SERIAL_NUMBER
INFO,0,MOMENT_UNITS
INFO,Eu5In2Sb6_TBe339_16p06mg_MPMS_MvH_10K_aAxis_041523,SAMPLE_MATERIAL
INFO,,SAMPLE_COMMENT
INFO,16.06,SAMPLE_MASS
INFO,,SAMPLE_VOLUME
INFO,,SAMPLE_MOLECULAR_WEIGHT
INFO,,SAMPLE_SIZE
INFO,,SAMPLE_SHAPE
INFO,Brass,SAMPLE_HOLDER
INFO,Standard,SAMPLE_HOLDER_DETAIL
INFO,66.33,SAMPLE_OFFSET
DATATYPE,COMMENT,1
DATATYPE,TIME,2
STARTUPAXIS,X,2
STARTUPAXIS,Y1,5
FIELDGROUP, VSM,2,3,4,5,6,8,9,10,11,14,15
FIELDGROUP, DC, 2,3,4,14,56,57,58,59,60,61,62,63,64,65,66,67,68,69
FIELDGROUP, AC, 2,3,4,11,16,17,18,19,20,21,22,23,24,25,26,27,28,29,30
STARTUPGROUP, All
[Data]
Comment,Time Stamp (sec),Temperature (K),Magnetic Field (Oe),Moment (emu),M. Std. Err. (emu),Transport Action,Averaging Time (sec),Frequency (Hz),Peak Amplitude (mm),Center Position (mm),Lockin Signal' (V),Lockin Signal (V),Range,M. Quad. Signal (emu),AC Moment (emu),AC M. Std Err. (emu),AC Phase (deg),AC Phase Std. Err. (deg),AC Susceptibility (emu/Oe),AC Suscept. Std Err. (emu/Oe),AC X' (emu/Oe),AC X' Std Err. (emu/Oe),AC X'' (emu/Oe),AC X'' Std Err. (emu/Oe),AC Drive (Oe),AC Frequency (Hz),AC Averaging Time (sec),AC Cycles,AC Range,AC Measure Type,AC Signal' (V),AC Signal'' (V),AC Trim Coil Ratio,AC Trim Coil Phase,Min. Temperature (K),Max. Temperature (K),Min. Field (Oe),Max. Field (Oe),Mass (grams),Motor Lag (deg),Pressure (Torr),Measure Count,Measurement Number,SQUID Status (code),Motor Status (code),Measure Status (code),Motor Current (amps),Motor Temp. (C),Temp. Status (code),Field Status (code),Chamber Status (code),Chamber Temp (K),Redirection State,Evercool Status,Average Temp (K),Rotation Angle (deg),Rotator state,DC Moment Fixed Ctr (emu),DC Moment Err Fixed Ctr (emu),DC Moment Free Ctr (emu),DC Moment Err Free Ctr (emu),DC Fixed Fit,DC Free Fit,DC Calculated Center (mm),DC Calculated Center Err (mm),DC Scan Length (mm),DC Scan Time (s),DC Number of Points,DC Squid Drift,DC Min V (V),DC Max V (V),DC Scans per Measure,Map 01,Map 02,Map 03,Map 04,Map 05,Map 06,Map 07,Map 08,Map 09,Map 10,Map 11,Map 12,Map 13,Map 14,Map 15,Map 16
,3890745261.31937,9.99991512298584,-0.269376069307327,,,6,,,,3.89491802737971,,,100,,,,,,,,,,,,,,,,,,,,,,9.9992790222168,10.0003547668457,-0.269376069307327,-0.269376069307327,,,4.9386625289917,,1,0,0,0,0.0020599365234375,34.7018585205078,1,1,1,9.99982833862305,0,4232058464,9.99981292088826,,,0.00544637886654588,0.000259089821321001,0.00544650257987575,0.000259094249024532,0.984293520450592,0.984655797481537,3.8826310634613,0,30,1,200,-7.64308351790532E-5,-0.247583493590355,0.0636991187930107,1,,,,,,,,,,,,,,,,
,3890745361.11758,9.99954986572266,349.723602294922,,,6,,,,3.89491802737971,,,100,,,,,,,,,,,,,,,,,,,,,,9.99886798858643,9.99981784820557,349.723602294922,349.723602294922,,,5.00099277496338,,1,0,0,0,0.014190673828125,34.7018585205078,1,1,1,9.99973964691162,0,4232058304,9.9992883682251,,,0.0130014255775243,0.000618491707244404,0.0130017719922024,0.000618503769275543,0.984232902526855,0.984692454338074,3.8810727596283,0.0568200089037418,30,1,200,-0.000242240334046073,-0.592291712760925,0.151348501443863,1,,,,,,,,,,,,,,,,
,3890745461.79042,9.99977540969849,699.863525390625,,,6,,,,3.89491802737971,,,100,,,,,,,,,,,,,,,,,,,,,,9.9991626739502,9.99986457824707,699.863525390625,699.863525390625,,,5.03198909759521,,1,0,0,0,0.0014495849609375,34.7018585205078,1,1,1,9.99997997283935,0,4232058592,9.99954357147217,,,0.0199860897332088,0.000950755506960173,0.0199866273934063,0.000950774178401208,0.984485447406769,0.984960734844208,3.88095307350159,0,30,1,200,-0.00115754792932421,-0.908222496509552,0.238320335745811,1,,,,,,,,,,,,,,,,
,3890745562.12681,9.99980974197388,1050.01574707031,,,6,,,,3.89491802737971,,,100,,,,,,,,,,,,,,,,,,,,,,9.99915981292725,9.99998378753662,1050.01574707031,1050.01574707031,,,5.0593991279602,,1,0,0,0,0.02288818359375,34.7018585205078,1,1,1,10.0000009536743,0,4232058432,9.99964027404785,,,0.0269391121288517,0.00128151966622653,0.0269397230045992,0.00128154156478056,0.984347283840179,0.984708368778229,3.88267159461975,,30,1,200,-0.0020996502134949,-1.22511672973633,0.324940204620361,1,,,,,,,,,,,,,,,,
,3890745662.4902,9.99853610992432,1400.216796875,,,6,,,,3.89491802737971,,,100,,,,,,,,,,,,,,,,,,,,,,9.99775218963623,9.99863433837891,1400.216796875,1400.216796875,,,5.0788369178772,,1,0,0,0,0.0014495849609375,33.7243423461914,1,1,1,9.99872875213623,0,4232058208,9.99824028015137,,,0.0338781075582117,0.00161161728023007,0.0338788040372641,0.00161164268222197,0.984258532524109,0.984566211700439,3.88357210159302,0,30,1,200,-0.00519294617697597,-1.54192709922791,0.406338751316071,1,,,,,,,,,,,,,,,,
,3890745762.46132,9.99804067611694,1750.16064453125,,,6,,,,3.89491802737971,,,100,,,,,,,,,,,,,,,,,,,,,,9.99701499938965,9.99825382232666,1750.16064453125,1750.16064453125,,,5.08385038375854,,1,0,0,0,0.0014495849609375,34.2131004333496,1,1,1,9.99800968170166,0,4232058304,9.99772968292236,,,0.0408058649729406,0.0019411741240805,0.0408066499626049,0.0019412030798942,0.984396874904633,0.98467618227005,3.8841495513916,0.618898749351501,30,1,200,-0.00512844882905483,-1.85604393482208,0.483728766441345,1,,,,,,,,,,,,,,,,
,3890745863.00989,9.99964904785156,2099.95776367187,,,6,,,,3.89491802737971,,,100,,,,,,,,,,,,,,,,,,,,,,9.99917507171631,10.0000486373901,2099.95776367187,2099.95776367187,,,5.07984066009521,,1,0,0,0,0.023040771484375,36.6568908691406,1,1,1,9.99970245361328,0,4232058272,9.99959716796875,,,0.0477125884110664,0.00226972947673679,0.0477134663958796,0.0022697619651429,0.984492063522339,0.984757900238037,3.88444352149963,1.97089922428131,30,1,200,-0.00657017854973674,-2.16202855110168,0.566889762878418,1,,,,,,,,,,,,,,,,
,3890745963.49392,9.99983549118042,2450.2568359375,,,6,,,,3.89491802737971,,,100,,,,,,,,,,,,,,,,,,,,,,9.99896907806397,9.99996852874756,2450.2568359375,2450.2568359375,,,5.08803129196167,,1,0,0,0,0.0139617919921875,34.7018585205078,1,1,1,10.0000009536743,0,4232712192,9.99943408966064,,,0.054632179105471,0.00259890363158121,0.054633155950838,0.00259894009430521,0.984408378601074,0.984657287597656,3.88475275039673,0,30,1,200,-0.00712851248681545,-2.47722339630127,0.652591288089752,1,,,,,,,,,,,,,,,,
,3890746064.05298,9.99979591369629,2800.33569335938,,,6,,,,3.89491802737971,,,100,,,,,,,,,,,,,,,,,,,,,,9.9990348815918,10.0000524520874,2800.33569335938,2800.33569335938,,,5.08803224563599,,1,0,0,0,0.0139617919921875,34.7018585205078,1,1,1,9.99979400634766,0,4232058400,9.99960556030274,,,0.0615337106670822,0.00292722857856964,0.061534792599304,0.00292726961470566,0.984139740467071,0.984366059303284,3.88513922691345,0,30,1,200,-0.00918039493262768,-2.79446172714233,0.734376311302185,1,,,,,,,,,,,,,,,,
,3890746165.18545,9.99973917007446,3150.48779296875,,,6,,,,3.89491802737971,,,100,,,,,,,,,,,,,,,,,,,,,,9.99908351898193,10.000207901001,3150.48779296875,3150.48779296875,,,5.09692335128784,,1,0,0,0,0.0014495849609375,34.7018585205078,1,1,1,9.99971771240234,0,4232058464,9.99967803955078,,,0.0683928792741723,0.00325351191990884,0.0683940324510963,0.00325355543292019,0.984443008899689,0.984668731689453,3.88524460792542,2.45834125962574E-5,30,1,200,-0.00890485476702452,-3.10006499290466,0.817387700080872,1,,,,,,,,,,,,,,,,
,3890746266.41487,9.99995899200439,3500.41967773438,,,6,,,,3.89491802737971,,,100,,,,,,,,,,,,,,,,,,,,,,9.99914264678955,10.0001888275146,3500.41967773438,3500.41967773438,,,5.10181760787964,,1,0,0,0,0.018768310546875,34.7018585205078,1,1,1,10.0000600814819,0,4232058240,9.99968986511231,,,0.0752304771903682,0.00357878647927991,0.0752317159857411,0.00357883383539567,0.984358608722687,0.984566748142242,3.88560247421265,2.40533681790112E-5,30,1,200,-0.00994968134909868,-3.4126615524292,0.893155932426453,1,,,,,,,,,,,,,,,,
,3890746371.05959,9.999915599823,3850.36352539063,,,6,,,,3.89491802737971,,,100,,,,,,,,,,,,,,,,,,,,,,9.9990291595459,10.0000133514404,3850.36352539063,3850.36352539063,,,5.10572957992554,,1,0,0,0,0.0014495849609375,34.2131004333496,1,1,1,10.0000972747803,0,4232058176,9.9995493888855,,,0.0820727205904511,0.0039042706489886,0.0820740237206744,0.00390432038393597,0.984511196613312,0.984715163707733,3.88573956489563,5.7247748374939,30,1,200,-0.0117400586605072,-3.72327566146851,0.976062953472137,1,,,,,,,,,,,,,,,,
,3890746477.30121,9.99995231628418,4200.45458984375,,,6,,,,3.89491802737971,,,100,,,,,,,,,,,,,,,,,,,,,,9.99914455413818,10.0000534057617,4200.45458984375,4200.45458984375,,,5.11264276504517,,1,0,0,0,0.0014495849609375,34.7018585205078,1,1,1,10.0000810623169,0,4232058144,9.99966621398926,,,0.0889334119693844,0.00423064665492857,0.0889347681298456,0.00423069880495786,0.984379470348358,0.984567642211914,3.88606214523315,0,30,1,200,-0.0119678918272257,-4.03858327865601,1.06166458129883,1,,,,,,,,,,,,,,,,
,3890746582.23407,9.99988031387329,4550.177734375,,,6,,,,3.89491802737971,,,100,,,,,,,,,,,,,,,,,,,,,,9.99898815155029,10.0001249313354,4550.177734375,4550.177734375,,,5.11348247528076,,1,0,0,0,0.02166748046875,34.2131004333496,1,1,1,10.0000057220459,0,4232058464,9.99954586029053,,,0.0957864234509319,0.00455666903676603,0.0957879252260341,0.00455672713792694,0.984131693840027,0.984317243099213,3.88605570793152,1.04883142171275E-7,30,1,200,-0.0111921904608607,-4.34709072113037,1.1415468454361,1,,,,,,,,,,,,,,,,
,3890746689.35351,9.99975633621216,4900.45263671875,,,6,,,,3.89491802737971,,,100,,,,,,,,,,,,,,,,,,,,,,9.99913024902344,10.0000410079956,4900.45263671875,4900.45263671875,,,5.11827516555786,,1,0,0,0,0.0014495849609375,34.2131004333496,1,1,1,9.99987983703613,0,4232058176,9.99958820343017,,,0.10264879063298,0.00488308869465712,0.10265027775245,0.00488314630447651,0.984503626823425,0.984678149223328,3.88642263412476,0,30,1,200,-0.0124581065028906,-4.65271854400635,1.22431933879852,1,,,,,,,,,,,,,,,,
,3890746794.16674,9.99991273880005,4750.2998046875,,,6,,,,3.89491802737971,,,100,,,,,,,,,,,,,,,,,,,,,,9.99899196624756,10.0001249313354,4750.2998046875,4750.2998046875,,,5.12019491195679,,1,0,0,0,0.020751953125,34.7018585205078,1,1,1,9.99997806549072,0,4232058304,9.99965000152588,,,0.0996646071492882,0.004741146366317,0.099666069692678,0.00474120320209688,0.984307467937469,0.984479546546936,3.88642740249634,,30,1,200,-0.00326961860992014,-4.52120637893677,1.19894707202911,1,,,,,,,,,,,,,,,,
,3890746898.25117,9.99989223480225,4400.2216796875,,,6,,,,3.89491802737971,,,100,,,,,,,,,,,,,,,,,,,,,,9.99907493591309,10.0000419616699,4400.2216796875,4400.2216796875,,,5.12488412857056,,1,0,0,0,0.0202178955078125,34.2131004333496,1,1,1,10.0000905990601,0,4232058368,9.99962940216065,,,0.0927093703019759,0.00441027427795015,0.0927106999265057,0.00441032625549945,0.984359920024872,0.984524190425873,3.88663578033447,0,30,1,200,-0.00467326585203409,-4.2074089050293,1.10839629173279,1,,,,,,,,,,,,,,,,
,3890747002.16457,9.99991703033447,4050.24047851562,,,6,,,,3.89491802737971,,,100,,,,,,,,,,,,,,,,,,,,,,9.99905967712402,10.0001058578491,4050.24047851562,4050.24047851562,,,5.12758684158325,,1,0,0,0,0.0206756591796875,34.7018585205078,1,1,1,10.0000495910645,0,4232058240,9.99962482452393,,,0.0857603612618448,0.00407969589237313,0.0857615347982764,0.00407974175446451,0.984451413154602,0.984609246253967,3.88682222366333,5.72489023208618,30,1,200,-0.00210215733386576,-3.89197421073914,1.03356659412384,1,,,,,,,,,,,,,,,,
,3890747107.99129,9.99969577789307,3700.2353515625,,,6,,,,3.89491802737971,,,100,,,,,,,,,,,,,,,,,,,,,,9.99897766113281,10.0000247955322,3700.2353515625,3700.2353515625,,,5.12674283981323,,1,0,0,0,0.001678466796875,34.2131004333496,1,1,1,9.99969577789307,0,4232058208,9.99955081939697,,,0.0788151631190308,0.00374930794421773,0.0788162403433064,0.00374935024457572,0.984457850456238,0.984612047672272,3.88691687583923,1.61419427394867,30,1,200,-0.0015468942001462,-3.57316589355469,0.950541436672211,1,,,,,,,,,,,,,,,,
,3890747211.67877,9.99990510940552,3350.36499023438,,,6,,,,3.89491802737971,,,100,,,,,,,,,,,,,,,,,,,,,,9.99909210205078,10.0000667572021,3350.36499023438,3350.36499023438,,,5.1277904510498,,1,0,0,0,0.0014495849609375,34.2131004333496,1,1,1,10.0001096725464,0,4232058272,9.99955291748047,,,0.071873810654979,0.00341909889278961,0.0718747535029545,0.00341913602894817,0.98451429605484,0.984660685062408,3.88713645935059,0,30,1,200,-0.00100374757312238,-3.25630044937134,0.865159690380096,1,,,,,,,,,,,,,,,,
,3890747314.84834,9.99980640411377,3000.4453125,,,6,,,,3.89491802737971,,,100,,,,,,,,,,,,,,,,,,,,,,9.99875068664551,10.0000944137573,3000.4453125,3000.4453125,,,5.12688970565796,,1,0,0,0,0.01495361328125,34.7018585205078,1,1,1,9.99982166290283,0,4232058240,9.99948043823242,,,0.0649480574892564,0.00308963172135176,0.0649489062102223,0.00308966517764907,0.984558045864105,0.984703719615936,3.88716626167297,0,30,1,200,0.00127325637731701,-2.93694162368774,0.786159038543701,1,,,,,,,,,,,,,,,,
,3890747418.70226,9.99977207183838,2650.35424804687,,,6,,,,3.89491802737971,,,100,,,,,,,,,,,,,,,,,,,,,,9.99905776977539,10.0001420974731,2650.35424804687,2650.35424804687,,,5.12571239471436,,1,0,0,0,0.0214385986328125,34.2131004333496,1,1,1,9.99978923797607,0,4232058304,9.99964904785156,,,0.0580135428624628,0.00275975663808292,0.0580142957343111,0.00275978634561563,0.984447300434113,0.984590172767639,3.88721227645874,,30,1,200,0.0022799673024565,-2.62242722511291,0.699330925941467,1,,,,,,,,,,,,,,,,
,3890747517.72381,9.99977922439575,2300.41040039062,,,6,,,,3.89491802737971,,,100,,,,,,,,,,,,,,,,,,,,,,9.99880504608154,10.0000772476196,2300.41040039062,2300.41040039062,,,5.12347364425659,,1,0,0,0,0.0014495849609375,34.2131004333496,1,1,1,9.99980163574219,0,4232058336,9.99946956634522,,,0.0510865296081523,0.00243023606740988,0.0510871949725859,0.00243026256118374,0.984332144260407,0.984468162059784,3.88737154006958,0,30,1,200,0.00351475807838142,-2.30693507194519,0.614139497280121,1,,,,,,,,,,,,,,,,
,3890747617.7347,9.9998631477356,1950.41735839844,,,6,,,,3.89491802737971,,,100,,,,,,,,,,,,,,,,,,,,,,9.99894428253174,10.0000228881836,1950.41735839844,1950.41735839844,,,5.12585258483887,,1,0,0,0,0.0014495849609375,34.2131004333496,1,1,1,9.99987983703613,0,4232058272,9.999534034729,,,0.0441604774665601,0.0021007475318204,0.0441610302204357,0.00210076935311659,0.984636723995209,0.984775900840759,3.88735795021057,0.000118264193588402,30,1,200,0.00466492399573326,-1.99656283855438,0.534493446350098,1,,,,,,,,,,,,,,,,
,3890747716.63912,9.99990367889404,1600.35095214844,,,6,,,,3.89491802737971,,,100,,,,,,,,,,,,,,,,,,,,,,9.99919605255127,10.0001668930054,1600.35095214844,1600.35095214844,,,5.13094425201416,,1,0,0,0,0.0189971923828125,34.2131004333496,1,1,1,9.99995422363281,0,4232058176,9.99971084594727,,,0.0372377281221363,0.00177144097461437,0.0372382091389448,0.00177146019748997,0.984153091907501,0.984283924102783,3.88747382164001,0,30,1,200,0.00565454736351967,-1.68748474121094,0.454171031713486,1,,,,,,,,,,,,,,,,
,3890747817.14612,10.0000190734863,1250.26000976562,,,6,,,,3.89491802737971,,,100,,,,,,,,,,,,,,,,,,,,,,9.99910068511963,10.0000772476196,1250.26000976562,1250.26000976562,,,5.12749910354614,,1,0,0,0,0.0139617919921875,34.2131004333496,1,1,1,10.000262260437,0,4232058272,9.99964332580566,,,0.0303158462406106,0.00144214825718963,0.0303162263568615,0.00144216335526281,0.984627902507782,0.984763085842133,3.88746547698975,1.99769219761947E-5,30,1,200,0.00731915887445211,-1.36501514911652,0.365573436021805,1,,,,,,,,,,,,,,,,
,3890747915.69298,9.99983310699463,900.340454101562,,,6,,,,3.89491802737971,,,100,,,,,,,,,,,,,,,,,,,,,,9.99886131286621,9.99995708465576,900.340454101562,900.340454101562,,,5.12839365005493,,1,0,0,0,0.0201416015625,34.2131004333496,1,1,1,9.99991130828857,0,4232058400,9.99948863983154,,,0.0233950516478511,0.00111291987387691,0.0233953345392934,0.00111293122149362,0.984680354595184,0.984804570674896,3.88778495788574,,30,1,200,0.00796629581600428,-1.04954957962036,0.290348917245865,1,,,,,,,,,,,,,,,,
,3890748015.67557,10.0015034675598,550.06591796875,,,6,,,,3.89491802737971,,,100,,,,,,,,,,,,,,,,,,,,,,10.0010814666748,10.0021524429321,550.06591796875,550.06591796875,,,5.1200532913208,,1,0,0,0,0.0229644775390625,33.7243423461914,1,1,1,10.0014133453369,0,4232058464,10.0015550613403,,,0.0164645279618255,0.000783226999855394,0.0164647276168299,0.000783234949682155,0.984879612922668,0.985010802745819,3.88763475418091,0,30,1,200,0.00944850593805313,-0.73790979385376,0.201346963644028,1,,,,,,,,,,,,,,,,
,3890748113.90209,9.9993257522583,200.023971557617,,,6,,,,3.89491802737971,,,100,,,,,,,,,,,,,,,,,,,,,,9.99836730957031,9.99979972839356,200.023971557617,200.023971557617,,,5.1113543510437,,1,0,0,0,0.0014495849609375,34.2131004333496,1,1,1,10.0002841949463,0,4232058336,9.99876937866211,,,0.00954083883532972,0.000453861919208585,0.00954096087920666,0.00045386675160738,0.985120058059692,0.985264897346497,3.88732933998108,9.06261050204193E-7,30,1,200,0.010036263614893,-0.427343875169754,0.121267899870872,1,,,,,,,,,,,,,,,,
,3890748215.38601,10.0005345344543,-149.895538330078,,,6,,,,3.89491802737971,,,10,,,,,,,,,,,,,,,,,,,,,,9.99977874755859,10.0027751922607,-149.895538330078,-149.895538330078,,,5.11228942871094,,1,0,0,0,0.0176239013671875,34.2131004333496,1,1,1,10.0012903213501,0,4232058528,10.0011132558187,,,0.00260466423970448,0.000123910554466159,0.00260465983176687,0.000123910339331337,0.982348918914795,0.982351422309875,3.89600276947022,0.114030621945858,30,1,200,0.0613510683178902,-1.12069725990295,0.352817356586456,1,,,,,,,,,,,,,,,,
,3890748319.89896,10.0003428459167,-499.998718261719,,,6,,,,3.89491802737971,,,100,,,,,,,,,,,,,,,,,,,,,,9.99885940551758,10.0012769699097,-499.998718261719,-499.998718261719,,,5.11120462417603,,1,0,0,0,0.0228118896484375,34.2131004333496,1,1,1,10.0007410049438,0,4232058432,10.0000203450521,,,-0.0144369430197169,0.000686833105031784,-0.014436885980051,0.000686783717077,0.979972064495087,0.983713626861572,3.93757343292236,0,30,1,200,0.00577138038352132,-4.82263565063477,4.84474277496338,1,,,,,,,,,,,,,,,,
,3890748422.40986,10.0000109672546,-849.8203125,,,6,,,,3.89491802737971,,,100,,,,,,,,,,,,,,,,,,,,,,9.99922466278076,10.000391960144,-849.8203125,-849.8203125,,,5.09953451156616,,1,0,0,0,0.017242431640625,35.190616607666,1,1,1,10.0000104904175,0,4232058432,9.99982051849365,,,-0.0231122166532933,0.00109946887350958,-0.0231123750056364,0.0010994756194357,0.984456062316895,0.984502136707306,3.89053583145142,1.97244417667389,30,1,200,0.0107833696529269,-0.270069628953934,1.05913162231445,1,,,,,,,,,,,,,,,,
,3890748522.80767,9.99996662139893,-1200.0458984375,,,6,,,,3.89491802737971,,,100,,,,,,,,,,,,,,,,,,,,,,9.99903869628906,10.0002908706665,-1200.0458984375,-1200.0458984375,,,5.09732580184937,,1,0,0,0,0.0014495849609375,34.2131004333496,1,1,1,10.000171661377,0,4232058432,9.99970684051514,,,-0.0300506539085524,0.00142953313037487,-0.0300509348038516,0.0014295447311162,0.984590351581574,0.984670519828796,3.88916754722595,,30,1,200,0.00999115686863661,-0.353177905082703,1.37089431285858,1,,,,,,,,,,,,,,,,
,3890748623.43255,9.99997234344482,-1550.39392089844,,,6,,,,3.89491802737971,,,100,,,,,,,,,,,,,,,,,,,,,,9.99903774261475,10.0002346038818,-1550.39392089844,-1550.39392089844,,,5.09466457366943,,1,0,0,0,0.0220489501953125,34.2131004333496,1,1,1,10.000020980835,0,4232058208,9.99961185455322,,,-0.0369621363614785,0.00175832701007869,-0.0369625046512673,0.00175834216113835,0.984293580055237,0.984379589557648,3.88890624046326,0,30,1,200,0.00957642868161202,-0.434487193822861,1.68225395679474,1,,,,,,,,,,,,,,,,
,3890748723.65997,9.99976873397827,-1900.37475585938,,,6,,,,3.89491802737971,,,100,,,,,,,,,,,,,,,,,,,,,,9.99899387359619,10.0000772476196,-1900.37475585938,-1900.37475585938,,,5.09122467041016,,1,0,0,0,0.00152587890625,34.2131004333496,1,1,1,9.99981498718262,0,4232058176,9.99949035644531,,,-0.0438561117604582,0.00208626974153133,-0.0438565860232752,0.00208628893047158,0.984608650207519,0.984713971614838,3.88833165168762,0,30,1,200,0.00887371972203255,-0.526207089424133,1.99377679824829,1,,,,,,,,,,,,,,,,
,3890748824.3679,9.99958467483521,-2250.34326171875,,,6,,,,3.89491802737971,,,100,,,,,,,,,,,,,,,,,,,,,,9.99900722503662,10.0000991821289,-2250.34326171875,-2250.34326171875,,,5.08743095397949,,1,0,0,0,0.001373291015625,34.2131004333496,1,1,1,9.99964904785156,0,4232058240,9.99960880279541,,,-0.0507270704675926,0.0024131360322142,-0.0507276492745565,0.00241315944507538,0.984361410140991,0.984470963478088,3.88814806938171,1.97183871269226,30,1,200,0.00882638711482286,-0.599663078784943,2.29925346374512,1,,,,,,,,,,,,,,,,
,3890748926.46784,10.0002603530884,-2600.38525390625,,,6,,,,3.89491802737971,,,100,,,,,,,,,,,,,,,,,,,,,,9.99984836578369,10.0005350112915,-2600.38525390625,-2600.38525390625,,,5.09046220779419,,1,0,0,0,0.018768310546875,34.7018585205078,1,1,1,10.0006408691406,0,4232058176,10.0002151489258,,,-0.0576188212170487,0.00274097406868606,-0.0576194944347846,0.00274100099389707,0.984561264514923,0.984682261943817,3.88785171508789,,30,1,200,0.00875615980476141,-0.683930575847626,2.6164391040802,1,,,,,,,,,,,,,,,,
,3890749030.73532,9.99992752075195,-2950.24340820313,,,6,,,,3.89491802737971,,,100,,,,,,,,,,,,,,,,,,,,,,9.99898719787598,10.0001850128174,-2950.24340820313,-2950.24340820313,,,5.08726930618286,,1,0,0,0,0.00274658203125,34.7018585205078,1,1,1,10.000244140625,0,4232058240,9.99968509674072,,,-0.0644836696882409,0.00306754320235312,-0.0644844343531993,0.00306757376247453,0.984504997730255,0.984627783298492,3.88778519630432,0,30,1,200,0.00871098879724741,-0.771102547645569,2.91913747787476,1,,,,,,,,,,,,,,,,
,3890749136.01763,9.99974012374878,-3300.38354492188,,,6,,,,3.89491802737971,,,100,,,,,,,,,,,,,,,,,,,,,,9.9988260269165,9.99969005584717,-3300.38354492188,-3300.38354492188,,,5.08378887176514,,1,0,0,0,0.021209716796875,34.7018585205078,1,1,1,10.0000610351562,0,4232058336,9.99938507080078,,,-0.0713339870486811,0.00339342464966379,-0.0713348844784981,0.00339346049980521,0.984383523464203,0.984513103961945,3.88756322860718,0,30,1,200,0.00959110073745251,-0.851160287857056,3.23775243759155,1,,,,,,,,,,,,,,,,
,3890749240.98695,9.9998779296875,-3650.388671875,,,6,,,,3.89491802737971,,,100,,,,,,,,,,,,,,,,,,,,,,9.9990701675415,10.0000085830688,-3650.388671875,-3650.388671875,,,5.08361530303955,,1,0,0,0,0.014190673828125,34.2131004333496,1,1,1,10.0000505447388,0,4232058336,9.99956779479981,,,-0.0781746074733658,0.00371883781285743,-0.0781756023869026,0.00371887743211201,0.984413027763367,0.984546542167664,3.88746023178101,2.13231087400345E-5,30,1,200,0.00919138640165329,-0.935943424701691,3.53946423530579,1,,,,,,,,,,,,,,,,
,3890749345.64904,9.99993991851807,-4000.35717773438,,,6,,,,3.89491802737971,,,100,,,,,,,,,,,,,,,,,,,,,,9.99891471862793,10.0003910064697,-4000.35717773438,-4000.35717773438,,,5.08078861236572,,1,0,0,0,0.0226593017578125,35.190616607666,1,1,1,10.0000982284546,0,4232058464,9.9996410369873,,,-0.0850265448591076,0.00404481008623062,-0.0850276602033008,0.00404485468933609,0.984109699726105,0.984241783618927,3.88742899894714,5.72566652297974,30,1,200,0.0100813368335366,-1.02079951763153,3.85320138931274,1,,,,,,,,,,,,,,,,
,3890749451.40499,10.0003290176392,-4350.23974609375,,,6,,,,3.89491802737971,,,100,,,,,,,,,,,,,,,,,,,,,,9.9996919631958,10.000563621521,-4350.23974609375,-4350.23974609375,,,5.07618141174316,,1,0,0,0,0.0202178955078125,34.7018585205078,1,1,1,10.0009660720825,0,4232058400,10.0001586914062,,,-0.0918640880648834,0.00437005204331019,-0.091865240671057,0.00437009755120439,0.984529316425324,0.984667778015137,3.88735222816467,0,30,1,200,0.0119212390854955,-1.09693551063538,4.16281175613403,1,,,,,,,,,,,,,,,,
,3890749557.9087,9.99926233291626,-4700.4775390625,,,6,,,,3.89491802737971,,,100,,,,,,,,,,,,,,,,,,,,,,9.99808979034424,9.99994277954102,-4700.4775390625,-4700.4775390625,,,5.07599067687988,,1,0,0,0,0.0014495849609375,34.2131004333496,1,1,1,9.99890232086182,0,4232058272,9.99909553527832,,,-0.0987305012514473,0.00469670031893598,-0.0987317774044563,0.00469675068510575,0.984430015087128,0.984572052955627,3.88723182678223,0,30,1,200,0.0123784616589546,-1.18213331699371,4.47735500335693,1,,,,,,,,,,,,,,,,
,3890749664.15942,9.99913787841797,-4950.2138671875,,,6,,,,3.89491802737971,,,100,,,,,,,,,,,,,,,,,,,,,,9.99787139892578,9.99937152862549,-4950.2138671875,-4950.2138671875,,,5.06661605834961,,1,0,0,0,0.0014495849609375,34.7018585205078,1,1,1,9.99904155731201,0,4232058400,9.99876022338867,,,-0.103648044553253,0.00493062385302387,-0.103649419730619,0.00493067795085405,0.984540998935699,0.984690248966217,3.88706827163696,0,30,1,200,0.00418569007888436,-1.2435394525528,4.69742965698242,1,,,,,,,,,,,,,,,,
,3890749768.81934,9.99971389770508,-4600.36767578125,,,6,,,,3.89491802737971,,,100,,,,,,,,,,,,,,,,,,,,,,9.99833679199219,9.99935817718506,-4600.36767578125,-4600.36767578125,,,5.07151699066162,,1,0,0,0,0.0012969970703125,34.2131004333496,1,1,1,10.001091003418,0,4232058336,9.99896764755249,,,-0.096674796854995,0.004598909756587,-0.09667602706051,0.00459895859226017,0.984407424926758,0.984543025493622,3.88740038871765,0,30,1,200,0.00530122732743621,-1.1630322933197,4.38148784637451,1,,,,,,,,,,,,,,,,
,3890749874.50723,10.0010566711426,-4250.47265625,,,6,,,,3.89491802737971,,,100,,,,,,,,,,,,,,,,,,,,,,10.0000514984131,10.0015459060669,-4250.47265625,-4250.47265625,,,5.07124090194702,,1,0,0,0,0.0014495849609375,34.2131004333496,1,1,1,10.0008554458618,0,4232058368,10.0008281707764,,,-0.0897242266376067,0.00426826171412568,-0.0897253919871411,0.00426830775033478,0.984475970268249,0.984618484973907,3.88723063468933,0,30,1,200,0.00476663280278444,-1.08138513565063,4.06064748764038,1,,,,,,,,,,,,,,,,
,3890749980.57846,10.0000514984131,-3900.16137695313,,,6,,,,3.89491802737971,,,100,,,,,,,,,,,,,,,,,,,,,,9.99891376495361,10.0002174377441,-3900.16137695313,-3900.16137695313,,,5.07185316085815,,1,0,0,0,0.0194549560546875,34.7018585205078,1,1,1,10.0011892318726,0,4232058304,9.99979000091553,,,-0.0827707202976341,0.003937468942069,-0.0827717807095829,0.00393751087705434,0.984577655792236,0.984718382358551,3.88730216026306,1.97162425518036,30,1,200,0.00266699003987014,-0.995026111602783,3.74435567855835,1,,,,,,,,,,,,,,,,
,3890750087.08258,9.99971675872803,-3550.49877929687,,,6,,,,3.89491802737971,,,100,,,,,,,,,,,,,,,,,,,,,,9.99848461151123,9.99989032745361,-3550.49877929687,-3550.49877929687,,,5.05978870391846,,1,0,0,0,0.0014495849609375,34.2131004333496,1,1,1,9.99987411499023,0,4232058208,9.99929580688477,,,-0.0758305386672557,0.00360731808681366,-0.0758314716746542,0.00360735507301426,0.984615802764893,0.984749674797058,3.88749933242798,0,30,1,200,0.00250247144140303,-0.909603297710419,3.43908524513245,1,,,,,,,,,,,,,,,,
,3890750191.48514,9.99916791915894,-3200.4814453125,,,6,,,,3.89491802737971,,,100,,,,,,,,,,,,,,,,,,,,,,9.99772167205811,9.99935340881348,-3200.4814453125,-3200.4814453125,,,5.06886720657349,,1,0,0,0,0.0014495849609375,34.2131004333496,1,1,1,9.99898242950439,0,4232058336,9.99852828979492,,,-0.0688992979116,0.00327759635949729,-0.0689001336054285,0.00327762963291332,0.984547555446625,0.984676003456116,3.88763332366943,0,30,1,200,0.00147736736107618,-0.82931524515152,3.11820268630981,1,,,,,,,,,,,,,,,,
,3890750295.70111,9.99994707107544,-2850.40283203125,,,6,,,,3.89491802737971,,,100,,,,,,,,,,,,,,,,,,,,,,9.99862194061279,10.0001974105835,-2850.40283203125,-2850.40283203125,,,5.06857967376709,,1,0,0,0,0.00152587890625,34.7018585205078,1,1,1,10.0012722015381,0,4232058240,9.99945850372314,,,-0.0619625822963448,0.00294761185750702,-0.0619633473680525,0.00294764232411526,0.984545826911926,0.984676480293274,3.88757157325745,,30,1,200,-4.48126484116074E-5,-0.748818874359131,2.809321641922,1,,,,,,,,,,,,,,,,
,3890750399.9045,9.99924087524414,-2500.33642578125,,,6,,,,3.89491802737971,,,100,,,,,,,,,,,,,,,,,,,,,,9.99748039245606,9.99999713897705,-2500.33642578125,-2500.33642578125,,,5.06498718261719,,1,0,0,0,0.0139617919921875,34.2131004333496,1,1,1,9.99848461151123,0,4232058144,9.99863338470459,,,-0.0550315933092705,0.00261789887778952,-0.0550322503113207,0.00261792504549599,0.984565675258636,0.98469203710556,3.88769721984863,0,30,1,200,-0.00109230435919017,-0.667620956897736,2.48939180374146,1,,,,,,,,,,,,,,,,
,3890750503.43509,9.99983072280884,-2150.20874023438,,,6,,,,3.89491802737971,,,100,,,,,,,,,,,,,,,,,,,,,,9.99936580657959,10.0004987716675,-2150.20874023438,-2150.20874023438,,,5.06130123138428,,1,0,0,0,0.0171661376953125,34.2131004333496,1,1,1,9.99985218048096,0,4232058496,9.9999755859375,,,-0.0481018067732958,0.00228824432978697,-0.048102370874639,0.00228826681392226,0.984523236751556,0.984646558761597,3.88777542114258,,30,1,200,-0.00210114708170295,-0.58319753408432,2.17286491394043,1,,,,,,,,,,,,,,,,
,3890750605.55609,9.99997234344482,-1800.22802734375,,,6,,,,3.89491802737971,,,100,,,,,,,,,,,,,,,,,,,,,,9.99921321868897,9.99997425079346,-1800.22802734375,-1800.22802734375,,,5.06667947769165,,1,0,0,0,0.0162506103515625,34.7018585205078,1,1,1,10.0005989074707,0,4232058560,9.99947376251221,,,-0.041180551276489,0.00195899493646102,-0.0411810367172333,0.00195901437679197,0.98449182510376,0.984612464904785,3.88784503936768,0,30,1,200,-0.00361809157766402,-0.504433274269104,1.86203300952911,1,,,,,,,,,,,,,,,,
,3890750709.27882,9.99990320205688,-1450.39428710938,,,6,,,,3.89491802737971,,,100,,,,,,,,,,,,,,,,,,,,,,9.99897766113281,10.001015663147,-1450.39428710938,-1450.39428710938,,,5.06478023529053,,1,0,0,0,0.017242431640625,34.7018585205078,1,1,1,9.99938869476318,0,4232058336,10.000025177002,,,-0.0342607051506754,0.00162980818075559,-0.0342611034128547,0.0016298241168327,0.984622776508331,0.984743356704712,3.88787865638733,0.174655482172966,30,1,200,-0.00476210052147508,-0.419031798839569,1.54650282859802,1,,,,,,,,,,,,,,,,
,3890750813.04288,9.99941396713257,-1100.291015625,,,6,,,,3.89491802737971,,,100,,,,,,,,,,,,,,,,,,,,,,9.99824142456055,9.99941253662109,-1100.291015625,-1100.291015625,,,5.06255435943604,,1,0,0,0,0.0014495849609375,34.2131004333496,1,1,1,10.000244140625,0,4232058560,9.99871673583984,,,-0.0273384607801766,0.00130051231099033,-0.0273387637553085,0.00130052452198338,0.984591841697693,0.984702050685883,3.8881778717041,,30,1,200,-0.00591328740119934,-0.329736739397049,1.23552811145782,1,,,,,,,,,,,,,,,,
,3890750913.83684,9.99973201751709,-750.310302734375,,,6,,,,3.89491802737971,,,100,,,,,,,,,,,,,,,,,,,,,,9.99902534484863,10.0000114440918,-750.310302734375,-750.310302734375,,,5.06612110137939,,1,0,0,0,0.01434326171875,33.7243423461914,1,1,1,9.99990081787109,0,4232058272,9.99956455230713,,,-0.0204240427857747,0.000971586121011851,-0.0204242640232269,0.000971595072412056,0.984725534915924,0.984831869602203,3.8883261680603,,30,1,200,-0.00722944363951683,-0.253972500562668,0.922747790813446,1,,,,,,,,,,,,,,,,
,3890751014.7608,10.0003733634949,-400.439758300781,,,6,,,,3.89491802737971,,,100,,,,,,,,,,,,,,,,,,,,,,9.99928283691406,10.0007858276367,-400.439758300781,-400.439758300781,,,5.06566953659058,,1,0,0,0,0.016937255859375,34.7018585205078,1,1,1,10.0014638900757,0,4232058528,10.000100517273,,,-0.0134990230896943,0.000642155930422719,-0.0134991594938169,0.000642161486213272,0.984936654567719,0.985033392906189,3.88867259025574,5.72550106048584,30,1,200,-0.0082427840679884,-0.167056560516357,0.608243048191071,1,,,,,,,,,,,,,,,,
,3890751113.17733,9.99967670440674,-50.3978118896484,,,6,,,,3.89491802737971,,,100,,,,,,,,,,,,,,,,,,,,,,9.99821853637695,9.99999809265137,-50.3978118896484,-50.3978118896484,,,5.06690168380737,,1,0,0,0,0.022735595703125,34.2131004333496,1,1,1,10.0011348724365,0,4232058400,9.99912300109863,,,-0.0065753314570489,0.000312789996567739,-0.00657537912434638,0.000312792010385511,0.985404670238495,0.985460340976715,3.89025044441223,1.97237181663513,30,1,200,-0.00859181303530931,-0.0856764689087868,0.287261843681335,1,,,,,,,,,,,,,,,,
,3890751216.35088,9.99970579147339,299.729858398438,,,6,,,,3.89491802737971,,,10,,,,,,,,,,,,,,,,,,,,,,9.998366355896,9.99929523468018,299.729858398438,299.729858398438,,,5.06773900985718,,1,0,0,0,0.00152587890625,34.2131004333496,1,1,1,10.0008344650269,0,4232058400,9.99865074157715,,,0.000351047321139501,1.67310804935543E-5,0.000351122477514331,1.67323678260444E-5,0.936787903308868,0.938987135887146,3.8349609375,0,30,1,200,-0.0866143554449081,-0.251696437597275,-0.0511255152523518,1,,,,,,,,,,,,,,,,
,3890751320.92307,9.99980545043945,649.955444335938,,,6,,,,3.89491802737971,,,100,,,,,,,,,,,,,,,,,,,,,,9.99865627288818,10.0000114440918,649.955444335938,649.955444335938,,,5.07107782363892,,1,0,0,0,0.00152587890625,31.7693061828613,1,1,1,9.99997997283935,0,4232058304,9.99938106536865,,,0.0174345923885673,0.000829410432722806,0.0174344495789015,0.000829370668803753,0.982181191444397,0.984571874141693,3.92755770683289,0,30,1,200,-0.00832324288785458,-0.795323312282562,0.205245479941368,1,,,,,,,,,,,,,,,,
,3890751421.0942,10.0000185966492,1000.02197265625,,,6,,,,3.89491802737971,,,100,,,,,,,,,,,,,,,,,,,,,,9.99923038482666,10.0001764297485,1000.02197265625,1000.02197265625,,,5.06625699996948,,1,0,0,0,0.0142669677734375,34.2131004333496,1,1,1,10.0000400543213,0,4232058240,9.99973106384277,,,0.026093150381164,0.00124127250463651,0.0260934035172741,0.00124128290819264,0.984576463699341,0.984662294387817,3.88896727561951,0.000107918647699989,30,1,200,-0.00855634082108736,-1.18649101257324,0.310404032468796,1,,,,,,,,,,,,,,,,
,3890751521.57431,9.99989748001099,1350.22302246094,,,6,,,,3.89491802737971,,,100,,,,,,,,,,,,,,,,,,,,,,9.99883365631103,10.0001039505005,1350.22302246094,1350.22302246094,,,5.06987428665161,,1,0,0,0,0.01922607421875,34.7018585205078,1,1,1,10.0000677108765,0,4232058496,9.999560546875,,,0.0330216329745796,0.00157086769231693,0.0330219855433102,0.00157088207336434,0.984505534172058,0.984604060649872,3.88852715492249,5.7255859375,30,1,200,-0.00814822781831026,-1.49908852577209,0.391220420598984,1,,,,,,,,,,,,,,,,
,3890751622.13885,9.9999737739563,1699.9833984375,,,6,,,,3.89491802737971,,,100,,,,,,,,,,,,,,,,,,,,,,9.99898147583008,10.0002975463867,1699.9833984375,1699.9833984375,,,5.06695175170898,,1,0,0,0,0.02288818359375,34.7018585205078,1,1,1,10.0000686645508,0,4232058240,9.9996675491333,,,0.0399130019632123,0.00189869492051572,0.0399134307203937,0.0018987123091731,0.984542965888977,0.984645783901215,3.88839864730835,1.9440709365881E-5,30,1,200,-0.00820219703018665,-1.80985021591187,0.47139984369278,1,,,,,,,,,,,,,,,,
,3890751722.75237,9.99922513961792,2050.03759765625,,,6,,,,3.89491802737971,,,100,,,,,,,,,,,,,,,,,,,,,,9.99844551086426,9.99913883209229,2050.03759765625,2050.03759765625,,,5.05816459655762,,1,0,0,0,0.00152587890625,35.190616607666,1,1,1,9.99996948242188,0,4232058400,9.99860382080078,,,0.0467947063262106,0.00222605837848338,0.0467952256987886,0.00222607919205575,0.984687149524689,0.984801769256592,3.88806700706482,1.96653618331766E-5,30,1,200,-0.00776667566969991,-2.12918591499329,0.553465485572815,1,,,,,,,,,,,,,,,,
,3890751823.30548,10.0000982284546,2400.28759765625,,,6,,,,3.89491802737971,,,100,,,,,,,,,,,,,,,,,,,,,,9.99883842468262,10.0001850128174,2400.28759765625,2400.28759765625,,,5.06575107574463,,1,0,0,0,0.0140380859375,34.7018585205078,1,1,1,10.0003547668457,0,4232058336,9.99961261749268,,,0.0537038566731905,0.00255473627604892,0.0537044843519886,0.00255476133577383,0.984560489654541,0.984682619571686,3.88781809806824,0,30,1,200,-0.00754910008981824,-2.4429726600647,0.642042458057404,1,,,,,,,,,,,,,,,,
,3890751923.5696,10.0000004768372,2750.32958984375,,,6,,,,3.89491802737971,,,100,,,,,,,,,,,,,,,,,,,,,,9.99899673461914,10.0003004074097,2750.32958984375,2750.32958984375,,,5.06551170349121,,1,0,0,0,0.02105712890625,34.7018585205078,1,1,1,10.0001564025879,0,4232058368,9.99969253540039,,,0.0605712261664657,0.00288142309193512,0.0605719336448947,0.00288145142625848,0.98456484079361,0.984684944152832,3.88787889480591,0,30,1,200,-0.00835069082677364,-2.74730849266052,0.715545833110809,1,,,,,,,,,,,,,,,,
,3890752023.71597,10.0002903938293,3100.28588867188,,,6,,,,3.89491802737971,,,100,,,,,,,,,,,,,,,,,,,,,,9.99912452697754,10.0007247924805,3100.28588867188,3100.28588867188,,,5.06487989425659,,1,0,0,0,0.020599365234375,34.2131004333496,1,1,1,10.0000610351562,0,4232058176,9.99998416900635,,,0.0674213643073423,0.00320729034887856,0.0674221515542047,0.00320732199350876,0.984530448913574,0.984647870063782,3.88794851303101,2.08352321351413E-5,30,1,200,-0.00851207040250301,-3.0604875087738,0.801823198795319,1,,,,,,,,,,,,,,,,
,3890752127.70725,9.99975967407227,3450.43798828125,,,6,,,,3.89491802737971,,,100,,,,,,,,,,,,,,,,,,,,,,9.99870872497559,10.000205039978,3450.43798828125,3450.43798828125,,,5.06261968612671,,1,0,0,0,0.0014495849609375,34.2131004333496,1,1,1,10.0008106231689,0,4232058208,9.99962673187256,,,0.074259048208205,0.00353258512022648,0.074259961451833,0.00353262169295134,0.984180748462677,0.984304189682007,3.88769483566284,0,30,1,200,-0.00882148742675781,-3.36855626106262,0.880679726600647,1,,,,,,,,,,,,,,,,
,3890752234.60942,9.9998631477356,3800.45532226562,,,6,,,,3.89491802737971,,,100,,,,,,,,,,,,,,,,,,,,,,9.99844837188721,10.0004806518555,3800.45532226562,3800.45532226562,,,5.06198310852051,,1,0,0,0,0.0197601318359375,34.2131004333496,1,1,1,10.001277923584,0,4232058272,9.99952507019043,,,0.0811128354737532,0.00385860724578826,0.0811138054821476,0.00385864570902316,0.984512686729431,0.98464173078537,3.88760924339294,0,30,1,200,-0.00927938055247068,-3.68608689308167,0.962523102760315,1,,,,,,,,,,,,,,,,
,3890752341.10452,9.99985361099243,4150.26513671875,,,6,,,,3.89491802737971,,,100,,,,,,,,,,,,,,,,,,,,,,9.99904441833496,10.0001811981201,4150.26513671875,4150.26513671875,,,5.05439567565918,,1,0,0,0,0.0217437744140625,34.7018585205078,1,1,1,10.000039100647,0,4232058368,9.99962120056152,,,0.0879548646061549,0.00418408482009983,0.0879559046524017,0.00418412635975818,0.984564423561096,0.984687745571137,3.88778352737427,0,30,1,200,-0.0118467435240746,-3.991131067276,1.05330109596252,1,,,,,,,,,,,,,,,,
,3890752448.76748,9.99991798400879,4500.3310546875,,,6,,,,3.89491802737971,,,100,,,,,,,,,,,,,,,,,,,,,,9.99907112121582,10.0001411437988,4500.3310546875,4500.3310546875,,,5.06207418441772,,1,0,0,0,0.00152587890625,36.6568908691406,1,1,1,10.0002527236938,0,4232058304,9.99954433441162,,,0.0948062175412733,0.00451000976429644,0.0948073841693954,0.00451005613157299,0.984573245048523,0.984705030918121,3.88754725456238,0,30,1,200,-0.0127301346510649,-4.30269145965576,1.12810492515564,1,,,,,,,,,,,,,,,,
,3890752555.00773,10.0002589225769,4850.458984375,,,6,,,,3.89491802737971,,,100,,,,,,,,,,,,,,,,,,,,,,9.9985523223877,10.0005187988281,4850.458984375,4850.458984375,,,5.06155920028687,,1,0,0,0,0.0014495849609375,34.7018585205078,1,1,1,9.99999904632568,0,4232058464,9.99961357116699,,,0.101671298861615,0.00483659856485225,0.101672558770495,0.00483664875210892,0.984408259391785,0.984538078308105,3.88756418228149,,30,1,200,-0.0108525035902858,-4.6092643737793,1.21134424209595,1,,,,,,,,,,,,,,,,
,3890752659.7638,9.99981355667114,4800.17138671875,,,6,,,,3.89491802737971,,,100,,,,,,,,,,,,,,,,,,,,,,9.99819374084473,10.0001001358032,4800.17138671875,4800.17138671875,,,5.05807781219482,,1,0,0,0,0.0139617919921875,34.7018585205078,1,1,1,10.0014333724976,0,4232058240,9.99929904937744,,,0.100654667726296,0.0047882224502104,0.100655938847261,0.00478827273649129,0.984599471092224,0.984738111495972,3.88736367225647,0,30,1,200,-0.00379723310470581,-4.56066846847534,1.20616960525513,1,,,,,,,,,,,,,,,,
,3890752763.89138,9.99987459182739,4450.28857421875,,,6,,,,3.89491802737971,,,100,,,,,,,,,,,,,,,,,,,,,,9.99876499176025,9.999924659729,4450.28857421875,4450.28857421875,,,5.06091356277466,,1,0,0,0,0.00152587890625,34.7018585205078,1,1,1,10.000111579895,0,4232058144,9.99942588806152,,,0.0936930527094384,0.00445705998997072,0.0936941958346712,0.0044571055167721,0.984491765499115,0.984620332717896,3.88761734962463,1.41819270993437E-6,30,1,200,-0.00432979874312878,-4.2504301071167,1.12321054935455,1,,,,,,,,,,,,,,,,
,3890752867.73813,9.99866342544556,4100.33251953125,,,6,,,,3.89491802737971,,,100,,,,,,,,,,,,,,,,,,,,,,9.99815940856934,9.99872589111328,4100.33251953125,4100.33251953125,,,5.05894136428833,,1,0,0,0,0.019073486328125,34.7018585205078,1,1,1,9.99916744232178,0,4232058336,9.99847602844238,,,0.0867507619923558,0.00412680615891152,0.0867517986871791,0.00412684752150155,0.984517276287079,0.984642267227173,3.88772654533386,5.7252345085144,30,1,200,-0.00276572955772281,-3.93465209007263,1.03652703762054,1,,,,,,,,,,,,,,,,
,3890752972.3275,10.0009217262268,3750.33935546875,,,6,,,,3.89491802737971,,,100,,,,,,,,,,,,,,,,,,,,,,10.0001516342163,10.0013160705566,3750.33935546875,3750.33935546875,,,5.05951833724976,,1,0,0,0,0.013580322265625,34.2131004333496,1,1,1,10.0012083053589,0,4232058208,10.000722694397,,,0.0797982710208121,0.00379607783461533,0.0797992388448591,0.00379611657837329,0.984407007694244,0.984530746936798,3.88773655891418,INF,30,1,200,-0.0026375709567219,-3.62227630615234,0.957910895347595,1,,,,,,,,,,,,,,,,
,3890753075.55549,9.99951696395874,3400.40771484375,,,6,,,,3.89491802737971,,,100,,,,,,,,,,,,,,,,,,,,,,9.99800205230713,9.99991130828857,3400.40771484375,3400.40771484375,,,5.05748844146729,,1,0,0,0,0.0014495849609375,35.6793746948242,1,1,1,9.99912261962891,0,4232058272,9.99902095794678,,,0.0728657594035179,0.0034662894722922,0.0728666258400756,0.00346632402391005,0.984463155269623,0.984587371349335,3.88773488998413,0,30,1,200,-0.00182290410157293,-3.3060028553009,0.872574746608734,1,,,,,,,,,,,,,,,,
,3890753180.29487,10.000702381134,3050.36572265625,,,6,,,,3.89491802737971,,,100,,,,,,,,,,,,,,,,,,,,,,9.99973201751709,10.0016002655029,3050.36572265625,3050.36572265625,,,5.05664682388306,,1,0,0,0,0.01373291015625,34.2131004333496,1,1,1,10.0002374649048,0,4232056832,10.0007202148437,,,0.0659239748658601,0.00313606503541166,0.0659247565659488,0.00313609632504235,0.984400928020477,0.984521925449371,3.88781547546387,1.40949168780935E-6,30,1,200,-0.000969714485108852,-2.98595476150513,0.790275573730469,1,,,,,,,,,,,,,,,,
,3890753283.59493,9.99975681304932,2700.39721679687,,,6,,,,3.89491802737971,,,100,,,,,,,,,,,,,,,,,,,,,,9.99871444702148,9.99936771392822,2700.39721679687,2700.39721679687,,,5.05540609359741,,1,0,0,0,0.002288818359375,34.2131004333496,1,1,1,10.0004358291626,0,4232058432,9.99906730651855,,,0.0590033521519682,0.00280684185431288,0.059004059411892,0.00280686994793813,0.984483957290649,0.984611928462982,3.88763332366943,0,30,1,200,0.00159371155314147,-2.67473554611206,0.714765012264252,1,,,,,,,,,,,,,,,,
,3890753386.29985,10.0010738372803,2350.30615234375,,,6,,,,3.89491802737971,,,100,,,,,,,,,,,,,,,,,,,,,,10.0000581741333,10.0016212463379,2350.30615234375,2350.30615234375,,,5.05193901062012,,1,0,0,0,0.0139617919921875,34.7018585205078,1,1,1,10.0008039474487,0,4232058560,10.0008543014526,,,0.0520699401080871,0.00247700885423492,0.0520705740068748,0.00247703404987017,0.984596073627472,0.98472660779953,3.88758826255798,0,30,1,200,0.0029171328060329,-2.35443544387817,0.62266606092453,1,,,,,,,,,,,,,,,,
,3890753486.79595,9.99927949905395,2000.48461914062,,,6,,,,3.89491802737971,,,100,,,,,,,,,,,,,,,,,,,,,,9.99840927124023,9.9996395111084,2000.48461914062,2000.48461914062,,,5.0606746673584,,1,0,0,0,0.0014495849609375,34.2131004333496,1,1,1,9.99918460845947,0,4232058240,9.99907684326172,,,0.0451523289372009,0.00214793107189038,0.0451528657669042,0.00214795258522469,0.984645962715149,0.984768450260162,3.88782715797424,0,30,1,200,0.00434567220509052,-2.03951692581177,0.548759460449219,1,,,,,,,,,,,,,,,,
,3890753589.17781,9.99962615966797,1650.40600585938,,,6,,,,3.89491802737971,,,100,,,,,,,,,,,,,,,,,,,,,,9.99861145019531,10.0000581741333,1650.40600585938,1650.40600585938,,,5.05827569961548,,1,0,0,0,0.00152587890625,34.2131004333496,1,1,1,9.99948978424072,0,4232058240,9.99925575256348,,,0.03822986560705,0.00181863561071461,0.0382303465178689,0.00181865490828327,0.984205901622772,0.984330952167511,3.88765120506287,0,30,1,200,0.00568277295678854,-1.72509026527405,0.462911546230316,1,,,,,,,,,,,,,,,,
,3890753691.15889,9.99995279312134,1300.33947753906,,,6,,,,3.89491802737971,,,100,,,,,,,,,,,,,,,,,,,,,,9.99930858612061,10.0003776550293,1300.33947753906,1300.33947753906,,,5.05810880661011,,1,0,0,0,0.00152587890625,34.7018585205078,1,1,1,9.99977207183838,0,4232058528,9.99983921051025,,,0.0313090584705666,0.00148939503202484,0.0313094400091834,0.00148941022287522,0.9846550822258,0.984785079956055,3.88761568069458,1.97170376777649,30,1,200,0.00701530976220965,-1.41495609283447,0.384118676185608,1,,,,,,,,,,,,,,,,
,3890753790.80924,9.99922513961792,950.456726074219,,,6,,,,3.89491802737971,,,100,,,,,,,,,,,,,,,,,,,,,,9.99802398681641,9.99975681304932,950.456726074219,950.456726074219,,,5.05679225921631,,1,0,0,0,0.0214385986328125,34.7018585205078,1,1,1,10.0004262924194,0,4232058528,9.99875812530518,,,0.0243881432875578,0.00116016070339251,0.0243884367298644,0.00116017243606607,0.984726190567017,0.984852373600006,3.88774085044861,0,30,1,200,0.00829589739441872,-1.10481679439545,0.293475329875946,1,,,,,,,,,,,,,,,,
,3890753891.91681,9.99939489364624,600.353515625,,,6,,,,3.89491802737971,,,100,,,,,,,,,,,,,,,,,,,,,,9.99846363067627,10.0003261566162,600.353515625,600.353515625,,,5.05815553665161,,1,0,0,0,0.00152587890625,35.190616607666,1,1,1,10.0003261566162,0,4232058176,9.99951248168945,,,0.0174659378216254,0.000830865894640667,0.0174661486739455,0.000830874307553445,0.984819710254669,0.984948456287384,3.8876895904541,,30,1,200,0.00939737167209387,-0.782282829284668,0.215008869767189,1,,,,,,,,,,,,,,,,
,3890753990.68068,9.99870729446411,250.091186523438,,,6,,,,3.89491802737971,,,100,,,,,,,,,,,,,,,,,,,,,,9.99772644042969,9.99870586395264,250.091186523438,250.091186523438,,,5.05878973007202,,1,0,0,0,0.0014495849609375,34.7018585205078,1,1,1,9.99930286407471,0,4232058176,9.99817581176758,,,0.0105371075292833,0.000501254092160768,0.0105372320098418,0.000501259072045122,0.985186338424683,0.985313653945923,3.88781499862671,,30,1,200,0.0103312712162733,-0.475051164627075,0.131680905818939,1,,,,,,,,,,,,,,,,
,3890754060.93643,9.99994277954102,0.244887337088585,,,6,,,,3.89491802737971,,,100,,,,,,,,,,,,,,,,,,,,,,9.99887275695801,10.0001430511475,0.244887337088585,0.244887337088585,,,5.06079149246216,,1,0,0,0,0.0170135498046875,34.7018585205078,1,1,1,10.001012802124,0,4232058464,9.9996265411377,,,0.0055891345985901,0.000265876080509836,0.00558919979897621,0.000265878700247631,0.985459268093109,0.985584378242493,3.88793992996216,0,30,1,200,0.0102623850107193,-0.24297359585762,0.0754486843943596,1,,,,,,,,,,,,,,,,