File: Data/Susceptibility/Eu5In2Sb6_b_TBe339_17p17mg_b_102422.dat
[Header]
; MPMS3 Data File (default extension .dat)
; Copyright (c) 2007, Quantum Design, Inc. All rights reserved.
TITLE,
FILEOPENTIME,3875795734.05684,10/24/2022,5:55 pm
BYAPP,MPMS3 w/ AC,1.0,1.1
INFO,MPMS3 Measurement Release 1.1.16 Build 419, MultiVu Release 2.3.4.15,APPNAME
INFO,Linear Motor Servo Controller,MOTOR_MODULE_NAME
INFO,3101-100 F0,MOTOR_HW_VERSION
INFO,MMC1118,MOTOR_SERIAL_NUMBER
INFO,01.04.28,MOTOR_SOFTWARE_VERSION
INFO,Quantum Design Squid Module,SQUID_MODULE_NAME
INFO,3101-501 B0,SQUID_HW_VERSION
INFO,SQM313,SQUID_SERIAL_NUMBER
INFO,01.03.04,SQUID_SOFTWARE_VERSION
INFO,Quantum Design VSM Oven,OVEN_MODULE_NAME
INFO,3101-201 A3,OVEN_HW_VERSION
INFO,OVB345,OVEN_SERIAL_NUMBER
INFO,01.07.07,OVEN_SOFTWARE_VERSION
INFO,SQUID AC,AC_MODULE_NAME
INFO,3101-401 G0,AC_HW_VERSION
INFO,SAC210,AC_SERIAL_NUMBER
INFO,SQUID AC 00.95.07,AC_SOFTWARE_VERSION
INFO,TCI318,COIL_SERIAL_NUMBER
INFO,0,MOMENT_UNITS
INFO,Eu5In2Sb6,SAMPLE_MATERIAL
INFO,Eu5In2Sb6_b_TBe339_17p17mg_b_102422,SAMPLE_COMMENT
INFO,17.17,SAMPLE_MASS
INFO,,SAMPLE_VOLUME
INFO,,SAMPLE_MOLECULAR_WEIGHT
INFO,,SAMPLE_SIZE
INFO,,SAMPLE_SHAPE
INFO,Straw,SAMPLE_HOLDER
INFO,Standard,SAMPLE_HOLDER_DETAIL
INFO,67.68,SAMPLE_OFFSET
DATATYPE,COMMENT,1
DATATYPE,TIME,2
STARTUPAXIS,X,2
STARTUPAXIS,Y1,5
FIELDGROUP, VSM,2,3,4,5,6,8,9,10,11,14,15
FIELDGROUP, DC, 2,3,4,14,56,57,58,59,60,61,62,63,64,65,66,67,68,69
FIELDGROUP, AC, 2,3,4,11,16,17,18,19,20,21,22,23,24,25,26,27,28,29,30
STARTUPGROUP, All
[Data]
Comment,Time Stamp (sec),Temperature (K),Magnetic Field (Oe),Moment (emu),M. Std. Err. (emu),Transport Action,Averaging Time (sec),Frequency (Hz),Peak Amplitude (mm),Center Position (mm),Lockin Signal' (V),Lockin Signal (V),Range,M. Quad. Signal (emu),AC Moment (emu),AC M. Std Err. (emu),AC Phase (deg),AC Phase Std. Err. (deg),AC Susceptibility (emu/Oe),AC Suscept. Std Err. (emu/Oe),AC X' (emu/Oe),AC X' Std Err. (emu/Oe),AC X'' (emu/Oe),AC X'' Std Err. (emu/Oe),AC Drive (Oe),AC Frequency (Hz),AC Averaging Time (sec),AC Cycles,AC Range,AC Measure Type,AC Signal' (V),AC Signal'' (V),AC Trim Coil Ratio,AC Trim Coil Phase,Min. Temperature (K),Max. Temperature (K),Min. Field (Oe),Max. Field (Oe),Mass (grams),Motor Lag (deg),Pressure (Torr),Measure Count,Measurement Number,SQUID Status (code),Motor Status (code),Measure Status (code),Motor Current (amps),Motor Temp. (C),Temp. Status (code),Field Status (code),Chamber Status (code),Chamber Temp (K),Redirection State,Evercool Status,Average Temp (K),Rotation Angle (deg),Rotator state,DC Moment Fixed Ctr (emu),DC Moment Err Fixed Ctr (emu),DC Moment Free Ctr (emu),DC Moment Err Free Ctr (emu),DC Fixed Fit,DC Free Fit,DC Calculated Center (mm),DC Calculated Center Err (mm),DC Scan Length (mm),DC Scan Time (s),DC Number of Points,DC Squid Drift,DC Min V (V),DC Max V (V),DC Scans per Measure,Map 01,Map 02,Map 03,Map 04,Map 05,Map 06,Map 07,Map 08,Map 09,Map 10,Map 11,Map 12,Map 13,Map 14,Map 15,Map 16
,3875797313.59106,2.00077319145203,1000.13214111328,,,3,,,,32.4248886108398,,,,,,,,,,,,,,,,,,,,,,,,,2.00077319145203,2.00077319145203,1000.13214111328,1000.13214111328,,,2.77431559562683,,0,,,,,,5,1,1,2.00077319145203,0,0,0,,,,,,,,,,,,,,,,,,,,,,,,,,,,,,,,,
,3875797650.80861,3.1409627199173,1000.13214111328,,,6,,,,32.4248886108398,,,10,,,,,,,,,,,,,,,,,,,,,,3.11989545822144,3.15944910049438,1000.13214111328,1000.13214111328,,,3.34271788597107,,1,0,0,0,0.013885498046875,31.7693061828613,6,1,1,3.16202998161316,0,2084574912,3.137082862854,,,0.0103734111555889,0.000517514528180616,0.0103742573489605,0.000517517194610732,0.977092862129211,0.980713486671448,32.4714050292969,0,30,4,200,-0.000291046511847526,-4.31138372421265,0.609703004360199,1,,,,,,,,,,,,,,,,
,3875797974.99088,4.58189463615417,1000.13214111328,,,6,,,,32.4299050431819,,,10,,,,,,,,,,,,,,,,,,,,,,4.55926704406738,4.60147571563721,1000.13214111328,1000.13214111328,,,3.9258770942688,,1,0,0,0,0.013885498046875,31.7693061828613,6,1,1,4.60452222824097,0,2084574592,4.57782754898071,,,0.0102056915398006,0.000509342488602297,0.0102106182304727,0.000509355830828955,0.964066207408905,0.980528354644775,32.543586730957,5.29475736618042,30,4,200,-0.000496932480018586,-4.19628143310547,0.647055983543396,1,,,,,,,,,,,,,,,,
,3875798290.96852,6.04592108726502,1000.13214111328,,,6,,,,32.4299050431819,,,10,,,,,,,,,,,,,,,,,,,,,,6.02406597137451,6.06700801849365,1000.13214111328,1000.13214111328,,,4.3537974357605,,1,0,0,0,0.013885498046875,30.7917900085449,6,1,1,6.06901025772095,0,2084574912,6.04238362312317,,,0.00989246071958108,0.000494127467826213,0.00990586075409133,0.000494160346710981,0.945429921150207,0.979800462722778,32.6207122802734,5.29086494445801,30,4,200,-0.000464060460217297,-4.08304214477539,0.619214594364166,1,,,,,,,,,,,,,,,,
,3875798608.56674,7.5480387210846,1000.13214111328,,,6,,,,32.4299050431819,,,10,,,,,,,,,,,,,,,,,,,,,,7.52614498138428,7.56719779968262,1000.13214111328,1000.13214111328,,,4.68397188186646,,1,0,0,0,0.013885498046875,31.7693061828613,6,1,1,7.56993246078491,0,2084574784,7.54412240982056,,,0.00972182200705095,0.000486047049472945,0.00974412550966957,0.000486100698971083,0.930758059024811,0.978939592838287,32.6781959533691,0.502956449985504,30,4,200,6.19950867530861E-7,-4.00118923187256,0.630366802215576,1,,,,,,,,,,,,,,,,
,3875798925.96208,9.06830406188965,1000.13214111328,,,6,,,,32.4299050431819,,,10,,,,,,,,,,,,,,,,,,,,,,9.04503059387207,9.08892822265625,1000.13214111328,1000.13214111328,,,4.94714832305908,,1,0,0,0,0.013885498046875,31.2805480957031,6,1,1,9.09157752990723,0,2084574688,9.06591596603394,,,0.0115011219932495,0.000574374772396819,0.0115144830605018,0.000574406641531819,0.948882758617401,0.979870736598968,32.606746673584,0.547108590602875,30,4,200,9.75273360381834E-5,-4.78229331970215,0.791072010993958,1,,,,,,,,,,,,,,,,
,3875799251.84919,10.6342329978943,1000.13214111328,,,6,,,,32.4299050431819,,,100,,,,,,,,,,,,,,,,,,,,,,10.6099071502686,10.6546068191528,1000.13214111328,1000.13214111328,,,5.1646900177002,,1,0,0,0,0.013885498046875,31.2805480957031,6,1,1,10.65855884552,0,2084574784,10.6322082519531,,,0.0136321314947944,0.000680393505566173,0.0136396475551415,0.000680413551724795,0.962270975112915,0.980482041835785,32.5514221191406,0.136806935071945,30,4,200,2.88939882011618E-5,-0.567499697208405,0.0903305411338806,1,,,,,,,,,,,,,,,,
,3875799569.57994,12.1671094894409,1000.13214111328,,,6,,,,32.4299050431819,,,100,,,,,,,,,,,,,,,,,,,,,,12.1456289291382,12.1886234283447,1000.13214111328,1000.13214111328,,,5.33527660369873,,1,0,0,0,0.013885498046875,31.2805480957031,6,1,1,12.1898317337036,0,2084574464,12.1671951293945,,,0.0160435924946262,0.000800513083827368,0.0160475247858897,0.000800523891212056,0.971227288246155,0.980894923210144,32.5108833312988,5.2960991859436,30,4,200,3.05175108223921E-5,-0.665806829929352,0.105990998446941,1,,,,,,,,,,,,,,,,
,3875799902.90039,13.781843662262,1000.13214111328,,,6,,,,32.4349248774724,,,100,,,,,,,,,,,,,,,,,,,,,,13.7583332061768,13.800802230835,1000.13214111328,1000.13214111328,,,5.47949361801147,,1,0,0,0,0.013885498046875,31.2805480957031,6,1,1,13.8053541183472,0,2084574848,13.7801064491272,,,0.0192564937066035,0.000960634538477352,0.01925732508491,0.000960637838928391,0.979183733463287,0.981188476085663,32.4684677124023,0,30,4,200,0.000176312969415449,-0.791617751121521,0.122692920267582,1,,,,,,,,,,,,,,,,
,3875800219.73206,15.3486638069153,1000.13214111328,,,6,,,,32.4349248774724,,,100,,,,,,,,,,,,,,,,,,,,,,15.3183526992798,15.3766136169434,1000.13214111328,1000.13214111328,,,5.56243896484375,,1,0,0,0,0.013885498046875,31.2805480957031,2,1,1,15.3789749145508,0,2084575072,15.3566442489624,,,0.0199494627902715,0.000995160810252077,0.0199494628931369,0.000995160773515778,0.981397271156311,0.981399536132813,32.4338340759277,,30,4,200,5.10583959112409E-5,-0.817657709121704,0.127429723739624,1,,,,,,,,,,,,,,,,
,3875800535.88315,16.9742746353149,1000.13214111328,,,6,,,,32.4349248774724,,,100,,,,,,,,,,,,,,,,,,,,,,16.9501037597656,16.9964332580566,1000.13214111328,1000.13214111328,,,5.61011266708374,,1,0,0,0,0.0139617919921875,30.7917900085449,2,1,1,16.9984455108643,0,2084574976,16.9731519699097,,,0.0189799318434373,0.000946799279664353,0.0189799352902906,0.000946799237131517,0.981263756752014,0.981275856494904,32.4323921203613,,30,4,200,3.95729293813929E-5,-0.776910185813904,0.122453950345516,1,,,,,,,,,,,,,,,,
,3875800851.22971,18.5356616973877,1000.13214111328,,,6,,,,32.4349248774724,,,100,,,,,,,,,,,,,,,,,,,,,,18.5123767852783,18.5567836761475,1000.13214111328,1000.13214111328,,,5.68538475036621,,1,0,0,0,0.013885498046875,31.2805480957031,2,1,1,18.5589466094971,0,2084574656,18.5345914840698,,,0.0180151349584189,0.000898672816655669,0.018015137817372,0.000898672753728041,0.981155276298523,0.981167376041412,32.4323806762695,,30,4,200,3.60484918928705E-5,-0.746739685535431,0.117418505251408,1,,,,,,,,,,,,,,,,
,3875801167.12854,20.0004024505615,1000.13214111328,,,6,,,,32.4349248774724,,,100,,,,,,,,,,,,,,,,,,,,,,19.9997787475586,20.0007228851318,1000.13214111328,1000.13214111328,,,5.75692129135132,,1,0,0,0,0.013885498046875,31.2805480957031,5,1,1,20.0003356933594,0,2084574816,20.0001636505127,,,0.017143825135831,0.000855209466138802,0.0171438268193175,0.000855209440828153,0.981071829795837,0.981078565120697,32.4330215454102,0.152434885501862,30,4,200,6.11227296758443E-5,-0.70835292339325,0.103763766586781,1,,,,,,,,,,,,,,,,
,3875801902.22764,3.09548187255859,1000.13214111328,,,6,,,,32.4087066650391,,,100,,,,,,,,,,,,,,,,,,,,,,3.07407188415527,3.11331844329834,1000.13214111328,1000.13214111328,,,3.1885097026825,,1,0,0,0,0.014801025390625,31.2805480957031,6,1,1,3.11689186096191,0,2084574720,3.09135563373566,,,0.0103748586515803,0.000517632769699369,0.0103766564976343,0.000517638310607387,0.973490178585053,0.980562686920166,32.4765472412109,0,30,4,200,4.01459728891496E-5,-0.423780679702759,0.0681453943252563,1,,,,,,,,,,,,,,,,
,3875802218.19984,4.49335837364197,1000.13214111328,,,6,,,,32.4087066650391,,,100,,,,,,,,,,,,,,,,,,,,,,4.47140073776245,4.51415252685547,1000.13214111328,1000.13214111328,,,3.79073858261108,,1,0,0,0,0.013885498046875,31.2805480957031,6,1,1,4.51531600952148,0,2084574688,4.49053845405579,,,0.0102242157457943,0.000510581334572593,0.0102356757931043,0.000510611407482888,0.949801921844482,0.979993760585785,32.5820045471191,3.88702828786336E-5,30,4,200,4.20871037931647E-5,-0.421705722808838,0.0638759732246399,1,,,,,,,,,,,,,,,,
,3875802534.98657,5.96075868606567,1000.13214111328,,,6,,,,32.4087066650391,,,100,,,,,,,,,,,,,,,,,,,,,,5.93910264968872,5.97989463806152,1000.13214111328,1000.13214111328,,,4.24824237823486,,1,0,0,0,0.013885498046875,30.3030319213867,6,1,1,5.98241472244263,0,2084574624,5.95723705291748,,,0.00992829336045171,0.000496772967768277,0.00995949629696549,0.000496849050927792,0.919937312602997,0.978528082370758,32.6990814208984,8.24594462756067E-5,30,4,200,3.51569360645954E-5,-0.414398789405823,0.0692748725414276,1,,,,,,,,,,,,,,,,
,3875802858.79551,7.48842215538025,1000.13214111328,,,6,,,,32.413715255507,,,100,,,,,,,,,,,,,,,,,,,,,,7.46519756317139,7.50848388671875,1000.13214111328,1000.13214111328,,,4.60294914245605,,1,0,0,0,0.013885498046875,31.2805480957031,6,1,1,7.51164674758911,0,2084574880,7.48524041175842,,,0.0096773021286802,0.000485314731568582,0.00973034280181192,0.000485437993010863,0.895546793937683,0.976628243923187,32.7970504760742,2.96457310469123E-5,30,4,200,6.65958796162158E-5,-0.40963751077652,0.0638870075345039,1,,,,,,,,,,,,,,,,
,3875803174.44648,9.00029134750366,1000.13214111328,,,6,,,,32.413715255507,,,100,,,,,,,,,,,,,,,,,,,,,,8.97636890411377,9.02190971374512,1000.13214111328,1000.13214111328,,,4.87860774993897,,1,0,0,0,0.013885498046875,31.2805480957031,6,1,1,9.02421379089356,0,2084574880,8.99797801971436,,,0.0114325551965784,0.000571819845686585,0.0114637638472036,0.000571891438771579,0.924877822399139,0.978612303733826,32.6847801208496,0,30,4,200,8.57953637023456E-5,-0.471251755952835,0.0737462490797043,1,,,,,,,,,,,,,,,,
,3875803491.49818,10.5242228507996,1000.13214111328,,,6,,,,32.413715255507,,,100,,,,,,,,,,,,,,,,,,,,,,10.5004377365112,10.5446624755859,1000.13214111328,1000.13214111328,,,5.10228872299194,,1,0,0,0,0.013885498046875,31.2805480957031,6,1,1,10.5480079650879,0,2084574656,10.5218923568726,,,0.0134800769460234,0.000673328505128679,0.01349834697117,0.000673374108745215,0.945416450500488,0.97974306344986,32.6044807434082,4.19725751876831,30,4,200,0.000106903418782167,-0.565033376216888,0.0863394662737846,1,,,,,,,,,,,,,,,,
,3875803807.18297,12.0505757331848,1000.13214111328,,,6,,,,32.413715255507,,,100,,,,,,,,,,,,,,,,,,,,,,12.0269412994385,12.0713901519775,1000.13214111328,1000.13214111328,,,5.28321504592895,,1,0,0,0,0.013885498046875,30.7917900085449,6,1,1,12.0742101669312,0,2084574784,12.0486289024353,,,0.0158536506562917,0.000791346946579481,0.0158639154459267,0.000791371154781761,0.959829747676849,0.980467081069946,32.5458335876465,,30,4,200,0.000123114834423177,-0.659067511558533,0.104070618748665,1,,,,,,,,,,,,,,,,
,3875804123.0511,13.5704979896545,1000.13214111328,,,6,,,,32.413715255507,,,100,,,,,,,,,,,,,,,,,,,,,,13.5520830154419,13.5866069793701,1000.13214111328,1000.13214111328,,,5.42565155029297,,1,0,0,0,0.0139617919921875,31.2805480957031,6,1,1,13.5889129638672,0,2084574784,13.5707518577576,,,0.018770670779249,0.000936567394735496,0.018774939789246,0.000936578468166567,0.97185081243515,0.980987787246704,32.4918441772461,0,30,4,200,0.000133699402795173,-0.771953105926514,0.119175903499126,1,,,,,,,,,,,,,,,,
,3875804447.57094,15.1937170028687,1000.13214111328,,,6,,,,32.4187377475253,,,100,,,,,,,,,,,,,,,,,,,,,,15.1297769546509,15.2460441589355,1000.13214111328,1000.13214111328,,,5.5608696937561,,1,0,0,0,0.013885498046875,31.7693061828613,6,1,1,15.2576570510864,0,2084574592,15.1691673278809,,,0.0200393304982009,0.000999652685294029,0.0200395180185286,0.000999653559649455,0.980931341648102,0.981381356716156,32.4342384338379,1,30,4,200,-8.88477825355949E-6,-0.827251672744751,0.122739069163799,1,,,,,,,,,,,,,,,,
,3875804763.5626,16.8982200622559,1000.13214111328,,,6,,,,32.4187377475253,,,100,,,,,,,,,,,,,,,,,,,,,,16.8739185333252,16.9187793731689,1000.13214111328,1000.13214111328,,,5.58121967315674,,1,0,0,0,0.013885498046875,31.2805480957031,2,1,1,16.9225215911865,0,2084574752,16.8956195831299,,,0.0190219268109858,0.000948900361156927,0.0190220612651115,0.000948900906669301,0.980904817581177,0.981247842311859,32.432300567627,0,30,4,200,4.1274142859038E-5,-0.782930850982666,0.118530102074146,1,,,,,,,,,,,,,,,,
,3875805080.81341,18.4719533920288,1000.13214111328,,,6,,,,32.4187377475253,,,100,,,,,,,,,,,,,,,,,,,,,,18.447639465332,18.4962673187256,1000.13214111328,1000.13214111328,,,5.66151523590088,,1,0,0,0,0.013885498046875,31.2805480957031,2,1,1,18.4962673187256,0,2084574592,18.4714441299438,,,0.0180484791345812,0.000900342307341965,0.0180486122411434,0.000900343184356531,0.980801403522491,0.981137633323669,32.432201385498,1.41251402965281E-5,30,4,200,5.41187073395122E-5,-0.73998486995697,0.115321673452854,1,,,,,,,,,,,,,,,,
,3875805401.19025,20.0002841949463,1000.13214111328,,,6,,,,32.4187377475253,,,100,,,,,,,,,,,,,,,,,,,,,,19.9996433258057,20.0004329681396,1000.13214111328,1000.13214111328,,,5.73658275604248,,1,0,0,0,0.013885498046875,31.2805480957031,5,1,1,20.0002613067627,0,2084574880,20.0000205993652,,,0.0171400147673912,0.000855025552752421,0.0171401479453181,0.000855026303273916,0.980694591999054,0.981054842472076,32.4327087402344,,30,4,200,6.16374381934293E-5,-0.710056126117706,0.101965047419071,1,,,,,,,,,,,,,,,,
,3875805742.07972,29.2630023956299,1000.13214111328,,,6,,,,32.4187377475253,,,100,,,,,,,,,,,,,,,,,,,,,,29.0982856750488,29.3951950073242,1000.13214111328,1000.13214111328,,,6.05444383621216,,1,0,0,0,0.013885498046875,31.7693061828613,2,1,1,29.4277191162109,0,2084574688,29.2462350845337,,,0.0127790495983794,0.00063749507127833,0.0127792835488214,0.00063749627690667,0.979477286338806,0.980293095111847,32.4402923583984,,30,4,200,-6.67883577989414E-5,-0.53089427947998,0.0762514546513557,1,,,,,,,,,,,,,,,,
,3875806074.12435,40.1119251251221,1000.13214111328,,,6,,,,32.4290169969937,,,100,,,,,,,,,,,,,,,,,,,,,,39.9587173461914,40.2178573608398,1000.13214111328,1000.13214111328,,,6.29453611373901,,1,0,0,0,0.013885498046875,31.2805480957031,2,1,1,40.2651329040527,0,2084574912,40.0925682915582,,,0.00967094888289955,0.000482453313766904,0.0096711630221676,0.000482454168931919,0.978621900081635,0.979596495628357,32.4530258178711,,30,4,200,-3.40497099386994E-5,-0.404200077056885,0.05524767562747,1,,,,,,,,,,,,,,,,
,3875806405.60908,51.0014553070068,1000.13214111328,,,6,,,,32.439510934424,,,100,,,,,,,,,,,,,,,,,,,,,,50.8392333984375,51.1435737609863,1000.13214111328,1000.13214111328,,,6.45457410812378,,1,0,0,0,0.0139617919921875,30.7917900085449,2,1,1,51.1636772155762,0,2084574880,51.0001342773437,,,0.00773318486174105,0.000385794365365653,0.00773344163426513,0.000385795344508539,0.977446675300598,0.978849291801453,32.4689598083496,0,30,4,200,-5.9139169025002E-5,-0.317223638296127,0.0502147302031517,1,,,,,,,,,,,,,,,,
,3875806743.99669,62.1374549865723,1000.13214111328,,,6,,,,32.4546754950292,,,100,,,,,,,,,,,,,,,,,,,,,,61.9811553955078,62.2795906066895,1000.13214111328,1000.13214111328,,,6.56583070755005,,1,0,0,0,0.013885498046875,31.2805480957031,2,1,1,62.2937545776367,0,2084574592,62.1267040252686,,,0.00640258449708415,0.000319421795327075,0.00640285449078041,0.000319422544360362,0.976278126239777,0.978019952774048,32.4882316589355,0.188802734017372,30,4,200,-8.7509470176883E-6,-0.261827707290649,0.0424720533192158,1,,,,,,,,,,,,,,,,
,3875807083.75923,73.3326072692871,1000.13214111328,,,6,,,,32.4702176872004,,,100,,,,,,,,,,,,,,,,,,,,,,73.1789627075195,73.4746780395508,1000.13214111328,1000.13214111328,,,6.64916896820068,,1,0,0,0,0.013885498046875,31.2805480957031,2,1,1,73.4862518310547,0,2084574688,73.3244606018066,,,0.00545028159428806,0.000271921533380591,0.0054506098702719,0.000271922638013723,0.974827408790588,0.977166056632996,32.5100555419922,0,30,4,200,-2.96997022815049E-5,-0.230335935950279,0.0288053210824728,1,,,,,,,,,,,,,,,,
,3875807423.02313,84.5339317321777,1000.13214111328,,,6,,,,32.4862180209566,,,100,,,,,,,,,,,,,,,,,,,,,,84.3764877319336,84.682373046875,1000.13214111328,1000.13214111328,,,6.71626472473145,,1,0,0,0,0,31.2805480957031,2,1,1,84.6913757324219,0,2084575104,84.5308639526367,,,0.00474163304471531,0.000236576832898422,0.00474204092728514,0.000236578064349023,0.97310733795166,0.976299941539764,32.533992767334,0,30,4,200,-1.31963975036342E-6,-0.196259111166,0.0292902681976557,1,,,,,,,,,,,,,,,,
,3875807770.13159,96.0634002685547,1000.13214111328,,,6,,,,32.5071135386937,,,100,,,,,,,,,,,,,,,,,,,,,,95.9031372070312,96.207649230957,1000.13214111328,1000.13214111328,,,6.77051019668579,,1,0,0,0,0.013885498046875,31.2805480957031,2,1,1,96.2236633300781,0,2084574880,96.0563079833984,,,0.00418268150983556,0.000208697172282666,0.00418312519691141,0.000208698435938204,0.971643924713135,0.97542005777359,32.5602493286133,0,30,4,200,-1.06516768028087E-6,-0.178157985210419,0.0208829771727324,1,,,,,,,,,,,,,,,,
,3875808124.30737,107.799221038818,1000.13214111328,,,6,,,,32.5335636536935,,,100,,,,,,,,,,,,,,,,,,,,,,107.638771057129,107.94408416748,1000.13214111328,1000.13214111328,,,6.81600189208984,,1,0,0,0,0.013885498046875,31.2805480957031,2,1,1,107.959671020508,0,2084574976,107.793968963623,,,0.00373262139696743,0.000186246813397182,0.00373304777965981,0.000186248004284487,0.970591723918915,0.974517703056335,32.5887260437012,0,30,4,200,7.46697708109423E-7,-0.152893990278244,0.0248371120542288,1,,,,,,,,,,,,,,,,
,3875808477.67653,119.534675598145,1000.13214111328,,,6,,,,32.5608767026624,,,100,,,,,,,,,,,,,,,,,,,,,,119.375305175781,119.669876098633,1000.13214111328,1000.13214111328,,,6.85385274887085,,1,0,0,0,0.013885498046875,31.2805480957031,2,1,1,119.694046020508,0,2084575008,119.523599243164,,,0.00336973100999994,0.000168145240582299,0.00337014999781018,0.000168146412618195,0.969480693340302,0.973601222038269,32.6184120178223,0,30,4,200,2.46004765358521E-6,-0.141516357660294,0.0190251357853413,1,,,,,,,,,,,,,,,,
,3875808831.99119,131.327415466309,1000.13214111328,,,6,,,,32.5882653962382,,,100,,,,,,,,,,,,,,,,,,,,,,131.167938232422,131.475326538086,1000.13214111328,1000.13214111328,,,6.88677167892456,,1,0,0,0,0,31.2805480957031,2,1,1,131.486892700195,0,2084574752,131.324310302734,,,0.00306882919795935,0.000153136609912624,0.00306926215542583,0.000153137971430401,0.968219518661499,0.972689390182495,32.6493072509766,,30,4,200,4.0731998751653E-7,-0.132259175181389,0.0140141183510423,1,,,,,,,,,,,,,,,,
,3875809193.8439,143.331245422363,1000.13214111328,,,6,,,,32.6210862036918,,,100,,,,,,,,,,,,,,,,,,,,,,143.175003051758,143.470672607422,1000.13214111328,1000.13214111328,,,6.9193811416626,,1,0,0,0,0.013885498046875,31.7693061828613,2,1,1,143.487487792969,0,2084574720,143.321745300293,,,0.00281219290602647,0.000140333871025744,0.00281259596708016,0.000140335368886185,0.967430591583252,0.971791386604309,32.6822166442871,,30,4,200,2.83572217085748E-6,-0.113600537180901,0.0205235965549946,1,,,,,,,,,,,,,,,,
,3875809568.47075,155.785598754883,1000.13214111328,,,6,,,,32.6608278530583,,,100,,,,,,,,,,,,,,,,,,,,,,155.623687744141,155.915390014648,1000.13214111328,1000.13214111328,,,6.94874620437622,,1,0,0,0,0.013885498046875,31.7693061828613,2,1,1,155.947509765625,0,2084574752,155.766278076172,,,0.00258748375550279,0.000129121186008025,0.00258779749067609,0.000129122184083159,0.967248380184174,0.970916330814362,32.7173690795898,8.61357420944842E-6,30,4,200,8.11708389392152E-7,-0.106995098292828,0.0164740569889545,1,,,,,,,,,,,,,,,,
,3875809952.19729,168.540054321289,1000.13214111328,,,6,,,,32.7039101318279,,,100,,,,,,,,,,,,,,,,,,,,,,168.371704101562,168.684951782227,1000.13214111328,1000.13214111328,,,6.97773456573486,,1,0,0,0,0.013885498046875,31.7693061828613,2,1,1,168.708404541016,0,2084574720,168.53073425293,,,0.00239064669417951,0.000119298708056831,0.002390875655689,0.000119299407146814,0.967231333255768,0.970097780227661,32.754222869873,0.0570916533470154,30,4,200,5.46787433108875E-8,-0.101289413869381,0.0128610394895077,1,,,,,,,,,,,,,,,,
,3875810439.47465,184.752990722656,1000.13214111328,,,6,,,,32.7625248827857,,,10,,,,,,,,,,,,,,,,,,,,,,184.590881347656,184.891586303711,1000.13214111328,1000.13214111328,,,7.011390209198,,1,0,0,0,0.01190185546875,31.7693061828613,2,1,1,184.915100097656,0,2084574848,184.745304870605,,,0.00217729968930128,0.000108651817652505,0.0021774272405634,0.0001086521587754,0.967336058616638,0.969078123569489,32.8020210266113,5.29593372344971,30,4,200,-2.40068334278476E-6,-0.954726636409759,0.193845734000206,1,,,,,,,,,,,,,,,,
,3875810980.97545,202.763610839844,1000.13214111328,,,6,,,,32.8366247468448,,,10,,,,,,,,,,,,,,,,,,,,,,202.606323242187,202.906967163086,1000.13214111328,1000.13214111328,,,7.04605150222778,,1,0,0,0,0.013885498046875,31.7693061828613,2,1,1,202.9208984375,0,2084573184,202.75832824707,,,0.00198275621925596,9.89432140852397E-5,0.00198278729973453,9.89433728668208E-5,0.96747213602066,0.967907130718231,32.856517791748,5.29559183120728,30,4,200,-0.000173843131051399,-0.793702721595764,0.154694944620132,1,,,,,,,,,,,,,,,,
,3875811573.0488,222.436782836914,1000.13214111328,,,6,,,,32.9239298598852,,,10,,,,,,,,,,,,,,,,,,,,,,222.278198242187,222.585372924805,1000.13214111328,1000.13214111328,,,7.08974981307983,,1,0,0,0,0.013885498046875,31.7693061828613,2,1,1,222.595367431641,0,2084574880,222.43670501709,,,0.00180502940649671,9.00773437951113E-5,0.00180503201440639,9.0077329176129E-5,0.966464221477509,0.966512143611908,32.9172096252441,0,30,4,200,7.87485441833269E-6,-0.748947441577911,0.11479938775301,1,,,,,,,,,,,,,,,,
,3875812164.2085,242.081359863281,1000.13214111328,,,6,,,,33.0191091066103,,,10,,,,,,,,,,,,,,,,,,,,,,241.921371459961,242.2216796875,1000.13214111328,1000.13214111328,,,7.18229389190674,,1,0,0,0,0.013885498046875,31.7693061828613,2,1,1,242.253768920898,0,2084574752,242.075073242187,,,0.00165760846843095,8.27295289238766E-5,0.0016577020201018,8.27295903823378E-5,0.963363945484161,0.964914977550507,32.9795570373535,0.188863575458527,30,4,200,-2.57600117947732E-6,-0.713381588459015,0.0806985795497894,1,,,,,,,,,,,,,,,,
,3875812773.71897,262.319839477539,1000.13214111328,,,6,,,,33.1258297130373,,,10,,,,,,,,,,,,,,,,,,,,,,262.165588378906,262.474090576172,1000.13214111328,1000.13214111328,,,7.58067989349365,,1,0,0,0,0.013885498046875,31.7693061828613,2,1,1,262.474090576172,0,2084574528,262.317636108398,,,0.0015297404473225,7.63668773491669E-5,0.00153011040037656,7.63674959215307E-5,0.957085967063904,0.96291971206665,33.0448532104492,5.74846506118774,30,4,200,9.5961486294982E-6,-0.684035181999207,0.0497963987290859,1,,,,,,,,,,,,,,,,
,3875813620.69338,290.475463867188,1000.13214111328,,,6,,,,33.2912693435189,,,10,,,,,,,,,,,,,,,,,,,,,,290.159118652344,290.766510009766,1000.13214111328,1000.13214111328,,,8.58900260925293,,1,0,0,0,0.013885498046875,32.2580642700195,2,1,1,290.791809082031,0,2084574688,290.459450169614,,,0.0013839032709114,6.91385297276514E-5,0.00138516050673056,6.91410732017229E-5,0.942168176174164,0.959921479225159,33.1350593566895,4.28390216827393,30,4,200,1.26850636661402E-5,-0.543808400630951,0.121884055435658,1,,,,,,,,,,,,,,,,
,3875815408.73377,2.48188102245331,99.8773040771484,,,6,,,,32.1864242553711,,,10,,,,,,,,,,,,,,,,,,,,,,2.46804451942444,2.48951053619385,99.8773040771484,99.8773040771484,,,3.06082272529602,,1,0,0,0,0.014801025390625,30.7917900085449,6,1,1,2.49091005325317,0,2084574880,2.47567837238312,,,0.00118526528335514,5.91930450627908E-5,0.0011866643317525,5.91965086698193E-5,0.948882460594177,0.980660080909729,32.3645401000977,5.68898391723633,30,4,200,8.71694064699113E-5,-0.472486436367035,0.0895975679159164,1,,,,,,,,,,,,,,,,
,3875815731.81924,3.78007900714874,99.8773040771484,,,6,,,,32.1914266993472,,,10,,,,,,,,,,,,,,,,,,,,,,3.75984978675842,3.79569506645203,99.8773040771484,99.8773040771484,,,3.65428948402405,,1,0,0,0,0.013885498046875,31.2805480957031,6,1,1,3.80126333236694,0,2084574816,3.77562218242221,,,0.00116391500355074,5.93175183878065E-5,0.00119007031665008,5.93756154019917E-5,0.794443130493164,0.97385048866272,32.9621810913086,0.192913040518761,30,4,200,0.00014527453458868,-0.474776893854141,0.0913875848054886,1,,,,,,,,,,,,,,,,
,3875816048.37601,5.21709275245666,99.8773040771484,,,6,,,,32.1914266993472,,,10,,,,,,,,,,,,,,,,,,,,,,5.19406270980835,5.23616600036621,99.8773040771484,99.8773040771484,,,4.14991521835327,,1,0,0,0,0.013885498046875,30.7917900085449,6,1,1,5.24012279510498,0,2084574656,5.21243472099304,,,0.00113370645922795,6.1207461775569E-5,0.00122980206889022,6.14213619370265E-5,0.617151618003845,0.947591304779053,33.6394309997559,0.000650915550068021,30,4,200,0.000146308288094588,-0.491281002759933,0.103437751531601,1,,,,,,,,,,,,,,,,
,3875816365.18149,6.7017560005188,99.8773040771484,,,6,,,,32.1914266993472,,,10,,,,,,,,,,,,,,,,,,,,,,6.68003511428833,6.72115039825439,99.8773040771484,99.8773040771484,,,4.52815914154053,,1,0,0,0,0.013885498046875,31.2805480957031,6,1,1,6.72347688674927,0,2084574592,6.69790391921997,,,0.00108131095558512,6.42713078345342E-5,0.00129207213272775,6.47402925783601E-5,0.456042528152466,0.904225587844849,34.2716636657715,0,30,4,200,0.000152816879563034,-0.62439888715744,0.127500489354134,1,,,,,,,,,,,,,,,,
,3875816680.69021,8.20325803756714,99.8773040771484,,,6,,,,32.1914266993472,,,10,,,,,,,,,,,,,,,,,,,,,,8.18049812316895,8.22358703613281,99.8773040771484,99.8773040771484,,,4.82094860076904,,1,0,0,0,0.013885498046875,29.8142719268799,6,1,1,8.22601795196533,0,2084574688,8.19984521865845,,,0.0011724679407934,6.81396394523397E-5,0.00136981853509945,6.85781618982129E-5,0.486683338880539,0.913369536399841,34.1484451293945,0.016652038320899,30,4,200,4.26998303737491E-5,-0.650245547294617,0.136410146951675,1,,,,,,,,,,,,,,,,
,3875816996.3255,9.71861219406128,99.8773040771484,,,6,,,,32.1914266993472,,,10,,,,,,,,,,,,,,,,,,,,,,9.69634246826172,9.73841094970703,99.8773040771484,99.8773040771484,,,5.05675888061523,,1,0,0,0,0.013885498046875,31.2805480957031,6,1,1,9.74088191986084,0,2084574656,9.71590194702148,,,0.00139428998890522,7.55444625978964E-5,0.00151794523176307,7.58223621007969E-5,0.609325230121613,0.945148587226868,33.6688537597656,0.190475285053253,30,4,200,7.28880622773431E-5,-0.698408663272858,0.145671814680099,1,,,,,,,,,,,,,,,,
,3875817312.30918,11.2406530380249,99.8773040771484,,,6,,,,32.1914266993472,,,10,,,,,,,,,,,,,,,,,,,,,,11.2174682617187,11.2564525604248,99.8773040771484,99.8773040771484,,,5.24667358398438,,1,0,0,0,0.013885498046875,31.2805480957031,6,1,1,11.2638378143311,0,2084574880,11.2360706329346,,,0.00165085657942687,8.61429524037969E-5,0.00172954529086761,8.63210183505811E-5,0.706050932407379,0.962992489337921,33.298152923584,,30,4,200,0.000106607498310041,-0.769362092018127,0.168064251542091,1,,,,,,,,,,,,,,,,
,3875817630.10881,12.7751860618591,99.8773040771484,,,6,,,,32.1914266993472,,,10,,,,,,,,,,,,,,,,,,,,,,12.7527532577515,12.7950468063354,99.8773040771484,99.8773040771484,,,5.4015645980835,,1,0,0,0,0.013885498046875,31.2805480957031,6,1,1,12.7976188659668,0,2084574592,12.7734954833984,,,0.00195349171026275,9.96855799655237E-5,0.00200006502029305,9.97895965880373E-5,0.788537085056305,0.973351359367371,32.9846496582031,0.168896853923798,30,4,200,0.000123201112728566,-0.86104941368103,0.0919052734971046,1,,,,,,,,,,,,,,,,
,3875817954.99483,14.3520865440369,99.8773040771484,,,6,,,,32.196441124109,,,10,,,,,,,,,,,,,,,,,,,,,,14.3290128707886,14.3726377487183,99.8773040771484,99.8773040771484,,,5.53201341629028,,1,0,0,0,0.013885498046875,31.2805480957031,6,1,1,14.3751602172852,0,2084574624,14.3510767936707,,,0.00232081298468202,0.000115996215477141,0.0023255498660477,0.000116007881156837,0.935094237327576,0.981431305408478,32.4306564331055,,30,4,200,8.39345739223063E-5,-0.971000075340271,0.130317330360413,1,,,,,,,,,,,,,,,,
,3875818270.07696,15.9654250144958,99.8773040771484,,,6,,,,32.196441124109,,,10,,,,,,,,,,,,,,,,,,,,,,15.9385166168213,15.9878625869751,99.8773040771484,99.8773040771484,,,5.57208633422852,,1,0,0,0,0.013885498046875,32.2580642700195,2,1,1,15.9923334121704,0,2084574912,15.963583946228,,,0.00223217020641551,0.00011156317284984,0.00223665752229884,0.000111573811227405,0.93545389175415,0.981318533420563,32.4291343688965,,30,4,200,4.83720286865719E-5,-0.939416825771332,0.120377950370312,1,,,,,,,,,,,,,,,,
,3875818586.34175,17.5416250228882,99.8773040771484,,,6,,,,32.196441124109,,,10,,,,,,,,,,,,,,,,,,,,,,17.5192413330078,17.5626354217529,99.8773040771484,99.8773040771484,,,5.64365720748901,,1,0,0,0,0.013885498046875,31.2805480957031,2,1,1,17.5640087127686,0,2084574784,17.5397403717041,,,0.00212153455584879,0.00010603274230824,0.00212577585369712,0.000106042831522836,0.935588240623474,0.981200993061066,32.4284439086914,9.32521561480826E-6,30,4,200,4.80082890135236E-5,-0.901833415031433,0.105423644185066,1,,,,,,,,,,,,,,,,
,3875818902.91952,19.106143951416,99.8773040771484,,,6,,,,32.196441124109,,,10,,,,,,,,,,,,,,,,,,,,,,19.0818977355957,19.128812789917,99.8773040771484,99.8773040771484,,,5.71684551239014,,1,0,0,0,0.013885498046875,32.2580642700195,2,1,1,19.1303901672363,0,2084574784,19.1052295684814,,,0.00201214011428962,0.000100565781649217,0.00201618283536802,0.000100576023150964,0.935503423213959,0.981084585189819,32.4286460876465,0,30,4,200,5.64171168662142E-5,-0.864717662334442,0.0907002538442612,1,,,,,,,,,,,,,,,,
,3875819638.35983,2.23533499240875,99.8773040771484,,,6,,,,32.1129570007324,,,10,,,,,,,,,,,,,,,,,,,,,,2.21492218971252,2.24714946746826,99.8773040771484,99.8773040771484,,,2.6952657699585,,1,0,0,0,0.013885498046875,31.2805480957031,6,1,1,2.25574779510498,0,2084574784,2.22926028569539,,,0.00119040314670667,5.94067709061239E-5,0.00119090294418093,5.94079764325434E-5,0.965751826763153,0.980645298957825,32.219295501709,0,30,4,200,0.000113367670564912,-0.468688875436783,0.0954478904604912,1,,,,,,,,,,,,,,,,
,3875819954.57689,3.58425092697144,99.8773040771484,,,6,,,,32.1129570007324,,,10,,,,,,,,,,,,,,,,,,,,,,3.56217551231384,3.60362505912781,99.8773040771484,99.8773040771484,,,3.42372870445251,,1,0,0,0,0.013885498046875,31.7693061828613,6,1,1,3.60632634162903,0,2084574784,3.58131663799286,,,0.00115623657453571,5.92697019538413E-5,0.00118940933067669,5.93445722604713E-5,0.769082486629486,0.972633481025696,32.9809112548828,0.173455983400345,30,4,200,0.000167621823493391,-0.469391644001007,0.0968793928623199,1,,,,,,,,,,,,,,,,
,3875820270.31958,5.00826907157898,99.8773040771484,,,6,,,,32.1129570007324,,,10,,,,,,,,,,,,,,,,,,,,,,4.98572731018066,5.02332019805908,99.8773040771484,99.8773040771484,,,3.96865844726562,,1,0,0,0,0.013885498046875,31.7693061828613,6,1,1,5.03081083297729,0,2084574624,5.00194957521227,,,0.00112363533836323,6.25993041484766E-5,0.00125858764063776,6.29017985920445E-5,0.55443000793457,0.935953736305237,33.8070297241211,0,30,4,200,0.000189835642231628,-0.49700129032135,0.116651467978954,1,,,,,,,,,,,,,,,,
,3875820593.2517,6.51567959785461,99.8773040771484,,,6,,,,32.1179719692305,,,10,,,,,,,,,,,,,,,,,,,,,,6.49268341064453,6.53521585464478,99.8773040771484,99.8773040771484,,,4.38833713531494,,1,0,0,0,0.013885498046875,31.2805480957031,6,1,1,6.5386757850647,0,2084574688,6.51110234260559,,,0.00107094198012602,6.84501185666487E-5,0.00137579612537438,6.91342237065759E-5,0.374633014202118,0.878080248832703,34.5359878540039,0.122774422168732,30,4,200,0.00017342968203593,-0.650139272212982,0.155812323093414,1,,,,,,,,,,,,,,,,
,3875820909.46741,8.0155553817749,99.8773040771484,,,6,,,,32.1179719692305,,,10,,,,,,,,,,,,,,,,,,,,,,7.99211502075195,8.03505420684814,99.8773040771484,99.8773040771484,,,4.70808410644531,,1,0,0,0,0.0139617919921875,31.2805480957031,6,1,1,8.03899574279785,0,2084574720,8.01343050003052,,,0.00112753434095675,7.25700296748198E-5,0.00145835563183756,7.33129904333799E-5,0.367946237325668,0.874803602695465,34.5632133483887,0,30,4,200,2.8529826522572E-5,-0.678912937641144,0.170903950929642,1,,,,,,,,,,,,,,,,
,3875821227.22352,9.54013633728027,99.8773040771484,,,6,,,,32.1179719692305,,,10,,,,,,,,,,,,,,,,,,,,,,9.51725101470947,9.56008720397949,99.8773040771484,99.8773040771484,,,4.96565580368042,,1,0,0,0,0.013885498046875,31.7693061828613,6,1,1,9.56302165985107,0,2084574816,9.53716535568237,,,0.00135197378670228,7.76736928440013E-5,0.00156196516173136,7.81454432768501E-5,0.503650903701782,0.921409606933594,34.0107002258301,0.187562242150307,30,4,200,5.69376461498905E-5,-0.713529884815216,0.164102628827095,1,,,,,,,,,,,,,,,,
,3875821544.13663,11.0654525756836,99.8773040771484,,,6,,,,32.1179719692305,,,10,,,,,,,,,,,,,,,,,,,,,,11.0424118041992,11.0857954025269,99.8773040771484,99.8773040771484,,,5.17127799987793,,1,0,0,0,0.0139617919921875,31.2805480957031,6,1,1,11.088493347168,0,2084574656,11.0633583068848,,,0.00161068407335177,8.68559408967287E-5,0.00174538075133851,8.71618402158369E-5,0.619805693626404,0.949743688106537,33.5569915771484,0.204219952225685,30,4,200,8.59711071825586E-5,-0.774886131286621,0.176836267113686,1,,,,,,,,,,,,,,,,
,3875821860.43573,12.5938482284546,99.8773040771484,,,6,,,,32.1179719692305,,,10,,,,,,,,,,,,,,,,,,,,,,12.5719127655029,12.6150417327881,99.8773040771484,99.8773040771484,,,5.33863210678101,,1,0,0,0,0.0139617919921875,31.2805480957031,6,1,1,12.617579460144,0,2084574848,12.5923352241516,,,0.00191152513918817,9.9302208112921E-5,0.00199363930456529,9.94889590939302E-5,0.720279157161713,0.966669797897339,33.1716957092285,0.433999091386795,30,4,200,0.000110012493678369,-0.858661711215973,0.203045427799225,1,,,,,,,,,,,,,,,,
,3875822176.76442,14.1253032684326,99.8773040771484,,,6,,,,32.1179719692305,,,10,,,,,,,,,,,,,,,,,,,,,,14.1023216247559,14.1405916213989,99.8773040771484,99.8773040771484,,,5.47065591812134,,1,0,0,0,0.013885498046875,30.7917900085449,6,1,1,14.1482849121094,0,2084574752,14.1211618847317,,,0.0023015180389182,0.000115643086702591,0.00231884477210701,0.000115683880112119,0.878708124160767,0.977068483829498,32.5671310424805,0,30,4,200,-0.0008120650309138,-0.969237983226776,0.130983129143715,1,,,,,,,,,,,,,,,,
,3875822500.53928,15.8531699180603,99.8773040771484,,,6,,,,32.1229840418873,,,10,,,,,,,,,,,,,,,,,,,,,,15.828405380249,15.8755388259888,99.8773040771484,99.8773040771484,,,5.5308895111084,,1,0,0,0,0.013885498046875,31.2805480957031,2,1,1,15.8779344558716,0,2084574496,15.8511552810669,,,0.0022365784129038,0.000111938867182708,0.00224432834725887,0.000111956544632278,0.916763424873352,0.981291651725769,32.4285583496094,0,30,4,200,5.08479570271447E-5,-0.942543625831604,0.120768740773201,1,,,,,,,,,,,,,,,,
,3875822817.24316,17.4466953277588,99.8773040771484,,,6,,,,32.1229840418873,,,10,,,,,,,,,,,,,,,,,,,,,,17.4224224090576,17.4686603546143,99.8773040771484,99.8773040771484,,,5.60752630233765,,1,0,0,0,0.014801025390625,31.2805480957031,2,1,1,17.47096824646,0,2084574848,17.4459079742432,,,0.00212505422587683,0.000106355773868623,0.00213238525875733,0.000106372535678497,0.916918992996216,0.981191575527191,32.427864074707,,30,4,200,5.05610078107566E-5,-0.904832184314728,0.10551330447197,1,,,,,,,,,,,,,,,,
,3875823133.11626,19.0070581436157,99.8773040771484,,,6,,,,32.1229840418873,,,10,,,,,,,,,,,,,,,,,,,,,,18.9826583862305,19.0281639099121,99.8773040771484,99.8773040771484,,,5.68764066696167,,1,0,0,0,0.013885498046875,31.2805480957031,2,1,1,19.031457901001,0,2084574336,19.0062250137329,,,0.00201604709883086,0.000100900845415602,0.00202302485511386,0.000100917371203348,0.916831791400909,0.981074035167694,32.4280738830566,0,30,4,200,4.3380419811001E-5,-0.867801785469055,0.0907883197069168,1,,,,,,,,,,,,,,,,
,3875823468.4362,22.0737066268921,99.8773040771484,,,6,,,,32.1229840418873,,,10,,,,,,,,,,,,,,,,,,,,,,21.9135913848877,22.2086410522461,99.8773040771484,99.8773040771484,,,5.81694316864014,,1,0,0,0,0.013885498046875,31.2805480957031,2,1,1,22.2338218688965,0,2084574656,22.0617288589478,,,0.00181518271920443,9.08520076562807E-5,0.00182153736690122,9.08670013276085E-5,0.916285276412964,0.980677485466003,32.4298324584961,5.27920198440552,30,4,200,-0.00012288466678001,-0.801025748252869,0.0643221735954285,1,,,,,,,,,,,,,,,,
,3875823785.26177,32.402135848999,99.8773040771484,,,6,,,,32.1229840418873,,,10,,,,,,,,,,,,,,,,,,,,,,32.2475204467773,32.5481452941895,99.8773040771484,99.8773040771484,,,6.13601112365723,,1,0,0,0,0.013885498046875,32.7468223571777,2,1,1,32.5567512512207,0,2084574720,32.3973556518555,,,0.00133048080059759,6.66071654418467E-5,0.00133542916484187,6.66184798569199E-5,0.913644373416901,0.97999495267868,32.439380645752,0.186074480414391,30,4,200,-6.41591977910139E-5,-0.523387551307678,0.110714949667454,1,,,,,,,,,,,,,,,,
,3875824118.53223,43.33083152771,99.8773040771484,,,6,,,,32.1331575489667,,,10,,,,,,,,,,,,,,,,,,,,,,43.1636543273926,43.4788513183594,99.8773040771484,99.8773040771484,,,6.34872245788574,,1,0,0,0,0.013885498046875,31.2805480957031,2,1,1,43.4980087280273,0,2084574752,43.3128700256348,,,0.00102354144883157,5.12459970717723E-5,0.00102744172522438,5.12552550943614E-5,0.912538886070252,0.979182124137878,32.4530372619629,,30,4,200,-3.24011380143929E-5,-0.416652977466583,0.0711977928876877,1,,,,,,,,,,,,,,,,
,3875824457.21248,54.4601058959961,99.8773040771484,,,6,,,,32.1488369919724,,,10,,,,,,,,,,,,,,,,,,,,,,54.2926902770996,54.6084289550781,99.8773040771484,99.8773040771484,,,6.49898195266724,,1,0,0,0,0.013885498046875,31.2805480957031,2,1,1,54.6275215148926,0,2084574720,54.4485015869141,,,0.00082529710698865,4.1323110206085E-5,0.000828486119279068,4.13308556982122E-5,0.911804437637329,0.978312969207764,32.4706573486328,0,30,4,200,-1.72062827914488E-5,-0.349418491125107,0.0439335219562054,1,,,,,,,,,,,,,,,,
,3875824788.82,65.3716125488281,99.8773040771484,,,6,,,,32.1592625462965,,,10,,,,,,,,,,,,,,,,,,,,,,65.2128143310547,65.4942855834961,99.8773040771484,99.8773040771484,,,6.60457849502563,,1,0,0,0,0.013885498046875,31.7693061828613,2,1,1,65.5304107666016,0,2084574752,65.3512827555339,,,0.000691885552912657,3.46513234013383E-5,0.000694713930719699,3.46580441771232E-5,0.909177839756012,0.977385401725769,32.4903335571289,0,30,4,200,-7.64800279284827E-6,-0.303506731986999,0.0263723842799664,1,,,,,,,,,,,,,,,,
,3875825134.68571,76.7787246704102,99.8773040771484,,,6,,,,32.1802992787227,,,10,,,,,,,,,,,,,,,,,,,,,,76.6114120483398,76.9313659667969,99.8773040771484,99.8773040771484,,,6.68420553207398,,1,0,0,0,0.013885498046875,31.2805480957031,2,1,1,76.9460372924805,0,2084574560,76.7758399963379,,,0.000591397095346586,2.96206831278355E-5,0.00059383972162073,2.96262752375004E-5,0.908417224884033,0.976406574249268,32.5132904052734,,30,4,200,-3.67733846360352E-5,-0.268706470727921,0.0132894888520241,1,,,,,,,,,,,,,,,,
,3875825473.10307,87.9701499938965,99.8773040771484,,,6,,,,32.1963945925271,,,10,,,,,,,,,,,,,,,,,,,,,,87.814826965332,88.1115417480469,99.8773040771484,99.8773040771484,,,6.74628210067749,,1,0,0,0,0.013885498046875,31.7693061828613,2,1,1,88.1254730224609,0,2084574880,87.9652534484863,,,0.000517164435810684,2.59085906069524E-5,0.000519417577427364,2.59140183630488E-5,0.905979454517364,0.975435435771942,32.537841796875,2.87825041596079E-5,30,4,200,-3.3091114914896E-7,-0.243154734373093,0.0035792775452137,1,,,,,,,,,,,,,,,,
,3875825819.47798,99.4516181945801,99.8773040771484,,,6,,,,32.2173088553423,,,10,,,,,,,,,,,,,,,,,,,,,,99.284912109375,99.6029815673828,99.8773040771484,99.8773040771484,,,6.79700803756714,,1,0,0,0,0.013885498046875,32.2580642700195,2,1,1,99.6183242797852,0,2084574528,99.4477912902832,,,0.000458074244979661,2.29522882945288E-5,0.000460142102884048,2.29573114828578E-5,0.904173076152802,0.974416732788086,32.5646591186523,0,30,4,200,3.30718137320218E-7,-0.222878515720367,-0.00420843157917261,1,,,,,,,,,,,,,,,,
,3875826173.81583,111.233192443848,99.8773040771484,,,6,,,,32.2437353763741,,,10,,,,,,,,,,,,,,,,,,,,,,111.072814941406,111.376068115234,99.8773040771484,99.8773040771484,,,6.83997678756714,,1,0,0,0,0.013885498046875,31.2805480957031,2,1,1,111.393569946289,0,2084574880,111.21916885376,,,0.000409946885453385,2.05426761476807E-5,0.000411818709325235,2.05469216571094E-5,0.903244972229004,0.973402440547943,32.5935745239258,0.0671125575900078,30,4,200,2.17632555177261E-6,-0.206346780061722,-0.0105930827558041,1,,,,,,,,,,,,,,,,
,3875826528.59457,123.028263092041,99.8773040771484,,,6,,,,32.2701931973038,,,10,,,,,,,,,,,,,,,,,,,,,,122.871635437012,123.165710449219,99.8773040771484,99.8773040771484,,,6.87653398513794,,1,0,0,0,0,31.7693061828613,2,1,1,123.18489074707,0,2084574720,123.021044921875,,,0.000370813419267942,1.85839317865533E-5,0.000372546622971263,1.85880485538607E-5,0.902009069919586,0.972341656684876,32.6236000061035,5.65257778362138E-6,30,4,200,-1.68402257259004E-5,-0.192834302783012,-0.015701599419117,1,,,,,,,,,,,,,,,,
,3875826891.8395,135.102226257324,99.8773040771484,,,6,,,,32.3033613241079,,,10,,,,,,,,,,,,,,,,,,,,,,134.942749023438,135.235855102539,99.8773040771484,99.8773040771484,,,6.91046619415283,,1,0,0,0,0.013885498046875,31.2805480957031,2,1,1,135.261703491211,0,2084574720,135.096041870117,,,0.000337722951545121,1.6925691107771E-5,0.000339287933350306,1.6929126233127E-5,0.901921272277832,0.971275687217712,32.6558113098145,0.0689603090286255,30,4,200,2.68524649982282E-6,-0.181397557258606,-0.0199959147721529,1,,,,,,,,,,,,,,,,
,3875827254.24742,147.148468017578,99.8773040771484,,,6,,,,32.3369058315557,,,10,,,,,,,,,,,,,,,,,,,,,,146.98664855957,147.290115356445,99.8773040771484,99.8773040771484,,,6.94165277481079,,1,0,0,0,0.013885498046875,31.7693061828613,2,1,1,147.310287475586,0,2084574816,147.138697814941,,,0.000309958076958307,1.55346543755985E-5,0.000311399704441842,1.55380758882224E-5,0.901627242565155,0.970269978046417,32.6892395019531,0.0660563483834267,30,4,200,2.61371724263881E-6,-0.171810194849968,-0.0236249342560768,1,,,,,,,,,,,,,,,,
,3875827631.74496,159.726982116699,99.8773040771484,,,6,,,,32.3803057823334,,,10,,,,,,,,,,,,,,,,,,,,,,159.55973815918,159.863586425781,99.8773040771484,99.8773040771484,,,6.97188663482666,,1,0,0,0,0.013885498046875,31.7693061828613,2,1,1,159.894226074219,0,2084574976,159.710946655273,,,0.000285483695297292,1.43057561965466E-5,0.000286752857957319,1.43086822200668E-5,0.903242349624634,0.969289839267731,32.7249755859375,0.0861972123384476,30,4,200,-1.45056428664247E-5,-0.163367941975594,-0.0268866810947657,1,,,,,,,,,,,,,,,,
,3875828007.68583,172.219123840332,99.8773040771484,,,6,,,,32.4237280879701,,,10,,,,,,,,,,,,,,,,,,,,,,172.063858032227,172.361282348633,99.8773040771484,99.8773040771484,,,6.99904346466065,,1,0,0,0,0.013885498046875,31.7693061828613,2,1,1,172.374389648438,0,2084574944,172.212113952637,,,0.000264594707294608,1.32571460634901E-5,0.000265727649054307,1.3259915465561E-5,0.904682040214539,0.968393445014954,32.761402130127,0.000245648756390437,30,4,200,4.00437693315325E-6,-0.156129658222198,-0.0296054501086473,1,,,,,,,,,,,,,,,,
,3875828385.61662,184.740913391113,99.8773040771484,,,6,,,,32.4704913168982,,,10,,,,,,,,,,,,,,,,,,,,,,184.584579467773,184.884017944336,99.8773040771484,99.8773040771484,,,7.02516794204712,,1,0,0,0,0.013885498046875,31.2805480957031,2,1,1,184.897247314453,0,2084574848,184.735264587402,,,0.000246453282730072,1.23458350074329E-5,0.000247448585361821,1.2348177495186E-5,0.906690001487732,0.967396199703217,32.7986755371094,0,30,4,200,-1.21609646157594E-5,-0.149811640381813,-0.0319479666650295,1,,,,,,,,,,,,,,,,
,3875828762.26451,197.252777099609,99.8773040771484,,,6,,,,32.5178848490486,,,10,,,,,,,,,,,,,,,,,,,,,,197.096466064453,197.395599365234,99.8773040771484,99.8773040771484,,,7.04988050460815,,1,0,0,0,0.0139617919921875,31.2805480957031,2,1,1,197.409088134766,0,2084575040,197.243176269531,,,0.000230626693007902,1.15507475768549E-5,0.000231503349152174,1.15528317602009E-5,0.908804535865784,0.966479480266571,32.8361663818359,,30,4,200,1.77900835751643E-6,-0.144387528300285,-0.0340736657381058,1,,,,,,,,,,,,,,,,
,3875829167.81609,210.746398925781,99.8773040771484,,,6,,,,32.5781985170359,,,10,,,,,,,,,,,,,,,,,,,,,,210.578399658203,210.890426635742,99.8773040771484,99.8773040771484,,,7.07785797119141,,1,0,0,0,0.013885498046875,31.2805480957031,2,1,1,210.914398193359,0,2084574848,210.736302185059,,,0.000215737693609698,1.08009365837217E-5,0.000216463365555014,1.08026692454571E-5,0.913035750389099,0.965423226356506,32.8775749206543,,30,4,200,1.02534727375314E-8,-0.139236807823181,-0.0360388159751892,1,,,,,,,,,,,,,,,,
,3875829566.61816,223.96452331543,99.8773040771484,,,6,,,,32.6351023148853,,,10,,,,,,,,,,,,,,,,,,,,,,223.791275024414,224.117568969727,99.8773040771484,99.8773040771484,,,7.11135816574097,,1,0,0,0,0.013885498046875,31.2805480957031,2,1,1,224.137771606445,0,2084574848,223.95832824707,,,0.000202831146940527,1.015187919464E-5,0.000203444665251119,1.01533656863637E-5,0.916348338127136,0.964309692382813,32.918830871582,7.4677509473986E-6,30,4,200,6.09872040513437E-6,-0.134794369339943,-0.0377503335475922,1,,,,,,,,,,,,,,,,
,3875829973.64137,237.48217010498,99.8773040771484,,,6,,,,32.7020108224207,,,10,,,,,,,,,,,,,,,,,,,,,,237.320434570313,237.61833190918,99.8773040771484,99.8773040771484,,,7.16913223266602,,1,0,0,0,0.0139617919921875,31.7693061828613,2,1,1,237.643905639648,0,2084574624,237.470352172852,,,0.000191227121885215,9.56707543790475E-6,0.000191711638628,9.56821978824225E-6,0.921485483646393,0.963110208511353,32.9618301391602,5.28154134750366,30,4,200,1.82980477347883E-6,-0.130590975284576,-0.0390676148235798,1,,,,,,,,,,,,,,,,
,3875830381.66145,251.041709899902,99.8773040771484,,,6,,,,32.7712185652983,,,10,,,,,,,,,,,,,,,,,,,,,,250.881317138672,251.182266235352,99.8773040771484,99.8773040771484,,,7.31416606903076,,1,0,0,0,0.013885498046875,32.7468223571777,2,1,1,251.202102661133,0,2084574784,251.030128479004,,,0.000180902716241487,9.0470874657695E-6,0.000181277905423043,9.04796979993311E-6,0.926484942436218,0.961667120456696,33.0062599182129,0.189164415001869,30,4,200,2.51729034062009E-6,-0.126913785934448,-0.0403330586850643,1,,,,,,,,,,,,,,,,
,3875830797.60849,264.817504882813,99.8773040771484,,,6,,,,32.8454655158229,,,10,,,,,,,,,,,,,,,,,,,,,,264.660430908203,264.963256835938,99.8773040771484,99.8773040771484,,,7.70333909988403,,1,0,0,0,0.013885498046875,31.7693061828613,2,1,1,264.982147216797,0,2084574912,264.816806030273,,,0.000171555886131024,8.57616697409141E-6,0.000171828204192337,8.57682729868735E-6,0.932195067405701,0.960141956806183,33.0508880615234,,30,4,200,4.98155577588477E-6,-0.123590804636478,-0.0414545461535454,1,,,,,,,,,,,,,,,,
,3875831242.69744,279.59912109375,99.8773040771484,,,6,,,,32.9296127924227,,,10,,,,,,,,,,,,,,,,,,,,,,279.448120117187,279.753509521484,99.8773040771484,99.8773040771484,,,7.92843389511108,,1,0,0,0,0.013885498046875,31.7693061828613,2,1,1,279.766845703125,0,2084574592,279.596453857422,,,0.000162697493950632,8.12997323050421E-6,0.000162873055392937,8.13041096866278E-6,0.938559472560883,0.95839124917984,33.0988273620605,0.189116895198822,30,4,200,-3.52486540577956E-6,-0.120369873940945,-0.0425043664872646,1,,,,,,,,,,,,,,,,
,3875831689.58705,294.434341430664,99.8773040771484,,,6,,,,33.0187173544769,,,10,,,,,,,,,,,,,,,,,,,,,,294.271240234375,294.571990966797,99.8773040771484,99.8773040771484,,,8.94498825073242,,1,0,0,0,0.013885498046875,31.2805480957031,2,1,1,294.597442626953,0,2084574688,294.425762939453,,,0.00015490272189192,7.73752842080314E-6,0.000154996706289576,7.73777789847724E-6,0.945068001747131,0.956736624240875,33.1453437805176,,30,4,200,3.28872329191654E-6,-0.11751089990139,-0.0433417372405529,1,,,,,,,,,,,,,,,,
,3875833573.10733,2.0001916885376,17676.984375,,,6,,,,32.1173100164146,,,1000,,,,,,,,,,,,,,,,,,,,,,1.99854052066803,2.00181412696838,17676.984375,17676.984375,,,2.67534446716309,,1,0,0,0,0.014801025390625,31.7693061828613,1,1,1,2.00007629394531,0,2084574528,2.00010075569153,,,0.203678269416038,0.0101964489413011,0.204438139413164,0.0101982393358084,0.913859486579895,0.981255531311035,32.4341506958008,1.37422111947672E-5,30,4,200,0.000128738436615095,-0.846739709377289,0.137423142790794,1,,,,,,,,,,,,,,,,
,3875834596.02668,2.00042390823364,64343.6484375,,,6,,,,32.1173100164146,,,1000,,,,,,,,,,,,,,,,,,,,,,1.99816107749939,2.00113034248352,64343.6484375,64343.6484375,,,2.58518886566162,,1,0,0,0,0.013885498046875,31.2805480957031,1,1,1,2.00035858154297,0,2084574784,2.00008798837662,,,1.35133232130308,0.0677279357722501,1.35756567878004,0.0677987983139113,0.901463568210602,0.948613584041596,32.4344749450684,0,30,4,200,0.0741040408611298,-4.66409063339233,4.69299459457397,1,,,,,,,,,,,,,,,,
,3875846239.68856,2.00025248527527,43131.7734375,,,6,,,,32.1173100164146,,,1000,,,,,,,,,,,,,,,,,,,,,,1.99788272380829,2.00096082687378,43131.7734375,43131.7734375,,,2.4826865196228,,1,0,0,0,0.013885498046875,31.2805480957031,1,1,1,2.00021004676819,0,2084574848,2.00000442266464,,,0.902645570710176,0.0451821190339869,0.905900920995687,0.045189682297501,0.915327250957489,0.981832146644592,32.4289741516113,0,30,4,200,0.000289730785880238,-3.75083088874817,0.603974759578705,1,,,,,,,,,,,,,,,,
,3875848033.79173,10.0013833045959,27576.2109375,,,6,,,,32.1173100164146,,,1000,,,,,,,,,,,,,,,,,,,,,,9.9986686706543,10.0017929077148,27576.2109375,27576.2109375,,,4.91632843017578,,1,0,0,0,0.013885498046875,31.2805480957031,1,1,1,10.001727104187,0,2084574784,10.0001399040222,,,0.572795381116695,0.0286696727792831,0.574832142022065,0.028674768364197,0.916036009788513,0.981799364089966,32.4261894226074,5.6943998336792,30,4,200,0.000224683972191997,-2.37982273101807,0.382991880178452,1,,,,,,,,,,,,,,,,
,3875848577.1596,10.0013103485107,53030.5859375,,,6,,,,32.1173100164146,,,1000,,,,,,,,,,,,,,,,,,,,,,9.99832153320312,10.0015668869019,53030.5859375,53030.5859375,,,4.95179748535156,,1,0,0,0,0.013885498046875,31.2805480957031,1,1,1,10.0017595291138,0,2084574656,9.99990186691284,,,1.12246039085936,0.0561898673483121,1.12662139729794,0.0562000591835147,0.914321780204773,0.981830298900604,32.4328765869141,0,30,4,200,0.000393091846490279,-4.66515874862671,0.752537965774536,1,,,,,,,,,,,,,,,,