File: Data/HeatCapacity/hc_sample_12232020_1p8_300K.dat
[Header]
TITLE,hc_sample_12232020_1p8_300K.dat
BYAPP,HeatCapacity,3.8.14,1.7
INFO,1,MASS:Sample Mass (mg)
INFO,,MASSERR:Sample Mass Error (mg)
INFO,,MOLWGHT:Formula Weight (g/mole)
INFO,,ATOMS:Atoms per Formula Unit
INFO,PPMS Heat Capacity Option 3.8.14 Build 19,APPNAME
DATATYPE,TIME,1
DATATYPE,COMMENT,2
STARTUPAXIS, X, 8, LINEAR, AUTO
STARTUPAXIS, Y1, 10, LINEAR, AUTO
[Data]
Time Stamp (Seconds),Comment (),System Status (Code),Puck Temp (Kelvin),System Temp (Kelvin),Field (Oersted),Pressure (Torr),Sample Temp (Kelvin),Temp Rise (Kelvin),Samp HC (µJ/K),Samp HC Err (µJ/K),Addenda HC (µJ/K),Addenda HC Err (µJ/K),Total HC (µJ/K),Total HC Err (µJ/K),Fit Deviation (ChiSquare),Time Const tau1 (seconds),Time Const tau2 (seconds),Sample Coupling (Percent),Debye Temp (Kelvin),Debye Temp Err (Kelvin),Cal Correction (Factor),Therm Resist (Ohms),Htr Resist (Ohms),Puck Resist (Ohms),Wire Cond (W/K),Meas Time (seconds),Temp Squared (K^2),Samp HC/Temp (µJ/K/K),Addenda Offset HC (µJ/K)
31059192.14,CALFILE: Puck967.cal - Addenda #129 measured on 12/23/2020 from 1.9147 to 302.39 K
31059192.28,,5905,1.89939,1.9013,-0.005,9.3E-6,1.916355,0.028203307,22.194085,0.03615,0.33150647,0.001959,22.525591,0.03615,0.99393064,9.9034838,0.0015652936,98.898555,0,0,1,,,,2.2991E-6,19.27578,3.6724165,11.581406,0
31059366.45,,5905,1.89939,1.9028,-0.005,9.3E-6,1.9171518,0.029369126,22.2375,0.04194,0.33180551,0.00196,22.569306,0.04194,0.86940412,10.247569,0.0015907249,98.917331,0,0,1,,,,2.2258E-6,20.09763,3.6754712,11.599238,0
31059802.16,,5905,2.29179,2.2951,-0.005,9.3E-6,2.305773,0.02107254,32.605561,0.06758,0.49011666,0.003057,33.095678,0.06758,0.38059143,7.7713954,0.0018631494,98.330491,0,0,1,,,,4.3289E-6,14.55602,5.3165893,14.140837,0
31060222.61,,5905,2.68124,2.6879,-0.005,9.3E-6,2.6951189,0.018447077,42.794329,0.2134,0.71253404,0.00456,43.506863,0.2134,0.45054159,6.6732537,0.0020532914,98.054528,0,0,1,,,,6.6448E-6,12.27836,7.2636659,15.878457,0
31060359.88,,5905,2.68232,2.6871,-0.005,9.3E-6,2.6976638,0.021720915,43.029116,0.08604,0.71450766,0.004571,43.743624,0.08604,0.74010555,7.9357564,0.0025050888,97.997739,0,0,1,,,,5.6212E-6,14.4713,7.2773898,15.950511,0
31060701.03,,5905,3.07325,3.0853,-0.005,9.3E-6,3.0877724,0.021579995,53.24962,0.1581,1.0122408,0.005633,54.261861,0.1581,0.23875551,7.7763488,0.0032418232,97.672493,0,0,1,,,,7.138E-6,13.41323,9.5343387,17.245319,0
31061052.13,,5905,3.46318,3.4772,-0.005,9.2E-6,3.4814047,0.026748401,63.552304,0.1713,1.404637,0.006202,64.956941,0.1713,0.40045621,7.9594473,0.0035677353,97.838474,0,0,1,,,,8.3337E-6,17.0049,12.120179,18.254788,0
31061206.36,,5905,3.46467,3.4785,-0.005,9.3E-6,3.4847619,0.03008336,63.656337,0.09378,1.4092531,0.006208,65.06559,0.09378,0.32030481,9.7443989,0.0033765337,98.339469,0,0,1,,,,6.7852E-6,17.78539,12.143565,18.267055,0
31061576.56,,5905,3.85565,3.8747,-0.005,9.2E-6,3.8785866,0.034026059,73.379444,0.1278,1.9011522,0.007008,75.280597,0.1278,0.43104117,10.256949,0.0042278751,98.299421,0,0,1,,,,7.4602E-6,18.61684,15.043434,18.91912,0
31061964.3,,5905,4.24646,4.2567,-0.005,9.3E-6,4.2744952,0.041200634,82.933291,0.1415,2.4814186,0.008086,85.414709,0.1415,0.52388575,10.533368,0.0041847883,98.573481,0,0,1,,,,8.2196E-6,22.35069,18.27131,19.401891,0
31062150.45,,5905,4.24797,4.2591,-0.005,9.3E-6,4.2781757,0.045996542,83.358067,0.0531,2.4890283,0.0081,85.847096,0.0531,0.32450606,12.85278,0.0046406113,98.702573,0,0,1,,,,6.7621E-6,23.4009,18.302787,19.484489,0
31062563.34,,5905,4.63828,4.6561,-0.005,9.2E-6,4.6719956,0.052517846,91.975511,0.0813,3.1572191,0.009106,95.13273,0.0813,0.68810119,13.44822,0.0055952064,98.688317,0,0,1,,,,7.1619E-6,24.78743,21.827543,19.686558,0
31062994.61,,5905,5.02844,5.0523,-0.005,9.3E-6,5.0678419,0.061951647,101.70701,0.1585,3.9211418,0.009938,105.62816,0.1585,0.074747155,14.053858,0.0071314296,98.562657,0,0,1,,,,7.6176E-6,28.83341,25.683021,20.069098,0
31063224.44,,5905,5.03062,5.055,-0.005,9.2E-6,5.0734317,0.067600628,101.48765,0.07764,3.9347537,0.009948,105.4224,0.07764,1.4502703,15.81421,0.0067248268,98.804262,0,0,1,,,,6.7411E-6,30.05834,25.739709,20.003748,0
31063670.09,,5905,5.42231,5.4446,-0.005,9.4E-6,5.4682509,0.073046468,111.00109,0.08737,4.793535,0.01086,115.79462,0.08737,1.6613948,16.050359,0.0076704304,98.783274,0,0,1,,,,7.2962E-6,30.39651,29.901768,20.299195,0
31064129.19,,5905,5.81197,5.8356,-0.005,9.2E-6,5.8618709,0.081379371,121.15367,0.1288,5.7628451,0.01346,126.91651,0.1288,0.15525681,16.187896,0.0085573976,98.767879,0,0,1,,,,7.9294E-6,33.42927,34.36153,20.668089,0
31064382.03,,5905,5.81411,5.8386,-0.005,9.2E-6,5.8667482,0.08593902,120.97464,0.05372,5.7783769,0.0135,126.75302,0.05372,0.6860351,17.539933,0.0080814561,98.931635,0,0,1,,,,7.2977E-6,33.89235,34.418734,20.620391,0
31064850.5,,5905,6.20538,6.2307,-0.005,9.3E-6,6.2602779,0.090712893,131.28963,0.08273,6.8474458,0.01713,138.13707,0.08273,0.72911878,17.685863,0.0096814654,98.82694,0,0,1,,,,7.8944E-6,33.77139,39.191079,20.971853,0
31065325.09,,5905,6.59435,6.6218,-0.005,9.3E-6,6.6526361,0.09828059,143.52622,0.1513,8.0044347,0.02141,151.53065,0.1513,0.15750506,17.905231,0.010386484,98.829694,0,0,1,,,,8.5529E-6,36.434,44.257567,21.574338,0
31065596.5,,5905,6.59632,6.6233,-0.005,9.4E-6,6.6580303,0.10281126,143.42208,0.09879,8.0242229,0.02146,151.4463,0.09879,0.6063268,18.973341,0.0099612705,98.9448,0,0,1,,,,8.0584E-6,36.94545,44.329368,21.541217,0
31066090.25,,5905,6.98844,7.0189,-0.005,9.3E-6,7.0519949,0.10809873,158.36293,0.1485,9.3025938,0.02225,167.66553,0.1485,3.1901979,19.502507,0.011236203,98.890907,0,0,1,,,,8.6832E-6,38.01098,49.730632,22.456473,0
31066719.86,,5905,7.37903,7.4096,-0.005,9.3E-6,7.4509124,0.11661657,128.76921,0.05336,10.708697,0.02111,139.47791,0.05336,0.95677202,15.521474,0.012502397,98.854321,0,0,1,,,,9.075E-6,30.30111,55.516095,17.282342,0
31066961.39,,5905,7.38052,7.4135,-0.005,9.2E-6,7.4547917,0.12156275,128.86159,0.06575,10.724767,0.02111,139.58636,0.06575,0.19271309,16.093906,0.012323577,98.912049,0,0,1,,,,8.7546E-6,31.58921,55.57392,17.28574,0
31067405.5,,5905,7.77078,7.8013,-0.005,9.2E-6,7.8468156,0.12514822,133.78539,0.08396,12.202347,0.022,145.98774,0.08396,0.97518749,15.457488,0.013293103,98.868534,0,0,1,,,,9.5353E-6,30.49957,61.572516,17.049641,0
31067850.31,,5905,8.15947,8.1906,-0.005,9.3E-6,8.2386079,0.13215722,140.15451,0.1443,13.778331,0.02422,153.93284,0.1443,0.16897206,15.179203,0.014774079,98.796104,0,0,1,,,,1.0244E-5,31.4862,67.87466,17.011916,0
31068089.13,,5905,8.16248,8.1947,-0.005,9.3E-6,8.2431462,0.13422442,140.05187,0.09903,13.799795,0.02426,153.85167,0.09903,1.0878037,15.69885,0.014050892,98.89576,0,0,1,,,,9.8909E-6,30.86589,67.949459,16.990099,0
31068532.81,,5905,8.55375,8.5908,-0.005,9.3E-6,8.6360298,0.13956289,146.56806,0.1137,15.494274,0.02882,162.06233,0.1137,2.9605489,15.54839,0.015204661,98.860733,0,0,1,,,,1.0521E-5,30.57035,74.581011,16.971694,0
31068976.5,,5905,8.94175,8.9801,-0.005,9.4E-6,9.0267011,0.14673715,154.50214,0.1677,17.283587,0.03518,171.78573,0.1677,0.44332265,15.601255,0.01698407,98.787785,0,0,1,,,,1.112E-5,31.75342,81.481333,17.116125,0
31069218.13,,5905,8.94523,8.9828,-0.005,9.2E-6,9.0331167,0.14984484,154.36551,0.1216,17.317013,0.03529,171.68252,0.1216,0.69544682,16.036871,0.01572597,98.911384,0,0,1,,,,1.0801E-5,31.53773,81.597197,17.088842,0
31069672,,5905,9.33643,9.3742,-0.005,9.2E-6,9.4269833,0.15649706,162.76616,0.1027,19.228827,0.03938,181.99498,0.1027,20.309316,16.159032,0.016976728,98.880589,0,0,1,,,,1.1365E-5,31.93746,88.868014,17.265986,0
31070123.56,,5905,9.72613,9.7635,-0.005,9.3E-6,9.8188907,0.16280375,171.63801,0.1872,21.243681,0.04035,192.88169,0.1872,0.32473799,16.386059,0.019151259,98.798995,0,0,1,,,,1.1885E-5,32.75536,96.410615,17.480387,0
31070374.28,,5905,9.72987,9.7654,-0.005,9.3E-6,9.8262133,0.16781513,171.50267,0.1465,21.283947,0.04035,192.78662,0.1465,1.5406003,16.767436,0.017900566,98.905964,0,0,1,,,,1.1598E-5,33.14302,96.554467,17.453587,0
31071138.11,,5905,10.1195,10.1333,-0.005,9.3E-6,10.221595,0.18052245,180.95875,0.1632,23.421604,0.04049,204.38036,0.1632,0.18649836,17.525204,0.018004715,98.981538,0,0,1,,,,1.1756E-5,34.69354,104.481,17.703573,0
31071617.64,,5905,10.5123,10.526,-0.005,9.2E-6,10.615714,0.18643268,191.0429,0.1699,25.630882,0.04138,216.67378,0.1699,2.6798582,17.737636,0.019657604,98.931045,0,0,1,,,,1.2318E-5,35.58611,112.69337,17.996237,0
31071886.88,,5905,10.5123,10.5285,-0.005,9.4E-6,10.61955,0.1900739,191.30338,0.1959,25.655706,0.04139,216.95908,0.1959,0.87533502,17.871274,0.019835581,98.929097,0,0,1,,,,1.2242E-5,35.95605,112.77483,18.014265,0
31072369.3,,5905,10.9049,10.9108,-0.005,9.3E-6,11.015354,0.198486,202.31078,0.1736,27.966835,0.04235,230.27761,0.1736,0.84155914,18.373184,0.020371016,98.954879,0,0,1,,,,1.2636E-5,36.63323,121.33801,18.366254,0
31072856.73,,5905,11.2957,11.3019,-0.005,9.3E-6,11.406823,0.20314221,214.40703,0.2057,30.357585,0.044,244.76462,0.2057,20.289618,18.817095,0.02213612,98.910817,0,0,1,,,,1.3118E-5,37.20204,130.1156,18.796385,0
31073138.61,,5905,11.2971,11.3025,-0.005,9.2E-6,11.411919,0.20947725,214.40283,0.2057,30.395791,0.04404,244.79862,0.2057,0.491241,19.168327,0.021747309,98.950799,0,0,1,,,,1.2875E-5,37.94031,130.2319,18.787622,0
31073632.84,,5905,11.6878,11.6962,-0.005,9.3E-6,11.806436,0.21803823,226.47685,0.2297,32.935759,0.04709,259.41261,0.2297,0.43514921,19.592491,0.022034491,98.979871,0,0,1,,,,1.3345E-5,38.87633,139.39193,19.182491,0
31074134.36,,5905,12.0779,12.0929,-0.005,9.3E-6,12.198961,0.22323308,240.42049,0.2909,35.582052,0.05123,276.00254,0.2909,0.96973314,20.348699,0.024372408,98.927426,0,0,1,,,,1.3675E-5,39.59385,148.81465,19.708276,0
31074433.3,,5905,12.0797,12.0948,-0.005,9.4E-6,12.20528,0.23068673,240.55572,0.2813,35.627969,0.0513,276.18369,0.2813,0.41130422,20.541535,0.023441989,98.97889,0,0,1,,,,1.355E-5,40.72556,148.96886,19.709152,0
31074949.83,,5905,12.4702,12.4854,-0.005,9.3E-6,12.60114,0.24038,256.32542,0.3014,38.398,0.05572,294.72342,0.3014,1.0464052,21.28467,0.024720976,98.969492,0,0,1,,,,1.3956E-5,42.28561,158.78873,20.341447,0
31075473.06,,5905,12.8606,12.8779,-0.005,9.3E-6,12.991968,0.24230194,274.01092,0.3451,41.204646,0.05957,315.21557,0.3451,13.72705,22.153872,0.026113588,98.957051,0,0,1,,,,1.4342E-5,42.62908,168.79124,21.090793,0
31075793.72,,5905,12.8631,12.8788,-0.005,9.3E-6,12.999991,0.25211868,274.26918,0.3629,41.262368,0.05964,315.53155,0.3629,1.1512625,22.244794,0.024560736,99.023752,0,0,1,,,,1.429E-5,44.42947,168.99976,21.097644,0
31076333.69,,5905,13.2534,13.2712,-0.005,9.3E-6,13.396943,0.26231999,297.09502,0.4804,44.203686,0.06319,341.2987,0.4804,1.3280682,23.361619,0.023949112,99.086372,0,0,1,,,,1.4712E-5,46.94447,179.47808,22.176329,0
31076884.64,,5905,13.6441,13.6597,-0.005,9.3E-6,13.784967,0.25646008,331.09735,0.7786,47.169191,0.06676,378.26654,0.7786,13.345161,25.271218,0.027406168,99.001059,0,0,1,,,,1.5084E-5,46.97694,190.02531,24.018727,0
31077242.28,,5905,13.6461,13.6621,-0.005,9.2E-6,13.795105,0.27165954,332.36354,0.8331,47.247764,0.06685,379.6113,0.8331,1.5566318,25.402379,0.025409041,99.077522,0,0,1,,,,1.5051E-5,50.50478,190.30492,24.09286,0
31077820.56,,5905,14.0365,14.0527,-0.005,9.4E-6,14.170085,0.30030178,272.30276,9.125,50.241483,0.07087,322.54424,9.125,1858.0731,23.843144,0.076348681,97.538427,0,0,1,,,,1.3772E-5,44.17776,200.7913,19.216735,0
31078514.91,,5905,14.4274,14.4516,-0.005,9.4E-6,14.583097,0.29526651,159.29927,0.183,53.55643,0.07616,212.85569,0.183,14.210526,13.801297,0.033179354,98.721214,0,0,1,,,,1.5535E-5,27.60805,212.66672,10.923555,0
31078735.52,,5905,14.4288,14.451,-0.005,9.3E-6,14.584381,0.29573392,159.4604,0.1829,53.566618,0.07618,213.02702,0.1829,1.5819604,13.784546,0.031557945,98.781823,0,0,1,,,,1.5561E-5,27.56178,212.70416,10.933642,0
31079156.14,,5905,14.8182,14.8443,-0.005,9.3E-6,14.982863,0.3037566,151.86934,0.1,56.894882,0.08205,208.76422,0.1,0.43362284,13.070952,0.032281436,98.753294,0,0,1,,,,1.6079E-5,26.25311,224.48617,10.136203,0
31079572.7,,5905,15.2104,15.233,-0.005,9.3E-6,15.378339,0.31192471,149.60091,0.1223,60.280506,0.08793,209.88141,0.1223,0.51351124,12.798165,0.033368488,98.726062,0,0,1,,,,1.6507E-5,26.02697,236.49332,9.7280276,0
31079779.78,,5905,15.2116,15.2324,-0.005,9.3E-6,15.380442,0.31169684,149.46274,0.118,60.307557,0.08798,209.7703,0.118,0.10765938,12.730251,0.031745052,98.782318,0,0,1,,,,1.6581E-5,25.52989,236.558,9.7177142,0
31080189.39,,5905,15.6013,15.6236,-0.005,9.3E-6,15.774996,0.32086743,149.11765,0.1255,63.761206,0.0933,212.87885,0.1255,1.9952647,12.572962,0.032131486,98.782124,0,0,1,,,,1.7034E-5,25.28962,248.85049,9.4527854,0
31080596.67,,5905,15.9906,16.0219,-0.005,9.2E-6,16.164089,0.32664692,150.17429,0.1545,67.238961,0.0976,217.41325,0.1545,1.4059037,12.590169,0.035429202,98.683392,0,0,1,,,,1.7379E-5,25.18421,261.27778,9.2906123,0
31080801.31,,5905,15.9934,16.0267,-0.005,9.3E-6,16.171508,0.32944574,150.19439,0.1403,67.306858,0.09767,217.50125,0.1403,8.2817473,12.540994,0.033866889,98.736922,0,0,1,,,,1.7449E-5,25.0867,261.51768,9.2875934,0
31081210.45,,5905,16.3854,16.4149,-0.005,9.2E-6,16.566744,0.33936446,152.199,0.1593,70.921728,0.1014,223.12073,0.1593,15.528722,12.576597,0.034996164,98.717699,0,0,1,,,,1.7848E-5,25.18676,274.457,9.1870195,0
31081618.63,,5905,16.7748,16.7993,-0.005,9.2E-6,16.957726,0.34222052,154.65336,0.1677,74.564101,0.105,229.21746,0.1677,2.4918638,12.592566,0.035991986,98.699166,0,0,1,,,,1.8312E-5,24.97114,287.56447,9.1199352,0
31081824.7,,5905,16.7758,16.8028,-0.005,9.4E-6,16.964164,0.34629096,154.86793,0.1599,74.627192,0.1051,229.49513,0.1599,2.3178986,12.555988,0.034612081,98.745107,0,0,1,,,,1.8384E-5,25.07869,287.78285,9.1291228,0
31082231.47,,5905,17.1669,17.1905,-0.005,9.4E-6,17.358107,0.35609125,157.61607,0.1684,78.37679,0.1092,235.99286,0.1684,4.4512895,12.608281,0.034831562,98.756142,0,0,1,,,,1.8823E-5,25.30188,301.30388,9.0802568,0
31082640.67,,5905,17.5562,17.585,-0.005,9.3E-6,17.748317,0.35943577,161.13524,0.189,82.155339,0.1141,243.29058,0.189,1.7566298,12.761907,0.038404967,98.656583,0,0,1,,,,1.9178E-5,25.25253,315.00275,9.0789025,0
31082845.89,,5905,17.5601,17.5855,-0.005,9.4E-6,17.755489,0.36477503,161.08167,0.1819,82.228114,0.1142,243.30978,0.1819,0.96337928,12.697275,0.036151588,98.72938,0,0,1,,,,1.9271E-5,25.44192,315.2574,9.0722178,0
31083256.52,,5905,17.9508,17.9769,-0.005,9.3E-6,18.150117,0.37393929,164.89967,0.1949,86.105814,0.1196,251.00548,0.1949,4.3843629,12.822428,0.037579613,98.701768,0,0,1,,,,1.9687E-5,25.73397,329.42674,9.0853225,0
31083671.5,,5905,18.3413,18.3698,-0.005,9.4E-6,18.539872,0.37595658,168.9625,0.2087,90.013957,0.1253,258.97646,0.2087,1.9143303,12.986244,0.039151808,98.673033,0,0,1,,,,2.0057E-5,25.62774,343.72684,9.1134665,0
31083881.19,,5905,18.343,18.3722,-0.005,9.3E-6,18.546628,0.38186319,169.07183,0.2019,90.086871,0.1254,259.1587,0.2019,2.202304,12.949941,0.037904274,98.711711,0,0,1,,,,2.0124E-5,25.87713,343.97741,9.1160412,0
31084293.83,,5905,18.7344,18.7615,-0.005,9.2E-6,18.940596,0.39139424,173.19608,0.2067,94.12204,0.1318,267.31812,0.2067,4.0186239,13.082979,0.039307622,98.685657,0,0,1,,,,2.0547E-5,26.27606,358.74618,9.1441727,0
31084710.3,,5905,19.1219,19.1556,-0.005,9.3E-6,19.328933,0.3929628,177.46656,0.2312,98.174759,0.1388,275.64132,0.2312,1.8230307,13.292728,0.041868944,98.629555,0,0,1,,,,2.0856E-5,26.16712,373.60766,9.1813944,0
31084922.13,,5905,19.1269,19.1576,-0.005,9.4E-6,19.337147,0.39957508,177.50939,0.219,98.266226,0.1389,275.77562,0.219,1.8922145,13.235553,0.040422141,98.671378,0,0,1,,,,2.0953E-5,26.47134,373.92526,9.1797093,0
31085340.42,,5905,19.5172,19.5496,-0.005,9.3E-6,19.729969,0.40869172,182.12611,0.2301,102.4506,0.1471,284.57671,0.2301,7.1912478,13.409527,0.041279102,98.667066,0,0,1,,,,2.134E-5,26.84253,389.27167,9.2309377,0
31085757.58,,5905,19.9063,19.9334,-0.005,9.4E-6,20.118865,0.40944889,186.85931,0.2567,106.7081,0.1569,293.56741,0.2567,1.9354431,13.607273,0.043829698,98.611374,0,0,1,,,,2.1698E-5,26.77406,404.76872,9.2877661,0
31085976.34,,5905,19.909,19.9344,-0.005,9.3E-6,20.125828,0.41656571,187.13504,0.2461,106.79206,0.1571,293.9271,0.2461,2.4267402,13.58234,0.042977548,98.635549,0,0,1,,,,2.1762E-5,27.14788,405.04894,9.298253,0
31086399.41,,5905,20.3019,20.329,-0.005,9.2E-6,20.522642,0.42532906,192.14121,0.2636,111.23178,0.168,303.37299,0.2636,4.1882728,13.751246,0.043991619,98.626022,0,0,1,,,,2.2185E-5,27.55185,421.17883,9.3624012,0
31086822.53,,5905,20.687,20.7243,-0.005,9.3E-6,20.903464,0.42480017,197.41305,0.2787,115.54217,0.1783,312.95522,0.2787,2.9965806,13.957204,0.046463701,98.574627,0,0,1,,,,2.2552E-5,27.46804,436.95482,9.4440351,0
31087043.56,,5905,20.6917,20.7298,-0.005,9.3E-6,20.913928,0.43255487,197.3662,0.2714,115.64781,0.1785,313.01401,0.2714,1.2445908,13.875832,0.043491311,98.658185,0,0,1,,,,2.2681E-5,27.84169,437.3924,9.4370697,0
31087468.52,,5905,21.0822,21.1145,-0.005,9.2E-6,21.311809,0.44041625,202.63289,0.2802,120.19669,0.1881,322.82958,0.2802,7.0309503,14.068057,0.045604998,98.61683,0,0,1,,,,2.3075E-5,28.15916,454.19322,9.5080097,0
31087896.48,,5905,21.473,21.4988,-0.005,9.4E-6,21.697559,0.44021499,208.15047,0.2932,124.60895,0.1954,332.75942,0.2932,5.2901054,14.287441,0.047368682,98.588873,0,0,1,,,,2.3421E-5,28.10753,470.78405,9.5932667,0
31088122.36,,5905,21.4756,21.4997,-0.005,9.3E-6,21.706469,0.44747558,208.23788,0.2893,124.71568,0.1955,332.95356,0.2893,0.97897908,14.211388,0.044967452,98.653209,0,0,1,,,,2.3554E-5,28.48945,471.17078,9.5933558,0
31088553.63,,5905,21.8664,21.8874,-0.005,9.2E-6,22.101566,0.45738343,213.88108,0.2937,129.23133,0.2002,343.11241,0.2937,3.0093696,14.422683,0.046140626,98.641435,0,0,1,,,,2.3918E-5,28.97988,488.47921,9.6771915,0
31088987.16,,5905,22.2546,22.2888,-0.005,9.2E-6,22.483945,0.45647493,219.4279,0.3233,133.63134,0.2029,353.05924,0.3233,1.2372931,14.714125,0.051108341,98.528271,0,0,1,,,,2.4134E-5,28.83332,505.52779,9.7593148,0
31089218.3,,5905,22.2562,22.2931,-0.005,9.4E-6,22.494171,0.46442727,219.59243,0.3038,133.75373,0.203,353.34616,0.3038,1.3185269,14.618988,0.04749934,98.623068,0,0,1,,,,2.4301E-5,29.28495,505.98772,9.7621927,0
31089654.06,,5905,22.6499,22.6759,-0.005,9.2E-6,22.889367,0.47297287,225.18337,0.319,138.34317,0.2046,363.52653,0.319,0.64313984,14.785148,0.048459902,98.614008,0,0,1,,,,2.472E-5,29.72524,523.92314,9.8379025,0
31090089.8,,5905,23.04,23.0603,-0.005,9.2E-6,23.27816,0.47181415,230.88149,0.3115,142.90116,0.2061,373.78265,0.3115,8.9336991,15.018605,0.051130227,98.563153,0,0,1,,,,2.5027E-5,29.59037,541.87271,9.9183738,0
31090325.31,,5905,23.0414,23.0622,-0.005,9.3E-6,23.286015,0.4796419,231.1612,0.3099,142.98207,0.2061,374.14326,0.3099,2.0245468,14.987447,0.04979296,98.597494,0,0,1,,,,2.51E-5,29.94238,542.23848,9.9270399,0
31090766.33,,5905,23.4315,23.4601,-0.005,9.4E-6,23.679897,0.48844712,236.83128,0.3123,147.67849,0.2084,384.50977,0.3123,15.553969,15.173546,0.050419586,98.599996,0,0,1,,,,2.5478E-5,30.43599,560.73753,10.001364,0
31091206.27,,5905,23.8226,23.8523,-0.005,9.2E-6,24.066177,0.48736918,242.61388,0.3311,152.35787,0.2122,394.97175,0.3311,3.5272313,15.41913,0.054110772,98.524189,0,0,1,,,,2.5761E-5,30.33975,579.18086,10.081115,0
31091445.19,,5905,23.8251,23.8532,-0.005,9.4E-6,24.074816,0.49511425,242.69103,0.3306,152.46916,0.2123,395.16019,0.3306,1.2657935,15.342334,0.051353989,98.592277,0,0,1,,,,2.5895E-5,30.72644,579.59679,10.080701,0
31091891.67,,5905,24.214,24.2425,-0.005,9.3E-6,24.472032,0.50458822,248.8774,0.3415,157.35795,0.2177,406.23535,0.3415,1.3513905,15.544429,0.052734481,98.575428,0,0,1,,,,2.6276E-5,31.26075,598.88034,10.169871,0
31092340.17,,5905,24.6077,24.6289,-0.005,9.3E-6,24.85998,0.50258251,254.63591,0.3488,162.21207,0.2235,416.84797,0.3488,5.3507313,15.780078,0.056120686,98.509431,0,0,1,,,,2.6566E-5,31.09824,618.01861,10.242804,0
31092581.94,,5905,24.6062,24.6308,-0.005,9.4E-6,24.868521,0.51088779,254.86102,0.3451,162.3275,0.2236,417.18852,0.3451,1.1019172,15.734214,0.053683437,98.56974,0,0,1,,,,2.6659E-5,31.49572,618.44336,10.248338,0
31093033.38,,5905,24.9991,25.0398,-0.005,9.4E-6,25.259089,0.52086718,261.42499,0.3736,167.28204,0.2302,428.70703,0.3736,15.764793,16.060318,0.058988696,98.462349,0,0,1,,,,2.6849E-5,32.05531,638.02159,10.349739,0
31095295.05,,5905,10.0001,10.0088,-0.005,9.4E-6,10.112953,0.2061892,178.4592,0.1749,22.840859,0.0404,201.30006,0.1749,5.8328784,20.0432,0.01873126,99.06593,0,0,1,,,,1.0118E-5,39.48683,102.27182,17.646596,0
31095593.64,,5905,9.99993,10.0098,-0.005,9.2E-6,10.112615,0.20533628,178.46634,0.1832,22.838443,0.0404,201.30478,0.1832,0.36170214,20.017999,0.018956853,99.053313,0,0,1,,,,1.0132E-5,39.962,102.26499,17.647891,0
31096084.25,,5905,10.172,10.1829,-0.005,9.3E-6,10.286928,0.20997785,182.82394,0.1857,23.795712,0.0406,206.61965,0.1857,0.45240432,20.158177,0.019399464,99.050472,0,0,1,,,,1.0327E-5,40.56504,105.82088,17.772453,0
31096885.45,,5905,10.3442,10.355,-0.005,9.3E-6,10.459441,0.20932539,186.77042,0.1689,24.76105,0.04103,211.53147,0.1689,4.9216675,20.212798,0.019142789,99.078891,0,0,1,,,,1.0541E-5,40.1995,109.39991,17.856635,0
31097186.11,,5905,10.3456,10.3529,-0.005,9.3E-6,10.461755,0.21235946,187.3699,0.1914,24.773308,0.04104,212.14321,0.1914,0.48980504,20.276779,0.020127115,99.03231,0,0,1,,,,1.0542E-5,40.46957,109.44831,17.909988,0
31097676.56,,5905,10.5164,10.5251,-0.005,9.2E-6,10.635074,0.21680755,191.69649,0.1997,25.758708,0.04143,217.4552,0.1997,0.57990221,20.345435,0.019483965,99.078165,0,0,1,,,,1.0766E-5,41.0136,113.10479,18.024933,0
31098172.2,,5905,10.6891,10.6971,-0.005,9.3E-6,10.806586,0.21635819,196.56974,0.2027,26.74948,0.04181,223.31922,0.2027,18.087699,20.627758,0.021130535,99.023132,0,0,1,,,,1.0909E-5,40.78358,116.78229,18.18981,0
31098473.25,,5905,10.6904,10.697,-0.005,9.4E-6,10.810033,0.22026989,196.4594,0.2178,26.771807,0.04182,223.23121,0.2178,0.5145388,20.611393,0.021143789,99.022784,0,0,1,,,,1.0913E-5,41.09331,116.85682,18.173802,0
31098965.19,,5905,10.8612,10.8689,-0.005,9.2E-6,10.983625,0.22362682,201.48256,0.2061,27.790862,0.04227,229.27342,0.2061,0.71161275,20.633414,0.020265029,99.073258,0,0,1,,,,1.1192E-5,41.4771,120.64002,18.343904,0
31099462.64,,5905,11.0324,11.041,-0.005,9.3E-6,11.153676,0.22332015,206.72869,0.218,28.812289,0.04283,235.54098,0.218,41.468742,20.925071,0.022132963,99.009444,0,0,1,,,,1.1343E-5,41.45905,124.40449,18.534579,0
31099769.02,,5905,11.0338,11.0409,-0.005,9.3E-6,11.156477,0.22687554,206.78999,0.2442,28.830993,0.04284,235.62098,0.2442,0.26297324,20.860733,0.02174207,99.024278,0,0,1,,,,1.1381E-5,41.70491,124.46698,18.53542,0
31100271.39,,5905,11.2068,11.2149,-0.005,9.2E-6,11.331251,0.22987422,211.84091,0.216,29.903938,0.04361,241.74485,0.216,0.6482952,20.935859,0.021369206,99.053544,0,0,1,,,,1.1632E-5,41.98401,128.39726,18.695279,0
31100767.61,,5905,11.3785,11.387,-0.005,9.2E-6,11.502321,0.22975254,216.85666,0.2353,30.977551,0.04461,247.83422,0.2353,4.3182337,21.213587,0.022318145,99.033053,0,0,1,,,,1.177E-5,41.90072,132.30339,18.853296,0
31101078.7,,5905,11.3792,11.3881,-0.005,9.4E-6,11.505143,0.23323607,217.27042,0.258,30.997627,0.04463,248.26805,0.258,0.28463815,21.182275,0.022847366,99.007582,0,0,1,,,,1.1811E-5,42.24157,132.36833,18.884634,0
31101585.53,,5905,11.5512,11.5613,-0.005,9.2E-6,11.679857,0.23760924,222.58757,0.231,32.118153,0.04596,254.70572,0.231,0.72116097,21.283242,0.022169996,99.049933,0,0,1,,,,1.2055E-5,42.87674,136.41907,19.057388,0
31102087.3,,5905,11.7232,11.7337,-0.005,9.2E-6,11.848573,0.23615929,227.93362,0.2556,33.225387,0.04751,261.15901,0.2556,6.8582151,21.579354,0.023687187,99.006215,0,0,1,,,,1.2195E-5,42.45964,140.38869,19.23722,0
31102403.39,,5905,11.7236,11.7348,-0.005,9.4E-6,11.853257,0.24067249,228.03354,0.2561,33.258161,0.04756,261.2917,0.2561,1.3258022,21.424338,0.022530886,99.048494,0,0,1,,,,1.2285E-5,43.05392,140.49969,19.23805,0
31102914.36,,5905,11.8962,11.908,-0.005,9.2E-6,12.028309,0.24428657,234.07901,0.2811,34.429226,0.04936,268.50824,0.2811,0.31920352,21.665321,0.023238409,99.035572,0,0,1,,,,1.2485E-5,43.53973,144.68022,19.460675,0
31103420.55,,5905,12.0691,12.0798,-0.005,9.3E-6,12.197497,0.2432091,240.28828,0.295,35.582894,0.05123,275.87118,0.295,8.5300539,22.056987,0.024792684,98.99422,0,0,1,,,,1.2604E-5,43.37926,148.77893,19.699803,0
31103740.81,,5905,12.0692,12.0799,-0.005,9.3E-6,12.20149,0.24761631,240.42005,0.2895,35.612528,0.05128,276.03258,0.2895,0.7444802,21.964381,0.023841587,99.029111,0,0,1,,,,1.2661E-5,43.85704,148.87635,19.704156,0
31104257.56,,5905,12.2407,12.2533,-0.005,9.3E-6,12.375188,0.25093604,247.0732,0.3032,36.817275,0.05324,283.89048,0.3032,1.1994522,22.162566,0.024115139,99.031085,0,0,1,,,,1.2904E-5,44.37917,153.14529,19.965207,0
31104773.42,,5905,12.413,12.427,-0.005,9.2E-6,12.546031,0.24944466,254.07445,0.324,38.016894,0.05514,292.09135,0.324,30.026998,22.5675,0.025580939,98.993524,0,0,1,,,,1.3043E-5,44.26299,157.4029,20.251381,0
31105099.67,,5905,12.4141,12.4285,-0.005,9.2E-6,12.551191,0.25452092,254.20989,0.3229,38.051703,0.05519,292.2616,0.3229,0.75664871,22.440068,0.024482005,99.031761,0,0,1,,,,1.3121E-5,44.8852,157.53239,20.253847,0
31105617.88,,5905,12.5852,12.5999,-0.005,9.3E-6,12.723867,0.25813603,261.72162,0.3458,39.277763,0.05701,300.99939,0.3458,0.58168224,22.75165,0.024925623,99.029576,0,0,1,,,,1.3328E-5,45.56303,161.8968,20.569346,0
31106142.19,,5905,12.7575,12.772,-0.005,9.3E-6,12.894972,0.25637388,269.35219,0.3684,40.507336,0.05867,309.85953,0.3684,10.258926,23.15145,0.025869058,99.011678,0,0,1,,,,1.3485E-5,45.47047,166.2803,20.888156,0
31106473.59,,5905,12.7589,12.7714,-0.005,9.4E-6,12.899505,0.26110156,269.40467,0.3704,40.542159,0.05872,309.94683,0.3704,0.88202464,22.996433,0.024777694,99.047641,0,0,1,,,,1.3576E-5,46.01108,166.39723,20.884884,0
31107003.61,,5905,12.9318,12.9451,-0.005,9.2E-6,13.074399,0.26516121,278.61457,0.4091,41.816021,0.06033,320.43059,0.4091,0.67447617,23.409007,0.024864877,99.059323,0,0,1,,,,1.3787E-5,46.99207,170.93992,21.309933,0
31107533.36,,5905,13.1018,13.1167,-0.005,9.3E-6,13.242997,0.26314485,287.69549,0.4474,43.061327,0.06183,330.75682,0.4474,11.176993,23.953645,0.026607665,99.014049,0,0,1,,,,1.3912E-5,47.01908,175.37698,21.724349,0
31107877.52,,5905,13.1038,13.1186,-0.005,9.3E-6,13.248236,0.26860072,288.23732,0.4505,43.099057,0.06188,331.33637,0.4505,0.9686853,23.848173,0.025668921,99.044063,0,0,1,,,,1.3995E-5,47.81362,175.51576,21.756656,0
31108418.95,,5905,13.2753,13.2904,-0.005,9.2E-6,13.422395,0.27195022,299.21839,0.5216,44.401659,0.06342,343.62004,0.5216,1.4790998,24.326487,0.025323037,99.070361,0,0,1,,,,1.4226E-5,48.80915,180.1607,22.292473,0
31108958.63,,5905,13.4465,13.4632,-0.005,9.2E-6,13.591059,0.26777827,311.98358,0.6129,45.681299,0.06494,357.66488,0.6129,12.679446,25.117373,0.02780689,99.001034,0,0,1,,,,1.4349E-5,48.63933,184.71689,22.95506,0
31109314.81,,5905,13.4478,13.4633,-0.005,9.4E-6,13.597252,0.27454075,312.62186,0.6168,45.727388,0.06499,358.34924,0.6168,1.5919568,24.917417,0.025278505,99.084276,0,0,1,,,,1.4483E-5,49.89534,184.88525,22.991547,0
31109874.45,,5905,13.6206,13.6382,-0.005,9.3E-6,13.773647,0.27916027,330.05772,0.8115,47.082555,0.06665,377.14027,0.8115,2.0968831,25.829953,0.024571962,99.125191,0,0,1,,,,1.47E-5,52.04308,189.71334,23.962987,0
31110430.42,,5905,13.7916,13.8075,-0.005,9.3E-6,13.938475,0.26919534,353.65239,1.261,48.370431,0.06829,402.02282,1.261,15.672416,27.202838,0.0265623,99.07269,0,0,1,,,,1.4886E-5,51.56039,194.28109,25.372387,0
31110812.77,,5905,13.7917,13.8083,-0.005,9.4E-6,13.946619,0.27912246,355.73403,1.3,48.427509,0.06837,404.16154,1.3,7.4654572,27.016942,0.0222761,99.214791,0,0,1,,,,1.5051E-5,54.09747,194.50818,25.506829,0
31111406.25,,5905,13.9657,13.9813,-0.005,9.2E-6,14.12365,0.30927673,333.94256,11.49,49.839995,0.07029,383.78255,11.49,368.95014,25.79553,0,100,0,0,1,,,,1.4878E-5,59.94201,199.47749,23.644211,0
31112146.64,,5905,14.137,14.1553,-0.005,9.4E-6,14.283964,0.33177165,188.13093,2.831,51.156192,0.07224,239.28712,2.831,313.82351,18.203211,0.065566496,97.845531,0,0,1,,,,1.3325E-5,37.02948,204.03164,13.170778,0
31112456.64,,5905,14.1379,14.1556,-0.005,9.3E-6,14.284152,0.32939456,188.01061,2.79,51.15445,0.07223,239.16506,2.79,94.506681,18.123512,0.065179958,97.849597,0,0,1,,,,1.3376E-5,36.40045,204.03699,13.162183,0
31112898.67,,5905,14.3089,14.3285,-0.005,9.2E-6,14.465424,0.30026982,164.49508,0.3163,52.591273,0.07453,217.08635,0.3163,8.0789355,14.486507,0.035496499,98.662408,0,0,1,,,,1.5102E-5,29.20494,209.2485,11.371604,0
31113310.58,,5905,14.4798,14.5007,-0.005,9.3E-6,14.638767,0.30548543,157.83542,0.1706,54.007304,0.07694,211.84272,0.1706,0.60605769,13.881038,0.034939795,98.672778,0,0,1,,,,1.5376E-5,28.95212,214.29349,10.782016,0
31113532.11,,5905,14.4821,14.5019,-0.005,9.2E-6,14.644502,0.30061648,157.70912,0.1525,54.058952,0.07703,211.76807,0.1525,2.9111114,13.84682,0.034197704,98.698936,0,0,1,,,,1.5406E-5,27.69821,214.46145,10.769169,0
31113933.95,,5905,14.6535,14.6729,-0.005,9.4E-6,14.817591,0.30298934,154.06108,0.1061,55.501602,0.07957,209.56268,0.1061,0.98567027,13.445858,0.032693934,98.749794,0,0,1,,,,1.5693E-5,26.97866,219.56099,10.397175,0
31114336,,5905,14.8242,14.8478,-0.005,9.3E-6,14.991001,0.30559464,151.73413,0.1045,56.958442,0.08216,208.69257,0.1045,0.68614076,13.225498,0.033351425,98.728179,0,0,1,,,,1.5887E-5,26.82584,224.73011,10.121681,0
31114548.73,,5905,14.828,14.8478,-0.005,9.3E-6,14.993724,0.30615348,151.6362,0.1018,56.990144,0.08222,208.62635,0.1018,0.12712183,13.149836,0.031717867,98.784235,0,0,1,,,,1.5969E-5,26.38445,224.81175,10.113312,0
31114940.8,,5905,14.9989,15.02,-0.005,9.4E-6,15.168346,0.31078586,150.15688,0.09816,58.476209,0.08484,208.63309,0.09816,0.2995635,12.982316,0.031456909,98.798223,0,0,1,,,,1.6172E-5,26.17178,230.07874,9.8993575,0
31115915.36,,5905,4.99465,5.0189,-0.005,9.2E-6,5.0535573,0.10032243,102.12869,0.3318,3.9021129,0.009924,106.0308,0.3318,0.5053889,24.30559,0.0033576453,99.608978,0,0,1,,,,4.3783E-6,43.53551,25.538441,20.209267,0
31116592.69,,5905,4.99964,5.0257,-0.005,9.3E-6,5.0609758,0.10533274,100.72964,0.08971,3.9162391,0.009935,104.64588,0.08971,0.25330325,23.792889,0.0068645242,99.193536,0,0,1,,,,4.4313E-6,47.70297,25.613476,19.903205,0
31117115.75,,5905,5.10174,5.1266,-0.005,9.3E-6,5.1641838,0.1083235,103.16331,0.07752,4.1303944,0.01008,107.29371,0.07752,0.75928965,23.907291,0.0069014874,99.214847,0,0,1,,,,4.5208E-6,48.41417,26.668795,19.976692,0
31117718.55,,5905,5.20532,5.2293,-0.005,9.2E-6,5.2673517,0.10804613,105.60096,0.114,4.3505493,0.01026,109.95151,0.114,0.16173523,24.067232,0.0073118327,99.195067,0,0,1,,,,4.6027E-6,47.63018,27.744994,20.048207,0
31118061.55,,5905,5.20763,5.2363,-0.005,9.2E-6,5.27018,0.109518,105.65212,0.1516,4.3568194,0.01027,110.00894,0.1516,0.21414043,23.848699,0.0076745352,99.147803,0,0,1,,,,4.6494E-6,47.8867,27.774797,20.047156,0
31118583.42,,5905,5.30891,5.3316,-0.005,9.4E-6,5.3737154,0.11233836,108.11463,0.103,4.5859814,0.01053,112.70061,0.103,0.89427899,23.970889,0.0074746522,99.195744,0,0,1,,,,4.7367E-6,48.45103,28.876817,20.119157,0
31119106.97,,5905,5.41146,5.4323,-0.005,9.3E-6,5.4755735,0.11208963,110.85804,0.1211,4.8188948,0.01091,115.67693,0.1211,1.0363233,24.290657,0.0083341716,99.134301,0,0,1,,,,4.8004E-6,47.79617,29.981905,20.245923,0
31119453.5,,5905,5.41321,5.4343,-0.005,9.3E-6,5.4793979,0.11339267,110.89928,0.08678,4.8276045,0.01093,115.72689,0.08678,0.37938558,23.88055,0.0072715833,99.233358,0,0,1,,,,4.8805E-6,47.97592,30.023801,20.239319,0
31119981.94,,5905,5.51535,5.5365,-0.005,9.2E-6,5.5828554,0.11637178,113.49561,0.1083,5.0729093,0.01148,118.56852,0.1083,0.56371576,24.080393,0.008013071,99.181888,0,0,1,,,,4.9611E-6,48.62443,31.168275,20.329311,0
31120508.33,,5905,5.61889,5.6422,-0.005,9.4E-6,5.6846069,0.11622966,116.02378,0.1533,5.3225061,0.01214,121.34629,0.1533,0.11082036,24.335098,0.0087604919,99.135402,0,0,1,,,,5.0262E-6,48.0637,32.314756,20.410167,0
31120855.44,,5905,5.62059,5.6437,-0.005,9.3E-6,5.6881855,0.11762896,116.0446,0.1069,5.3313449,0.01217,121.37595,0.1069,0.26010506,24.02767,0.0080616028,99.195692,0,0,1,,,,5.089E-6,48.18545,32.355454,20.400988,0
31121390.86,,5905,5.72316,5.7466,-0.005,9.3E-6,5.7918511,0.1205393,118.66396,0.1197,5.59268,0.01293,124.25664,0.1197,0.55233326,24.108145,0.0081808541,99.205315,0,0,1,,,,5.1918E-6,48.83795,33.545539,20.488088,0
31121917.73,,5905,5.82527,5.8502,-0.005,9.3E-6,5.8932028,0.12014619,121.32747,0.1537,5.8558256,0.01375,127.18329,0.1537,0.23885326,24.451227,0.0091139721,99.145362,0,0,1,,,,5.2423E-6,48.13333,34.729839,20.587696,0
31122264.34,,5905,5.82741,5.8521,-0.005,9.4E-6,5.897363,0.12205795,121.36293,0.1142,5.8668499,0.01378,127.22978,0.1142,0.24955239,24.160484,0.0087734812,99.168754,0,0,1,,,,5.3062E-6,48.5382,34.77889,20.579186,0
31122792.8,,5905,5.92952,5.9541,-0.005,9.4E-6,6.0010914,0.12504248,124.14217,0.09955,6.1421199,0.01466,130.28429,0.09955,0.51622682,24.2806,0.0087478641,99.192642,0,0,1,,,,5.4054E-6,49.19325,36.013098,20.686599,0
31123322.5,,5905,6.03102,6.0569,-0.005,9.3E-6,6.1012741,0.12427681,127.02244,0.1521,6.4144367,0.01552,133.43688,0.1521,0.31819581,24.585329,0.0097942631,99.123158,0,0,1,,,,5.471E-6,48.53766,37.225545,20.819003,0
31123671.84,,5905,6.03334,6.0582,-0.005,9.2E-6,6.1053793,0.12592015,127.08315,0.1193,6.4249421,0.01555,133.50809,0.1193,0.29769694,24.287269,0.0088062198,99.2033,0,0,1,,,,5.5371E-6,48.64126,37.275656,20.814947,0
31124203.05,,5905,6.13652,6.1601,-0.005,9.4E-6,6.2099951,0.12904242,129.81887,0.1212,6.7153175,0.0166,136.53419,0.1212,0.52727259,24.399348,0.0092334935,99.185405,0,0,1,,,,5.6374E-6,49.42251,38.564039,20.904826,0
31124734.16,,5905,6.23839,6.263,-0.005,9.3E-6,6.3100975,0.12854681,132.70187,0.1669,6.9983848,0.01774,139.70026,0.1669,0.34113607,24.734941,0.009984638,99.14583,0,0,1,,,,5.6918E-6,48.85952,39.81733,21.030083,0
31125082.52,,5905,6.24071,6.2668,-0.005,9.3E-6,6.3140955,0.13013695,132.83825,0.1333,7.0098012,0.01779,139.84805,0.1333,0.23480703,24.445763,0.0093678859,99.189843,0,0,1,,,,5.7629E-6,48.95344,39.867803,21.038366,0
31125618.39,,5905,6.34368,6.3709,-0.005,9.3E-6,6.4188633,0.1332687,135.83695,0.1395,7.312898,0.01903,143.14985,0.1395,0.77976527,24.614604,0.0097259127,99.179492,0,0,1,,,,5.859E-6,49.79683,41.201805,21.162151,0
31126149.75,,5905,6.44523,6.473,-0.005,9.3E-6,6.5185879,0.1325209,139.00244,0.1679,7.6090556,0.02016,146.6115,0.1679,0.27803817,25.048216,0.010884685,99.110546,0,0,1,,,,5.9004E-6,49.13585,42.491988,21.324012,0
31126503.42,,5905,6.44755,6.4756,-0.005,9.2E-6,6.5233556,0.13456253,139.07845,0.1409,7.6233115,0.02021,146.70176,0.1409,0.45289756,24.680232,0.0099204084,99.178686,0,0,1,,,,5.9884E-6,49.55839,42.554168,21.320078,0
31127041.02,,5905,6.55093,6.58,-0.005,9.3E-6,6.6277459,0.13737066,142.37707,0.1528,7.9401175,0.02123,150.31718,0.1528,0.61376141,24.871427,0.010365628,99.161398,0,0,1,,,,6.0896E-6,50.21276,43.927016,21.481974,0
31127576.39,,5905,6.65263,6.6805,-0.005,9.4E-6,6.7274441,0.13638026,145.79459,0.2028,8.2512769,0.02197,154.04586,0.2028,0.3058589,25.297636,0.011621649,99.087182,0,0,1,,,,6.1396E-6,49.62819,45.258505,21.671616,0
31127934.14,,5905,6.65364,6.6809,-0.005,9.4E-6,6.7320408,0.1384621,145.87602,0.1596,8.2648655,0.02199,154.14088,0.1596,0.4620907,24.949773,0.010453686,99.168825,0,0,1,,,,6.2244E-6,49.99089,45.320374,21.668914,0
31128473.28,,5905,6.75783,6.7845,-0.005,9.3E-6,6.8365156,0.14132984,149.61316,0.1614,8.5986254,0.0224,158.21179,0.1614,1.2986995,25.188523,0.010759875,99.163307,0,0,1,,,,6.3285E-6,50.86678,46.737946,21.884417,0
31129010.52,,5905,6.85941,6.8877,-0.005,9.4E-6,6.93617,0.14008938,153.7497,0.2612,8.9258735,0.02246,162.67557,0.2612,0.4739252,25.750276,0.012574146,99.051276,0,0,1,,,,6.3715E-6,50.30409,48.110454,22.166368,0
31129373.56,,5905,6.86171,6.8918,-0.005,9.3E-6,6.9415371,0.14283229,153.3332,0.1817,8.9427257,0.02245,162.27593,0.1817,0.81812461,25.336125,0.010751739,99.179731,0,0,1,,,,6.4522E-6,50.80032,48.184937,22.089229,0
31129919.73,,5905,6.9648,6.9953,-0.005,9.3E-6,7.0461042,0.14589438,158.03301,0.2103,9.2931965,0.02226,167.32621,0.2103,0.48697049,25.648084,0.010713733,99.198606,0,0,1,,,,6.571E-6,52.05563,49.647585,22.428423,0
31130465.73,,5905,7.06582,7.0962,-0.005,9.3E-6,7.1452928,0.14374952,162.75699,0.2636,9.6336984,0.02193,172.39069,0.2636,0.63085509,26.293903,0.012563727,99.087821,0,0,1,,,,6.6101E-6,51.16441,51.055209,22.778211,0
31130835.27,,5905,7.06837,7.1,-0.005,9.2E-6,7.1505959,0.14664958,162.96752,0.2081,9.6513306,0.02191,172.61885,0.2081,0.36893997,25.964619,0.011241284,99.174446,0,0,1,,,,6.6976E-6,51.9747,51.131021,22.790761,0
31131374.66,,5905,7.17074,7.2009,-0.005,9.3E-6,7.2571755,0.16010671,138.94442,1.204,10.028167,0.02153,148.97259,1.204,67.935331,23.554445,0.021140893,98.554901,0,0,1,,,,6.4054E-6,48.15389,52.666596,19.145799,0
31131890.13,,5905,7.27268,7.3056,-0.005,9.3E-6,7.3652475,0.16251043,128.91348,0.1268,10.40704,0.02122,139.32052,0.1268,0.11381513,20.679173,0.014718165,98.96256,0,0,1,,,,6.7978E-6,46.82601,54.246871,17.502939,0
31132193.17,,5905,7.27524,7.3065,-0.005,9.3E-6,7.3640932,0.15264633,128.78004,0.07262,10.406874,0.02122,139.18691,0.07262,0.079190585,20.477443,0.013618019,99.03198,0,0,1,,,,6.854E-6,40.9692,54.229868,17.487562,0
31132669.28,,5905,7.37744,7.4105,-0.005,9.3E-6,7.4676381,0.15475252,128.91599,0.07429,10.781952,0.0211,139.69794,0.07429,0.45118417,20.106641,0.013060135,99.082071,0,0,1,,,,7.0027E-6,40.57217,55.765619,17.263289,0
31133142.44,,5905,7.47981,7.5132,-0.005,9.3E-6,7.5687737,0.15535287,129.90951,0.1349,11.155272,0.02123,141.06478,0.1349,0.50956602,20.175067,0.014264563,99.022447,0,0,1,,,,7.0506E-6,40.36224,57.286336,17.163878,0
31133437.36,,5905,7.48181,7.5122,-0.005,9.4E-6,7.5733062,0.15583973,129.74361,0.07863,11.172811,0.02124,140.91642,0.07863,0.37569822,19.865725,0.013125299,99.089139,0,0,1,,,,7.1488E-6,39.83939,57.354967,17.1317,0
31133905.19,,5905,7.58408,7.6169,-0.005,9.3E-6,7.6765925,0.15870213,131.34336,0.07624,11.561056,0.02147,142.90441,0.07624,1.4626348,19.803204,0.012378014,99.154425,0,0,1,,,,7.2682E-6,40.09786,58.930072,17.109591,0
31134374.2,,5905,7.68639,7.7178,-0.005,9.3E-6,7.7772252,0.15838764,132.68991,0.1353,11.945444,0.02177,144.63535,0.1353,0.28723439,19.960146,0.014342365,99.045398,0,0,1,,,,7.305E-6,39.59738,60.485232,17.061344,0
31134666.84,,5905,7.68945,7.7222,-0.005,9.2E-6,7.7820512,0.16000252,132.63642,0.09595,11.963833,0.02178,144.60026,0.09595,0.39532536,19.720754,0.013321407,99.104412,0,0,1,,,,7.3882E-6,39.53243,60.560321,17.04389,0
31135137.36,,5905,7.79114,7.8237,-0.005,9.3E-6,7.8851939,0.16315688,134.15177,0.1018,12.365617,0.02217,146.51738,0.1018,0.74514025,19.729264,0.01353215,99.106967,0,0,1,,,,7.4825E-6,39.83085,62.176283,17.013122,0
31135607.19,,5905,7.89292,7.9243,-0.005,9.2E-6,7.9858014,0.16238614,135.77245,0.1419,12.76307,0.02263,148.53552,0.1419,0.224274,19.808987,0.014444548,99.065711,0,0,1,,,,7.5575E-6,39.35295,63.773024,17.001731,0
31135897.69,,5905,7.89607,7.9274,-0.005,9.4E-6,7.9906682,0.16411252,135.97655,0.101,12.782578,0.02266,148.75913,0.101,0.30696386,19.650584,0.013623916,99.111985,0,0,1,,,,7.6269E-6,39.32408,63.850778,17.016919,0
31136364.94,,5905,7.99808,8.0279,-0.005,9.3E-6,8.0940333,0.16710359,137.55396,0.1074,13.199693,0.02324,150.75366,0.1074,1.357868,19.659378,0.014246134,99.087392,0,0,1,,,,7.7271E-6,39.63634,65.513375,16.994489,0
31141965.41,,5905,25.0091,25.0182,-0.005,9.4E-6,25.277671,0.51927083,259.6274,0.3573,167.51994,0.2305,427.14734,0.3573,0.94487119,15.755395,0.046966951,98.753458,0,0,1,,,,2.7238E-5,31.38946,638.96065,10.271017,0
31142224.59,,5905,24.9948,25.0356,-0.005,9.3E-6,25.251222,0.51521216,261.21079,0.3689,167.19212,0.2301,428.40291,0.3689,1.9967655,15.986398,0.05749903,98.494228,0,0,1,,,,2.6951E-5,31.52026,637.62423,10.344481,0
31142823.59,,5905,27.2354,27.2736,-0.005,9.4E-6,27.516927,0.56625109,292.871,0.4397,197.12199,0.2865,489.99299,0.4397,6.9387705,17.035134,0.067540682,98.358714,0,0,1,,,,2.8936E-5,34.06366,757.18125,10.643303,0
31143583.33,,5905,29.6734,29.7022,-0.005,9.4E-6,29.966602,0.58399488,328.03174,0.5231,231.44565,0.3689,559.47738,0.5231,0.21776168,17.767477,0.064376814,98.513006,0,0,1,,,,3.1653E-5,33.82714,897.99723,10.946578,0
31143852.28,,5905,29.6775,29.7024,-0.005,9.3E-6,29.981151,0.61220886,329.2951,0.5066,231.65676,0.3692,560.95186,0.5066,1.1718964,17.991989,0.070799316,98.384829,0,0,1,,,,3.1355E-5,35.92057,898.86944,10.983404,0
31144762.47,,5905,32.3366,32.3551,-0.005,9.2E-6,32.677491,0.68085755,370.3842,0.5717,270.33771,0.4087,640.72191,0.5717,0.36915182,18.998697,0.070869886,98.478231,0,0,1,,,,3.3899E-5,39.57355,1067.8184,11.334536,0
31145568.44,,5905,35.2165,35.2817,-0.005,9.3E-6,35.543874,0.69405081,412.24538,0.9268,314.81548,0.4987,727.06086,0.9268,0.030234751,20.081344,0.081080143,98.364917,0,0,1,,,,3.64E-5,38.04793,1263.367,11.598212,0
31145865.45,,5905,35.2271,35.2475,-0.005,9.3E-6,35.597988,0.73691242,412.09855,0.6744,315.66649,0.5005,727.76504,0.6744,0.24421121,20.163126,0.080567313,98.382453,0,0,1,,,,3.6285E-5,41.22147,1267.2168,11.576456,0
31146693.78,,5905,38.3746,38.4091,-0.005,9.4E-6,38.758364,0.792691,457.07223,0.7526,367.2695,0.5602,824.34174,0.7526,0.36296722,21.476667,0.097360171,98.177628,0,0,1,,,,3.8603E-5,42.35184,1502.2108,11.792867,0
31147546.64,,5905,41.7991,41.8625,-0.005,9.2E-6,42.190207,0.83147575,502.20577,1.125,426.46047,0.6016,928.66624,1.125,0.030824678,22.343425,0.095951413,98.282945,0,0,1,,,,4.1777E-5,42.96604,1780.0136,11.903373,0
31147871.83,,5905,41.8095,41.828,-0.005,9.2E-6,42.250624,0.87871557,502.68745,0.8249,427.53405,0.6026,930.2215,0.8249,0.1984717,22.573903,0.10061153,98.218656,0,0,1,,,,4.1427E-5,46.10036,1785.1153,11.897752,0
31148769.69,,5905,45.5539,45.5838,-0.005,9.3E-6,45.990972,0.93702771,549.82084,1.075,496.70963,0.6662,1046.5305,1.075,0.47809042,24.484514,0.14638599,97.627523,0,0,1,,,,4.3031E-5,46.5536,2115.1695,11.954973,0
31149689.38,,5905,49.6191,49.6631,-0.005,9.3E-6,50.083484,0.98099152,589.01756,1.065,578.05501,0.7366,1167.0726,1.065,0.15091463,24.555908,0.10174815,98.355724,0,0,1,,,,4.773E-5,47.60432,2508.3553,11.760715,0
31150045.13,,5905,49.6278,49.6397,-0.005,9.2E-6,50.138781,1.0413157,592.88844,0.9298,579.26816,0.7376,1172.1566,0.9298,0.53312687,25.124912,0.1265066,98.005149,0,0,1,,,,4.6897E-5,51.44683,2513.8974,11.824947,0
31151001.47,,5905,54.062,54.1066,-0.005,9.4E-6,54.568942,1.1060991,638.86811,1.121,675.40513,0.8109,1314.2732,1.121,0.7232456,26.835707,0.16834761,97.521305,0,0,1,,,,4.9271E-5,52.13984,2977.7695,11.707541,0
31151997.89,,5905,58.9005,58.9281,-0.005,9.3E-6,59.439521,1.1591846,675.34522,1.057,790.88785,0.9139,1466.2331,1.057,3.0379837,27.636347,0.14862918,97.861838,0,0,1,,,,5.3302E-5,53.07865,3533.0567,11.361889,0
31152417.61,,5905,58.9021,58.9202,-0.005,9.3E-6,59.486324,1.2147036,679.1273,1.111,792.07252,0.9151,1471.1998,1.111,1.3150339,27.927639,0.16535237,97.649588,0,0,1,,,,5.2951E-5,56.39158,3538.6227,11.416528,0
31153404.42,,5905,64.1626,64.2121,-0.005,9.3E-6,64.762855,1.3114737,721.27172,1.352,929.67038,1.078,1650.9421,1.352,0.30736696,29.318316,0.17957426,97.547879,0,0,1,,,,5.6583E-5,59.1131,4194.2273,11.137121,0
31154369.38,,5905,69.9207,69.9522,-0.005,9.3E-6,70.519204,1.3651502,758.13596,1.968,1094.03,1.284,1852.166,1.968,0.16103214,31.316807,0.23997973,96.895649,0,0,1,,,,5.9463E-5,59.06104,4972.9581,10.750773,0
31154797.39,,5905,69.9083,69.9508,-0.005,9.3E-6,70.563291,1.4075437,759.77764,1.552,1095.2875,1.285,1855.0651,1.552,0.52258699,31.095432,0.21592589,97.181994,0,0,1,,,,5.9949E-5,61.18798,4979.1781,10.767321,0
31155782.97,,5905,76.1561,76.1968,-0.005,9.3E-6,76.880882,1.5466598,790.69797,1.824,1291.1007,1.457,2081.7987,1.824,0.18838055,32.353482,0.20032795,97.419484,0,0,1,,,,6.4593E-5,66.30658,5910.67,10.284715,0
31156758.86,,5905,82.9895,83.0288,-0.005,9.4E-6,83.637147,1.5694872,836.34671,5.286,1519.5385,1.569,2355.8852,5.047,0.25213683,34.473982,0,100,0,0,1,,,,6.8338E-5,65.05799,6995.1724,9.999704,0
31157230.88,,5905,82.9666,83.0024,-0.005,9.3E-6,83.744548,1.661315,821.97688,2.281,1522.9769,1.571,2344.9538,2.281,0.081576229,34.0789,0.2131665,97.308069,0,0,1,,,,6.9045E-5,68.96538,7013.1493,9.8152883,0
31158188.63,,5905,90.3993,90.4417,-0.005,9.3E-6,91.197051,1.7966159,858.33846,2.002,1800.5212,1.776,2658.8596,2.002,1.7472423,36.45114,0.29209061,96.437532,0,0,1,,,,7.3226E-5,72.71026,8316.9022,9.4119102,0
31159174.94,,5905,98.4961,98.5395,-0.005,9.3E-6,99.235843,1.8625569,886.81618,4.112,2122.0664,1.991,3008.8826,4.112,0.093616768,39.181177,0.44110024,94.81535,0,0,1,,,,7.7163E-5,72.54117,9847.7525,8.9364503,0
31159697,,5905,98.4815,98.5092,-0.005,9.3E-6,99.391914,1.9463964,886.19832,2.479,2127.9794,1.994,3014.1777,2.479,0.24249188,38.174375,0.28230062,96.539092,0,0,1,,,,7.9205E-5,76.84532,9878.7526,8.9162013,0
31160777.42,,5905,107.292,107.362,-0.005,9.3E-6,108.24999,2.1245948,909.02586,2.628,2502.8187,2.237,3411.8446,2.628,0.39686564,40.25916,0.3236321,96.026978,0,0,1,,,,8.4998E-5,82.33203,11718.061,8.397468,0
31161922.53,,5905,116.894,116.931,-0.005,9.3E-6,117.77853,2.1714909,929.61388,4.771,2926.5316,2.54,3856.1455,4.771,0.092792399,43.137963,0.50747135,93.915255,0,0,1,,,,8.9732E-5,80.67068,13871.782,7.8928978,0
31162534.77,,5905,116.893,116.919,-0.005,9.3E-6,117.92249,2.2681375,930.91221,3.263,2932.6983,2.542,3863.6105,3.263,0.18836827,42.470048,0.34466783,95.729873,0,0,1,,,,9.121E-5,84.80005,13905.714,7.8942718,0
31163491.84,,5905,127.355,127.385,-0.005,9.3E-6,128.43773,2.4791967,952.80706,3.115,3415.9279,2.653,4368.7349,3.115,0.46918578,44.611753,0.39459543,95.045473,0,0,1,,,,9.8173E-5,90.70106,16496.251,7.4184357,0
31164511.8,,5905,138.773,138.838,-0.005,9.2E-6,139.78835,2.5526303,964.85697,6.655,3947.4094,2.882,4912.2664,6.655,0.071589696,47.346822,0.66378601,91.789775,0,0,1,,,,0.00010411,88.6454,19540.782,6.9022704,0
31165179.17,,5905,138.75,138.791,-0.005,9.4E-6,139.99615,2.6610557,962.45253,4.09,3956.4345,2.886,4918.887,4.09,0.10516729,46.096099,0.3085233,95.907813,0,0,1,,,,0.00010688,93.03883,19598.921,6.8748501,0
31166335.56,,5905,151.165,151.225,-0.005,9.4E-6,152.4958,2.9097209,982.13249,3.283,4543.8749,3.045,5526.0074,3.283,1.9269324,47.957283,0.43414124,94.145082,0,0,1,,,,0.00011546,98.0475,23254.97,6.4403903,0
31167550.23,,5905,164.689,164.708,-0.005,9.4E-6,165.92372,3.0025378,1005.7108,6.7,5165.2125,3.208,6170.9233,6.7,0.10484647,49.959173,0.79269688,89.521524,0,0,1,,,,0.00012391,95.43658,27530.682,6.0612842,0
31168300.28,,5905,164.676,164.663,-0.005,9.3E-6,166.12313,3.1141596,995.81848,3.645,5173.3491,3.211,6169.1676,3.645,0.43389239,48.609185,0.28960674,95.774806,0,0,1,,,,0.00012706,98.08795,27596.893,5.9944603,0
31169530.8,,5905,179.41,179.392,-0.005,9.2E-6,180.966,3.4218926,1014.2449,3.577,5836.2042,3.459,6850.4491,3.577,7.8919514,49.629569,0.37500382,94.33396,0,0,1,,,,0.00013821,101.6272,32748.693,5.6046155,0
31170809.52,,5905,195.478,195.447,-0.005,9.4E-6,196.98477,3.5353901,1029.5793,7.581,6527.8824,3.564,7557.4617,7.581,0.09668931,50.426139,0.72615643,89.051736,0,0,1,,,,0.00015022,98.39067,38802.998,5.226695,0
31171567.66,,5905,195.461,195.418,-0.005,9.2E-6,197.12636,3.5839644,1027.441,5.956,6534.2363,3.569,7561.6773,4.768,0.68436427,49.112574,0,100,0,0,1,,,,0.00015397,98.77911,38858.804,5.2120934,0
31172749,,5905,212.956,212.912,-0.005,9.3E-6,214.79017,3.886843,999.96689,9.033,7372.2126,4.975,8372.1795,7.54,0.16685743,48.702392,0,100,0,0,1,,,,0.0001719,100.7091,46134.819,4.6555523,0
31173922.38,,5905,232.031,231.992,-0.005,9.3E-6,233.82032,4.058143,1090.8503,10.38,8167.3358,4.439,9258.186,10.38,0.082563527,49.050562,0.93791556,84.393499,0,0,1,,,,0.00018924,97.87677,54671.942,4.6653356,0
31174660.17,,5905,232.001,231.959,-0.005,9.2E-6,233.92564,4.0651314,1088.7004,7.256,8171.4461,4.43,9260.1465,5.747,0.21730147,47.894192,0,100,0,0,1,,,,0.00019335,95.8719,54721.204,4.6540447,0
31175772.55,,5905,252.761,252.659,-0.005,9.4E-6,254.78724,4.4233499,1065.2136,7.226,8939.6607,4.728,10004.874,5.464,0.38889809,46.219374,0,100,0,0,1,,,,0.00021646,94.51813,64916.537,4.1807964,0
31176874.17,,5905,275.398,275.237,-0.005,9.2E-6,277.41832,4.6727511,1177.1016,11.71,9678.5894,6.676,10855.691,11.71,0.22038068,44.971288,1.8087404,70.406105,0,0,1,,,,0.00024263,92.77801,76960.927,4.2430563,0